Workbook

Sheet Balance Sheet
A1: Rupees in ‘000 | B1: 2021 | C1: 2020 | D1: 2019 | E1: 2018 | F1: 2017 | H1: 2017 | I1: 2018 | J1: 2019 | K1: 2020 | L1: 2021
A3: Assets
A4: Cash and balances with treasury banks | B4: 89432245 | C4: 73651718 | D4: 63039290 | E4: 49187645 | F4: 44239325 | H4: 44239325 | I4: 49187645 | J4: 63039290 | K4: 73651718 | L4: 89432245
A5: Balances with other banks | B5: 3556215 | C5: 8196147 | D5: 7886702 | E5: 4093402 | F5: 3193835 | H5: 3193835 | I5: 4093402 | J5: 7886702 | K5: 8196147 | L5: 3556215
A6: Lendings to financial institutions | B6: – | C6: – | D6: 20405972 | E6: – | F6: 2250000 | H6: 2250000 | I6: – | J6: 20405972 | K6: – | L6: –
A7: Investments | B7: 616231172 | C7: 449611987 | D7: 305435633 | E7: 260233987 | F7: 314956748 | H7: 314956748 | I7: 260233987 | J7: 305435633 | K7: 449611987 | L7: 616231172
A8: Advances | B8: 477673022 | C8: 395416055 | D8: 372913863 | E8: 343107147 | F8: 258693086 | H8: 258693086 | I8: 343107147 | J8: 372913863 | K8: 395416055 | L8: 477673022
A9: Fixed assets | B9: 20179222 | C9: 21232750 | D9: 19696568 | E9: 12791827 | F9: 9885958 | H9: 9885958 | I9: 12791827 | J9: 19696568 | K9: 21232750 | L9: 20179222
A10: Intangible assets | B10: 1188985 | C10: 1158857 | D10: 808994 | E10: 741361 | F10: 842869 | H10: 842869 | I10: 741361 | J10: 808994 | K10: 1158857 | L10: 1188985
A11: Deferred tax assets | B11: 5161697 | C11: 1597334 | D11: 2489752 | E11: 3773779 | F11: 100755 | H11: 100755 | I11: 3773779 | J11: 2489752 | K11: 1597334 | L11: 5161697
A12: Other assets | B12: 45906052 | C12: 42021813 | D12: 40450512 | E12: 32522174 | F12: 28448099 | H12: 28448099 | I12: 32522174 | J12: 40450512 | K12: 42021813 | L12: 45906052
D13: 833208006 | E13: 706451322 | F13: 662610675 | H13: 662610675 | I13: 706451322 | J13: 833208006
A14: Assets attributable to discontinued operations | D14: 315741 | E14: 214757 | F14: 327949 | H14: 327949 | I14: 214757 | J14: 315741
A17: Total Assets | B17: 1259328610 | C17: 992886661 | D17: 833443027 | E17: 706666079 | F17: 662938624 | H17: 662938624 | I17: 706666079 | J17: 833443027 | K17: 992886661 | L17: 1259328610
A18: Liabilities
A19: Bills payable | B19: 10235374 | C19: 12629996 | D19: 15768947 | E19: 15512880 | F19: 10769262 | H19: 10769262 | I19: 15512880 | J19: 15768947 | K19: 12629996 | L19: 10235374
A20: Borrowings | B20: 123563761 | C20: 84163669 | D20: 51187681 | E20: 52702323 | F20: 71587311 | H20: 71587311 | I20: 52702323 | J20: 51187681 | K20: 84163669 | L20: 123563761
A21: Deposits and other accounts | B21: 1015162254 | C21: 790982287 | D21: 679246312 | E21: 573596926 | F21: 525805051 | H21: 525805051 | I21: 573596926 | J21: 679246312 | K21: 790982287 | L21: 1015162254
A22: Liabilities against assets subject to finance lease | B22: – | C22: – | D22: – | E22: – | F22: – | H22: – | I22: – | J22: – | K22: – | L22: –
A23: Subordinated debts | B23: 12000000 | C23: 12000000 | D23: 9992000 | E23: 9993600 | F23: 4992800 | H23: 4992800 | I23: 9993600 | J23: 9992000 | K23: 12000000 | L23: 12000000
A24: Deferred tax liabilities | B24: – | C24: – | D24: – | E24: – | F24: – | H24: – | I24: – | J24: – | K24: – | L24: –
A25: Other liabilities | B25: 42326358 | C25: 38429434 | D25: 34704048 | E25: 21178476 | F25: 17098223 | H25: 17098223 | I25: 21178476 | J25: 34704048 | K25: 38429434 | L25: 42326358
A26: Total Liabilites | B26: 1203287747 | C26: 938205386 | D26: =SUM(D19:D25) -> 790898988 | E26: 672984205 | F26: 630252647 | H26: 630252647 | I26: 672984205 | J26: =SUM(J19:J25) -> 790898988 | K26: 938205386 | L26: 1203287747
A27: Liabilities associated with discontionued operations | B27: – | C27: – | D27: 141856 | E27: 81513 | F27: 140741 | H27: 140741 | I27: 81513 | J27: 141856 | K27: – | L27: –
D28: =SUM(D26:D27) -> 791040844 | E28: 673065718 | F28: 630393388 | H28: 630393388 | I28: 673065718 | J28: =SUM(J26:J27) -> 791040844
A29: Net Assets | B29: 56040863 | C29: 54681275 | D29: 42402183 | E29: 33600361 | F29: 32545236 | H29: 32545236 | I29: 33600361 | J29: 42402183 | K29: 54681275 | L29: 56040863
A30: Represented By
A31: Share capital | B31: 12602602 | C31: 12602602 | D31: 12602602 | E31: 12602602 | F31: 12602602 | H31: 12602602 | I31: 12602602 | J31: 12602602 | K31: 12602602 | L31: 12602602
A32: Reserves | B32: 32832051 | C32: 25701665 | D32: 19408889 | E32: 15588694 | F32: 12032263 | H32: 12032263 | I32: 15588694 | J32: 19408889 | K32: 25701665 | L32: 32832051
A33: Surplus on revaluation of assets - net of tax | B33: 1987976 | C33: 7670955 | K33: 7670955 | L33: 1987976
A34: Continued operations | B34: 8618234 | C34: 8706053 | D34: 4300426 | E34: 1649197 | F34: 5142254 | H34: 5142254 | I34: 1649197 | J34: 4300426 | K34: 8706053 | L34: 8618234
A35: Discontinued operations | D35: 39467 | E35: 5723 | F35: 19877 | H35: 19877 | I35: 5723 | J35: 39467
A36: Unappropriated profit | D36: 6002253 | E36: 3710867 | F36: 2703887 | H36: 2703887 | I36: 3710867 | J36: 6002253
D37: 42353637 | E37: 33557083 | F37: 32500883 | H37: 32500883 | I37: 33557083 | J37: 42353637
A39: Non-controlling interest | B39: – | C39: – | D39: 48546 | E39: 43278 | F39: 44353 | H39: 44353 | I39: 43278 | J39: 48546 | K39: – | L39: –
B41: 56040863 | C41: 54681275 | D41: =SUM(D37:D39) -> 42402183 | E41: 33600361 | F41: 32545236 | H41: 32545236 | I41: 33600361 | J41: =SUM(J37:J39) -> 42402183 | K41: 54681275 | L41: 56040863

Sheet Income Statement
A1: Rupees in ‘000 | B1: 2021 | C1: 2020 | D1: 2019 | E1: 2018 | F1: 2017 | H1: 2017 | I1: 2018 | J1: 2019 | K1: 2020 | L1: 2021
A3: Mark-up / return / interest earned | B3: 77,569,443 | C3: 79,118,320 | D3: 71704373 | E3: 43669883 | F3: 36267220 | H3: 36267220 | I3: 43669883 | J3: 71704373 | K3: 79,118,320 | L3: 77,569,443
A4: Mark-up / return / interest expenses | B4: 45139897 | C4: 48842539 | D4: 49567851 | E4: 25059925 | F4: 20071958 | H4: 20071958 | I4: 25059925 | J4: 49567851 | K4: 48842539 | L4: 45139897
A5: Net mark-up / interest income | B5: 32429546 | C5: 30275781 | D5: 22136522 | E5: 18609958 | F5: 16195262 | H5: 16195262 | I5: 18609958 | J5: 22136522 | K5: 30275781 | L5: 32429546
A6: Non mark-up / interest income
A7: Fee and commission income | B7: 4785268 | C7: 3991285 | D7: 3616428 | E7: 3116070 | F7: 2706794 | H7: 2706794 | I7: 3116070 | J7: 3616428 | K7: 3991285 | L7: 4785268
A8: Dividend income | B8: 421964 | C8: 273524 | D8: 274440 | E8: 231312 | F8: 302894 | H8: 302894 | I8: 231312 | J8: 274440 | K8: 273524 | L8: 421964
A9: Foreign exchange income | B9: 3123524 | C9: 2673493 | D9: 2507707 | E9: 1596027 | F9: 843032 | H9: 843032 | I9: 1596027 | J9: 2507707 | K9: 2673493 | L9: 3123524
A10: Income / (loss) from derivatives | B10: – | C10: – | D10: – | E10: – | F10: – | H10: – | I10: – | J10: – | K10: – | L10: –
A11: Gain on securities | B11: 814724 | C11: 2555400 | D11: 739351 | E11: 260103 | F11: 2063043 | H11: 2063043 | I11: 260103 | J11: 739351 | K11: 2555400 | L11: 814724
A12: Other income | B12: 402118 | C12: 349438 | D12: 266102 | E12: 418081 | F12: 200341 | H12: 200341 | I12: 418081 | J12: 266102 | K12: 349438 | L12: 402118
A13: Total non-markup / interest income | B13: 9547598 | C13: 9843140 | D13: 7404028 | E13: 5621593 | F13: 6116104 | H13: 6116104 | I13: 5621593 | J13: 7404028 | K13: 9843140 | L13: 9547598
A14: Total income | B14: 41977144 | C14: 40118921 | D14: 29540550 | E14: 24231551 | F14: 22311366 | H14: 22311366 | I14: 24231551 | J14: 29540550 | K14: 40118921 | L14: 41977144
A15: Non mark-up / interest expenses
A16: Operating expenses | B16: 21017376 | C16: 20217974 | D16: 18235061 | E16: 16240514 | F16: 14948796 | H16: 14948796 | I16: 16240514 | J16: 18235061 | K16: 20217974 | L16: 21017376
A17: Workers’ welfare fund | B17: 213484 | C17: 42982 | D17: 42117 | E17: -540060 | F17: 169833 | H17: 169833 | I17: -540060 | J17: 42117 | K17: 42982 | L17: 213484
A18: Total non-markup / interest expenses | B18: 90139 | C18: 48149 | D18: 99947 | E18: 191067 | F18: 23568 | H18: 23568 | I18: 191067 | J18: 99947 | K18: 48149 | L18: 90139
B19: 21320999 | C19: 20309105 | D19: 18377125 | E19: 15891521 | F19: 15142197 | H19: 15142197 | I19: 15891521 | J19: 18377125 | K19: 20309105 | L19: 21320999
A20: Profit before provisions | B20: 20656145 | C20: 19809816 | D20: 11163425 | E20: 8340030 | F20: 7169169 | H20: 7169169 | I20: 8340030 | J20: 11163425 | K20: 19809816 | L20: 20656145
A21: Provisions and write offs - net | B21: 4983944 | C21: 1974747 | D21: 773275 | E21: 1460575 | F21: -1176432 | H21: -1176432 | I21: 1460575 | J21: 773275 | K21: 1974747 | L21: 4983944
A22: Extraordinary / unusual items | B22: – | C22: – | D22: – | E22: – | F22: – | H22: – | I22: – | J22: – | K22: – | L22: –
A23: Profit before taxation | B23: 15672201 | C23: 17835069 | D23: 10390150 | E23: 6879455 | F23: 8345601 | H23: 8345601 | I23: 6879455 | J23: 10390150 | K23: 17835069 | L23: 15672201
A24: Taxation | B24: -5956468 | C24: -6978072 | D24: 3372249 | E24: -2448177 | F24: -3223915 | H24: -3223915 | I24: -2448177 | J24: 3372249 | K24: -6978072 | L24: -5956468
A25: Profit after taxation | B25: 9715733 | C25: 10856997 | D25: 7017901 | E25: 4431278 | F25: 5121686 | H25: 5121686 | I25: 4431278 | J25: 7017901 | K25: 10856997 | L25: 9715733
A26: (Loss) / profit after taxation - discontinued operations | D26: 14669 | E26: -2659 | F26: 6611 | H26: 6611 | I26: -2659 | J26: 14669
A27: Attributable to:
A28: Equity holders of the Bank | B28: 9715733 | C28: 10846333 | D28: 7028756 | E28: 4429310 | F28: 5121863 | H28: 5121863 | I28: 4429310 | J28: 7028756 | K28: 10846333 | L28: 9715733
A29: Non-controlling interest | B29: – | C29: 10664 | D29: 3814 | E29: -691 | F29: 6434 | H29: 6434 | I29: -691 | J29: 3814 | K29: 10664 | L29: –
B30: 9715733 | C30: 10856997 | D30: =SUM(D28:D29) -> 7032570 | E30: 4428619 | F30: 5128297 | H30: 5128297 | I30: 4428619 | J30: =SUM(J28:J29) -> 7032570 | K30: 10856997 | L30: 9715733
A32: Basic and diluted earnings per share | B32: 7.71 | C32: 8.61 | D32: 5.58 | E32: 3.51 | F32: 4.06 | H32: 4.06 | I32: 3.51 | J32: 5.58 | K32: 8.61 | L32: 7.71

Sheet Profitability Ratio
C1: 2021 | D1: 2020 | E1: 2019 | F1: 2018 | G1: 2017
B13: Earning Assets
B14: Loans and Advances | C14: 477673022 | D14: 395416055 | E14: 372913863 | F14: 343107147 | G14: 258693086
B15: Investments | C15: 616231172 | D15: 449611987 | E15: 305435633 | F15: 260233987 | G15: 314956748
B16: Lending to Financial Institutions - Net | C16: 0 | D16: 0 | E16: 20405972 | F16: 0 | G16: 2250000
B17: Balances with other banks | C17: 3556215 | D17: 8196147 | E17: 7886702 | F17: 4093402 | G17: 3193835
B18: TOTAL EARNING ASSETS | C18: =SUM(C14:C17) -> 1097460409 | D18: =SUM(D14:D17) -> 853224189 | E18: =SUM(E14:E17) -> 706642170 | F18: =SUM(F14:F17) -> 607434536 | G18: =SUM(G14:G17) -> 579093669
B20: Interest Bearing Liabilities
B21: Deposits (less of Current Accounts) | C21: 222888771 | D21: 539726821 | E21: 484456138 | F21: 404040078 | G21: 381975947
B22: Current Account Deposits | C22: 790982287 | D22: 1030588 | E22: 194254257 | F22: 168745407 | G22: 143678468
B23: Current Account Deposits | C23: 1291196 | D23: 250224878 | E23: 535917 | F23: 811441 | G23: 150636
B24: Borrowings | C24: 123563761 | D24: 84163669 | E24: 51187681 | F24: 52702323 | G24: 71587311
B25: Subordinated Debts | C25: 12000000 | D25: 12000000 | E25: 9992000 | F25: 9993600 | G25: 4992800
B26: Lease liability against ROU assets as per IFRS - 16 Leases | C26: 7393878 | D26: 8223995 | E26: 970082 | F26: 0 | G26: 0
B27: Total Interest Bearing Liability | C27: =SUM(C21:C26) -> 1158119893 | D27: =SUM(D21:D26) -> 895369951 | E27: =SUM(E21:E26) -> 741396075 | F27: =SUM(F21:F26) -> 636292849 | G27: =SUM(G21:G26) -> 602385162
B29: Net Income | C29: ='Income Statement'!B25 -> 9715733 | D29: ='Income Statement'!C25 -> 10856997 | E29: ='Income Statement'!D25 -> 7017901 | F29: ='Income Statement'!E25 -> 4431278 | G29: ='Income Statement'!F25 -> 5121686
B30: Equity | C30: ='Balance Sheet'!B41 -> 56040863 | D30: ='Balance Sheet'!C41 -> 54681275 | E30: ='Balance Sheet'!D41 -> 42402183 | F30: ='Balance Sheet'!E41 -> 33600361 | G30: ='Balance Sheet'!F41 -> 32545236
B31: Total Assets | C31: ='Balance Sheet'!B17 -> 1259328610 | D31: ='Balance Sheet'!C17 -> 992886661 | E31: ='Balance Sheet'!D17 -> 833443027 | F31: ='Balance Sheet'!E17 -> 706666079 | G31: ='Balance Sheet'!F17 -> 662938624
B32: Total Operating Revenue | C32: ='Income Statement'!B5-'Income Statement'!B19 -> 11108547 | D32: ='Income Statement'!C5-'Income Statement'!C19 -> 9966676 | E32: ='Income Statement'!D5-'Income Statement'!D19 -> 3759397 | F32: ='Income Statement'!E5-'Income Statement'!E19 -> 2718437 | G32: ='Income Statement'!F5-'Income Statement'!F19 -> 1053065
B40: Workings
B41: Total income | C41: 41977144 | D41: 40118921 | E41: 29540550 | F41: 24231551 | G41: 22311366 | T41: USE FOR NEXT RATIOS WHEN GIVEN | Z41: 2021 | AA41: 2020 | AB41: 2019 | AC41: 2018 | AD41: 2017
B42: Operating expenses | C42: 21017376 | D42: 20217974 | E42: 18235061 | F42: 16240514 | G42: 14948796 | T42: Return on Equity | U42: 13 | V42: ROE=(Net Income/ Pre-Tax Net Operating Income) * (Pre-Tax Net Operating Income/Total Operating Revenue) * (Total Operating Revenue/Total Assets) * (Total Assets/ TOtal Equity Capital )
B43: Total Assets | C43: 1259328610 | D43: 992886661 | E43: 833443027 | F43: 706666079 | G43: 662938624 | T43: Credit Risk | U43: 14 | V43: Nonperforming Loans/Total Loans | Z43: =C25/C14 -> 0.025121787 | AA43: =D25/D14 -> 0.030347781 | AB43: =E25/E14 -> 0.026794391 | AC43: =F25/F14 -> 0.029126761 | AD43: =G25/G14 -> 0.019300091
T44: Credit Risk | U44: 15 | V44: Net Charge-Offs/Total Loans
T45: Credit Risk | U45: 16 | V45: Provision for LOan Loses/Total Loans
T46: Credit Risk | U46: 17 | V46: Provision for LOan Loses/Equity Capital | Z46: ='Income Statement'!B21/'Balance Sheet'!B41 -> 0.088934105 | AA46: ='Income Statement'!C21/'Balance Sheet'!C41 -> 0.03611377 | AB46: ='Income Statement'!D21/'Balance Sheet'!D41 -> 0.018236679 | AC46: ='Income Statement'!E21/'Balance Sheet'!E41 -> 0.043469027 | AD46: ='Income Statement'!F21/'Balance Sheet'!F41 -> -0.036147595
T47: Credit Risk | U47: 18 | V47: Allowance for Loan Losses/ Toal Loans | Z47: ='Income Statement'!B21/C14 -> 0.010433798 | AA47: ='Income Statement'!C21/D14 -> 0.0049940992 | AB47: ='Income Statement'!D21/E14 -> 0.0020736022 | AC47: ='Income Statement'!E21/F14 -> 0.0042569064 | AD47: ='Income Statement'!F21/G14 -> -0.0045475974
Z48: 2021 | AA48: 2020 | AB48: 2019 | AC48: 2018 | AD48: 2017
V49: (Net Income/ Pre-Tax Net Operating Income) | Z49: ='Income Statement'!B25/'Income Statement'!B23 -> 0.61993418 | AA49: ='Income Statement'!C25/'Income Statement'!C23 -> 0.60874432 | AB49: ='Income Statement'!D25/'Income Statement'!D23 -> 0.67543789 | AC49: ='Income Statement'!E25/'Income Statement'!E23 -> 0.64413213 | AD49: ='Income Statement'!F25/'Income Statement'!F23 -> 0.61369888
V50: (Pre-Tax Net Operating Income/Total Operating Revenue)
V51: (Total Operating Revenue/Total Assets) | Z51: =C32/C31 -> 0.0088210074 | AA51: =D32/D31 -> 0.01003808 | AB51: =E32/E31 -> 0.0045106826 | AC51: =F32/F31 -> 0.003846848 | AD51: =G32/G31 -> 0.0015884804
V52: (Total Assets/ TOtal Equity Capital ) | Z52: ='Balance Sheet'!B17/'Balance Sheet'!B41 -> 22.471613 | AA52: ='Balance Sheet'!C17/'Balance Sheet'!C41 -> 18.157709 | AB52: ='Balance Sheet'!D17/'Balance Sheet'!D41 -> 19.655663 | AC52: ='Balance Sheet'!E17/'Balance Sheet'!E41 -> 21.031503 | AD52: ='Balance Sheet'!F17/'Balance Sheet'!F41 -> 20.369759
Z53: =Z49*Z50*Z51*Z52 -> 0 | AA53: =AA49*AA50*AA51*AA52 -> 0 | AB53: =AB49*AB50*AB51*AB52 -> 0 | AC53: =AC49*AC50*AC51*AC52 -> 0 | AD53: =AD49*AD50*AD51*AD52 -> 0
B56: Market Risk Measures | C56: 2021 | D56: 2020 | E56: 2019 | F56: 2018 | G56: 2017
B57: Book-Value of Assets/Market Value of Assets
B58: Book-Value of Equity/Market Value of Equity | C58: =(C61*C60)/(C60*C59) -> 2.0145322 | D58: =(D61*D60)/(D60*D59) -> 1.8503634 | E58: =(E61*E60)/(E60*E59) -> 1.8085221 | F58: =(F61*F60)/(F60*F59) -> 1.1116221 | G58: =(G61*G60)/(G60*G59) -> 1.3329881
B59: Market Value Per Share | C59: 22.02 | D59: 23.39 | E59: 18.54 | F59: 23.92 | G59: 19.31
B60: Number of Shares Outstanding | C60: 1260260180 | D60: 1260260180 | E60: 1260260180 | F60: 1260260180 | G60: 1260260180
B61: Book Value of Shares | C61: 44.36 | D61: 43.28 | E61: 33.53 | F61: 26.59 | G61: 25.74
B62: Book-Value of Bonds/Market Value of Bonds
...

Sheet Risk Ratios
A1: Credit Risk Ratios
B2: 2021 | C2: 2020 | D2: 2019 | E2: 2018 | F2: 2017 | H2: 2017 | I2: 2018 | J2: 2019 | K2: 2020 | L2: 2021
A3: Nonperforming Loans/Total Loans | B3: 0.025121787 | C3: 0.030347781 | D3: 0.026794391 | E3: 0.029126761 | F3: 0.019300091 | H3: 0.019300091 | I3: 0.029126761 | J3: 0.026794391 | K3: 0.030347781 | L3: 0.025121787
A4: Net Charge-Offs/Total Loans | B4: 0.010433798 | C4: 0.0043921138 | D4: 0.0020736022 | E4: 0.0056125451 | F4: -0.0045475974 | H4: -0.0045475974 | I4: 0.0056125451 | J4: 0.0020736022 | K4: 0.0043921138 | L4: 0.010433798
A5: Provision for loan losses/ Total Loans | B5: 0.012181679 | C5: 0.0059101617 | D5: 0.002319874 | E5: 0.0047825189 | F5: -0.0048996183 | H5: -0.0048996183 | I5: 0.0047825189 | J5: 0.002319874 | K5: 0.0059101617 | L5: 0.012181679
A6: Provision for loan losses/ Equity Capital | B6: 0.088934105 | C6: 0.03611377 | D6: 0.018236679 | E6: 0.043469027 | F6: -0.036147595 | H6: -0.036147595 | I6: 0.043469027 | J6: 0.018236679 | K6: 0.03611377 | L6: 0.088934105
A7: Allowance for loan losses/ Total Loans | B7: 0.0104 | C7: 0.005 | D7: 0.0021 | E7: 0.0043 | F7: -0.0045 | H7: -0.0045 | I7: 0.0043 | J7: 0.0021 | K7: 0.005 | L7: 0.0104
A8: Allowance for Loan Losses / Equity Capital | B8: 0.088934105 | C8: 0.03611377 | D8: 0.018236679 | E8: 0.043469027 | F8: -0.036147595 | H8: -0.036147595 | I8: 0.043469027 | J8: 0.018236679 | K8: 0.03611377 | L8: 0.088934105
A9: Non Perfoming Loans / Equity Capital | B9: 0.45348401 | C9: 0.44510023 | D9: 0.61924149 | E9: 0.77874827 | F9: 0.8220259 | H9: 0.8220259 | I9: 0.77874827 | J9: 0.61924149 | K9: 0.44510023 | L9: 0.45348401
A11: Liquidity Risk Measures
B12: 2021 | C12: 2020 | D12: 2019 | E12: 2018 | F12: 2017 | H12: 2017 | I12: 2018 | J12: 2019 | K12: 2020 | L12: 2021
A13: Purchased Funds / Total Assets | H13: =P33/'Balance Sheet'!H17 -> 0.074132887 | I13: =Q33/'Balance Sheet'!I17 -> 0.029386942 | J13: =R33/'Balance Sheet'!J17 -> 0.026294677 | K13: =S33/'Balance Sheet'!K17 -> 0.030257862 | L13: =T33/'Balance Sheet'!L17 -> 0.040426363
A14: Net Loans/Total Assets | B14: 0.37936327 | C14: 0.39839724 | D14: 0.44759426 | E14: 0.4856215 | F14: 0.39036735 | H14: 0.39036735 | I14: 0.4856215 | J14: 0.44759426 | K14: 0.39839724 | L14: 0.37936327
A15: Cash and Due From Banks/Total Assets | B15: 0.07385053 | C15: 0.082464945 | D15: 0.085123992 | E15: 0.075412075 | F15: 0.071576544 | H15: 0.071576544 | I15: 0.075412075 | J15: 0.085123992 | K15: 0.082464945 | L15: 0.07385053
A16: Cash and Government Securities/Total Assets | B16: 0.49171115 | C16: 0.45446059 | D16: 0.35671874 | E16: 0.36993281 | F16: 0.47395079 | H16: 0.47395079 | I16: 0.36993281 | J16: 0.35671874 | K16: 0.45446059 | L16: 0.49171115
A18: Market Risk Measures
B19: 2021 | C19: 2020 | D19: 2019 | E19: 2018 | F19: 2017 | H19: 2017 | I19: 2018 | J19: 2019 | K19: 2020 | L19: 2021
A20: Book-Value of Assets/Market Value of Assets
A21: Book-Value of Equity/Market Value of Equity | B21: 2.0145322 | C21: 1.8503634 | D21: 1.8085221 | E21: 1.1116221 | F21: 1.3329881 | H21: 1.3329881 | I21: 1.1116221 | J21: 1.8085221 | K21: 1.8503634 | L21: 2.0145322
A22: Book-Value of Bonds/Market Value of Bonds
A24: Interest Rate Risk Measures
B25: 2021 | C25: 2020 | D25: 2019 | E25: 2018 | F25: 2017 | H25: 2017 | I25: 2018 | J25: 2019 | K25: 2020 | L25: 2021
A26: Interest Sensitive Assets/Interest Sensitive Liabilities | B26: 1.3176955 | C26: 1.0580941 | D26: 1.0312515 | E26: 1.0721448 | F26: 1.0173813 | H26: 1.0173813 | I26: 1.0721448 | J26: 1.0312515 | K26: 1.0580941 | L26: 1.3176955
A27: Uninsured Deposits/Total Deposits | B27: 0.60150352 | C27: 0.95457934 | D27: 0.57388257 | E27: 0.54748614 | F27: 0.54793224 | H27: 0.54793224 | I27: 0.54748614 | J27: 0.57388257 | K27: 0.95457934 | L27: 0.60150352
A29: Capital Risk Measures
B30: 2021 | C30: 2020 | D30: 2019 | E30: 2018 | F30: 2017 | H30: 2017 | I30: 2018 | J30: 2019 | K30: 2020 | L30: 2021
A31: Stock Price/Earnings Per Share | B31: 22.02 | C31: 23.39 | D31: 18.54 | E31: 23.92 | F31: 19.31 | H31: 19.31 | I31: 23.92 | J31: 18.54 | K31: 23.39 | L31: 22.02
A32: Equity Capital/Total Assets | B32: 0.044500587 | C32: 0.055073028 | D32: 0.050875923 | E32: 0.04754772 | F32: 0.049092382 | H32: 0.049092382 | I32: 0.04754772 | J32: 0.050875923 | K32: 0.055073028 | L32: 0.044500587 | P32: 2017 | Q32: 2018 | R32: 2019 | S32: 2020 | T32: 2021
A33: Purchased funds/Total liabilties | H33: =P33/'Balance Sheet'!H26 -> 0.077977545 | I33: =Q33/'Balance Sheet'!I26 -> 0.030857715 | J33: =R33/'Balance Sheet'!J26 -> 0.02770912 | K33: =S33/'Balance Sheet'!K26 -> 0.032021377 | L33: =T33/'Balance Sheet'!L26 -> 0.042309145 | O33: Purchased Funds | P33: 49145554 | Q33: 20766755 | R33: 21915115 | S33: 30042628 | T33: 50910076
A34: Equity capital /Risk Assets | B34: 0.090941299 | C34: 0.12161881 | D34: 0.13882527 | E34: 0.12911596 | F34: 0.1033324 | H34: 0.1033324 | I34: 0.12911596 | J34: 0.13882527 | K34: 0.12161881 | L34: 0.090941299
A36: Other Goals in Banking
B37: 2021 | C37: 2020 | D37: 2019 | E37: 2018 | F37: 2017 | G37: Formula | H37: 2017 | I37: 2018 | J37: 2019 | K37: 2020 | L37: 2021
A38: Operating Efficieny ratio | B38: 0.50068618 | C38: 0.50395109 | D38: 0.61728915 | E38: 0.67022181 | F38: 0.6700081 | G38: Total Operating Expenses/Total Operating Revenues | H38: 0.6700081 | I38: 0.67022181 | J38: 0.61728915 | K38: 0.50395109 | L38: 0.50068618
A39: Employee productivity ratio | B39: 1299.2422 | C39: 1417.7327 | D39: 931.49735 | E39: 587.85858 | F39: 652.61035 | G39: (Non Performing Loans/No. of permamanet employees) | H39: 652.61035 | I39: 587.85858 | J39: 931.49735 | K39: 1417.7327 | L39: 1299.2422

Sheet CAMELS
A1: 1. Capital Adequacy | B1: 2021 | C1: 2020 | D1: 2019 | E1: 2018 | F1: 2017 | H1: CAMELS | I1: 2021 | J1: 2020 | K1: 2019 | L1: 2018 | M1: 2017 | N1: 2017 | O1: 2018 | P1: 2019 | Q1: 2020 | R1: 2021
B2: 0.1338 | C2: 0.1548 | D2: 0.1338 | E2: 0.1251 | F2: 0.1209 | H2: Capital Adequacy | I2: 0.2 | J2: 0.2 | K2: 0.2 | L2: 0.2 | M2: 0.2 | N2: 0.2 | O2: 0.2 | P2: 0.2 | Q2: 0.2 | R2: 0.2
A3: Rank | B3: 1 | C3: 1 | D3: 1 | E3: 1 | F3: 1 | H3: Asset Quality | I3: 0.2 | J3: 0.2 | K3: 0.2 | L3: 0.2 | M3: 0.2 | N3: 0.2 | O3: 0.2 | P3: 0.2 | Q3: 0.2 | R3: 0.2
A4: Weight | B4: 0.2 | C4: 0.2 | D4: 0.2 | E4: 0.2 | F4: 0.2 | H4: Management | I4: 1.25 | J4: 1.25 | K4: 1.25 | L4: 1.25 | M4: 1.25 | N4: 1.25 | O4: 1.25 | P4: 1.25 | Q4: 1.25 | R4: 1.25
A5: Rank x Weight | B5: =B4*B3 -> 0.2 | C5: =C4*C3 -> 0.2 | D5: =D4*D3 -> 0.2 | E5: =E4*E3 -> 0.2 | F5: =F4*F3 -> 0.2 | H5: Earnings | I5: =B23+B27 -> 0.9 | J5: =C23+C27 -> 0.75 | K5: =D23+D27 -> 1.05 | L5: =E23+E27 -> 1.2 | M5: =F23+F27 -> 1.05 | N5: 1.05 | O5: 1.2 | P5: 1.05 | Q5: 0.75 | R5: 0.9
H6: Liquidity | I6: =B33+B37 -> 0.1 | J6: =C33+C37 -> 0.1 | K6: =D33+D37 -> 0.1 | L6: =E33+E37 -> 0.1 | M6: =F33+F37 -> 0.1 | N6: 0.1 | O6: 0.1 | P6: 0.1 | Q6: 0.1 | R6: 0.1
A7: 2. Asset Quality | B7: 2021 | C7: 2020 | D7: 2019 | E7: 2018 | F7: 2017 | H7: Sensitivity | I7: 0.5 | J7: 0.5 | K7: 0.5 | L7: 0.5 | M7: 0.5 | N7: 0.5 | O7: 0.5 | P7: 0.5 | Q7: 0.5 | R7: 0.5
B8: 0.0055 | C8: 0.0098 | D8: 0.01 | E8: 0.0045 | F8: 0.0069 | H8: Total | I8: =SUM(I2:I7) -> 3.15 | J8: =SUM(J2:J7) -> 3 | K8: =SUM(K2:K7) -> 3.3 | L8: =SUM(L2:L7) -> 3.45 | M8: =SUM(M2:M7) -> 3.3 | N8: 3.3 | O8: 3.45 | P8: 3.3 | Q8: 3 | R8: 3.15
A9: Rank | B9: 1 | C9: 1 | D9: 1 | E9: 1 | F9: 1
A10: Weight | B10: 0.2 | C10: 0.2 | D10: 0.2 | E10: 0.2 | F10: 0.2 | H10: Average Rating | I10: =AVERAGE(I8:M8) -> 3.24 | N10: =AVERAGE(N8:R8) -> 3.24
A11: Rank x Weight | B11: =B10*B9 -> 0.2 | C11: 0.2 | D11: 0.2 | E11: 0.2 | F11: 0.2
A13: 3. Management | B13: 2021 | C13: 2020 | D13: 2019 | E13: 2018 | F13: 2017
B14: 2.1632 | C14: 1.8622 | D14: 2.5984 | E14: 3.665 | F14: 2.9187
A15: Rank | B15: 5 | C15: 5 | D15: 5 | E15: 5 | F15: 5
A16: Weight | B16: 0.25 | C16: 0.25 | D16: 0.25 | E16: 0.25 | F16: 0.25
A17: Rank x Weight | B17: 1.25 | C17: 1.25 | D17: 1.25 | E17: 1.25 | F17: 1.25
A19: 4. Earnings | B19: 2021 | C19: 2020 | D19: 2019 | E19: 2018 | F19: 2017
A20: Earnings (ROA) | B20: 0.0077 | C20: 0.0109 | D20: 0.0084 | E20: 0.0063 | F20: 0.0077
A21: Rank | B21: 4 | C21: 3 | D21: 4 | E21: 5 | F21: 4
A22: Weight | B22: 0.15 | C22: 0.15 | D22: 0.15 | E22: 0.15 | F22: 0.15
A23: Rank x Weight | B23: 0.6 | C23: 0.45 | D23: 0.6 | E23: 0.75 | F23: 0.6
A24: Earnings (ROE) | B24: 0.1734 | C24: 0.1986 | D24: 0.1655 | E24: 0.1319 | F24: 0.1574
A25: Rank | B25: 2 | C25: 2 | D25: 3 | E25: 3 | F25: 3
A26: Weight | B26: 0.15 | C26: 0.15 | D26: 0.15 | E26: 0.15 | F26: 0.15
A27: Rank x Weight | B27: 0.3 | C27: 0.3 | D27: 0.45 | E27: 0.45 | F27: 0.45
... A33: Rank x Weight | B33: 0.05 | C33: 0.05 | D33: 0.05 | E33: 0.05 | F33: 0.05
A34: 2. Circulating Assets/ Total Assets | B34: =477673022/1259328610 -> 0.37930769 | C34: =395416055/992886661 -> 0.39824893 | D34: =372913863/833433027 -> 0.44744311 | E34: =343107147/706451322 -> 0.48567698 | F34: =258693086/662610675 -> 0.39041491
A35: Rank | B35: 1 | C35: 1 | D35: 1 | E35: 1 | F35: 1
A36: Weight | B36: 0.05 | C36: 0.05 | D36: 0.05 | E36: 0.05 | F36: 0.05
A37: Rank x Weight | B37: 0.05 | C37: 0.05 | D37: 0.05 | E37: 0.05 | F37: 0.05
A39: 6. Sensitivity | B39: 2021 | C39: 2020 | D39: 2019 | E39: 2018 | F39: 2017
B40: 0.4881 | C40: 0.4514 | D40: 0.3649 | E40: 0.3669 | F40: 0.472
A41: Rank | B41: 5 | C41: 5 | D41: 5 | E41: 5 | F41: 5
A42: Weight | B42: 0.1 | C42: 0.1 | D42: 0.1 | E42: 0.1 | F42: 0.1
A43: Rank x Weight | B43: 0.5 | C43: 0.5 | D43: 0.5 | E43: 0.5 | F43: 0.5

Sheet Sheet2
A1: Market Risk Measures | B1: 2021 | C1: 2020 | D1: 2019 | E1: 2018 | F1: 2017
A2: Book-Value of Assets/Market Value of Assets
A3: Book-Value of Equity/Market Value of Equity | B3: 2.0145322 | C3: 1.8503634 | D3: 1.8085221 | E3: 1.1116221 | F3: 1.3329881
A4: Market Value Per Share | B4: 22.02 | C4: 23.39 | D4: 18.54 | E4: 23.92 | F4: 19.31
A5: Number of Shares Outstanding | B5: 1260260180 | C5: 1260260180 | D5: 1260260180 | E5: 1260260180 | F5: 1260260180
A6: Book Value of Shares | B6: 44.36 | C6: 43.28 | D6: 33.53 | E6: 26.59 | F6: 25.74
A7: Book-Value of Bonds/Market Value of Bonds
A8: Intrest Sensitive Assets/Intrest Sensitive Liabilities | B8: 1.3176955 | C8: 1.0580941 | D8: 1.0312515 | E8: 1.0721448 | F8: 1.0173813
A9: Intrest Sensitive Assets | B9: 1222420697 | C9: 956675071 | D9: 786642860 | E9: 667452221 | F9: 633359777
A10: Intrest Sensitive Liabilitis | B10: 927695864 | C10: 904149338 | D10: 762804062 | E10: 622539224 | F10: 622539224
A11: Uninsured Deposits/Total Deposits | B11: 0.60150352 | C11: 0.95457934 | D11: 0.57388257 | E11: 0.54748614 | F11: 0.54793224
A12: Uninsured Deposits | B12: 610784723000 | C12: 755250763000 | D12: 389838134000 | E12: 314057678000 | F12: 288107323000
A13: Total Deposits | B13: 1015430000000 | C13: 791187000000 | D13: 679299486000 | E13: 573635856000 | F13: 525808308000
A14: Stock Price/Earnings Per Share | B14: 2.8597403 | C14: 2.7292882 | D14: 3.3285458 | E14: 6.7954545 | F14: 4.6196172
A15: Stock Price | B15: 22.02 | C15: 23.39 | D15: 18.54 | E15: 23.92 | F15: 19.31
A16: Earnings Per Share | B16: 7.7 | C16: 8.57 | D16: 5.57 | E16: 3.52 | F16: 4.18
