Workbook

Sheet Balance Sheet
A1: Rupees in ‘000 | B1: 2021 | C1: 2020 | D1: 2019 | E1: 2018 | F1: 2017
A3: Assets
A4: Cash and balances with treasury banks | B4: 89432245 | C4: 73651718 | D4: 63039290 | E4: 49187645 | F4: 44239325
A5: Balances with other banks | B5: 3556215 | C5: 8196147 | D5: 7886702 | E5: 4093402 | F5: 3193835
A6: Lendings to financial institutions | B6: – | C6: – | D6: 20405972 | E6: – | F6: 2250000
A7: Investments | B7: 616231172 | C7: 449611987 | D7: 305435633 | E7: 260233987 | F7: 314956748
A8: Advances | B8: 477673022 | C8: 395416055 | D8: 372913863 | E8: 343107147 | F8: 258693086
A9: Fixed assets | B9: 20179222 | C9: 21232750 | D9: 19696568 | E9: 12791827 | F9: 9885958
A10: Intangible assets | B10: 1188985 | C10: 1158857 | D10: 808994 | E10: 741361 | F10: 842869
A11: Deferred tax assets | B11: 5161697 | C11: 1597334 | D11: 2489752 | E11: 3773779 | F11: 100755
A12: Other assets | B12: 45906052 | C12: 42021813 | D12: 40450512 | E12: 32522174 | F12: 28448099
D13: 833208006 | E13: 706451322 | F13: 662610675
A14: Assets attributable to discontinued operations | D14: 315741 | E14: 214757 | F14: 327949
A17: Total Assets | B17: 1259328610 | C17: 992886661 | D17: 833443027 | E17: 706666079 | F17: 662938624
A18: Liabilities
A19: Bills payable | B19: 10235374 | C19: 12629996 | D19: 15768947 | E19: 15512880 | F19: 10769262
A20: Borrowings | B20: 123563761 | C20: 84163669 | D20: 51187681 | E20: 52702323 | F20: 71587311
A21: Deposits and other accounts | B21: 1015162254 | C21: 790982287 | D21: 679246312 | E21: 573596926 | F21: 525805051
A22: Liabilities against assets subject to finance lease | B22: – | C22: – | D22: – | E22: – | F22: –
A23: Subordinated debts | B23: 12000000 | C23: 12000000 | D23: 9992000 | E23: 9993600 | F23: 4992800
A24: Deferred tax liabilities | B24: – | C24: – | D24: – | E24: – | F24: –
A25: Other liabilities | B25: 42326358 | C25: 38429434 | D25: 34704048 | E25: 21178476 | F25: 17098223
A26: Total Liabilites | B26: 1203287747 | C26: 938205386 | D26: =SUM(D19:D25) -> 790898988 | E26: 672984205 | F26: 630252647
A27: Liabilities associated with discontionued operations | B27: – | C27: – | D27: 141856 | E27: 81513 | F27: 140741
D28: =SUM(D26:D27) -> 791040844 | E28: 673065718 | F28: 630393388
A29: Net Assets | B29: 56040863 | C29: 54681275 | D29: 42402183 | E29: 33600361 | F29: 32545236
A30: Represented By
A31: Share capital | B31: 12602602 | C31: 12602602 | D31: 12602602 | E31: 12602602 | F31: 12602602
A32: Reserves | B32: 32832051 | C32: 25701665 | D32: 19408889 | E32: 15588694 | F32: 12032263
A33: Surplus on revaluation of assets - net of tax | B33: 1987976 | C33: 7670955
A34: Continued operations | B34: 8618234 | C34: 8706053 | D34: 4300426 | E34: 1649197 | F34: 5142254
A35: Discontinued operations | D35: 39467 | E35: 5723 | F35: 19877
A36: Unappropriated profit | D36: 6002253 | E36: 3710867 | F36: 2703887
D37: 42353637 | E37: 33557083 | F37: 32500883
A39: Non-controlling interest | B39: – | C39: – | D39: 48546 | E39: 43278 | F39: 44353
A41: Equity Capital | B41: 56040863 | C41: 54681275 | D41: =SUM(D37:D39) -> 42402183 | E41: 33600361 | F41: 32545236
D128: =28736000000/B41 -> 512.76869

Sheet Income Statement
A1: Rupees in ‘000 | B1: 2021 | C1: 2020 | D1: 2019 | E1: 2018 | F1: 2017
A3: Mark-up / return / interest earned | B3: 77,569,443 | C3: 79,118,320 | D3: 71704373 | E3: 43669883 | F3: 36267220
A4: Mark-up / return / interest expenses | B4: 45139897 | C4: 48842539 | D4: 49567851 | E4: 25059925 | F4: 20071958
A5: Net mark-up / interest income | B5: 32429546 | C5: 30275781 | D5: 22136522 | E5: 18609958 | F5: 16195262
A6: Non mark-up / interest income
A7: Fee and commission income | B7: 4785268 | C7: 3991285 | D7: 3616428 | E7: 3116070 | F7: 2706794
A8: Dividend income | B8: 421964 | C8: 273524 | D8: 274440 | E8: 231312 | F8: 302894
A9: Foreign exchange income | B9: 3123524 | C9: 2673493 | D9: 2507707 | E9: 1596027 | F9: 843032
A10: Income / (loss) from derivatives | B10: – | C10: – | D10: – | E10: – | F10: –
A11: Gain on securities | B11: 814724 | C11: 2555400 | D11: 739351 | E11: 260103 | F11: 2063043
A12: Other income | B12: 402118 | C12: 349438 | D12: 266102 | E12: 418081 | F12: 200341
A13: Total non-markup / interest income | B13: 9547598 | C13: 9843140 | D13: 7404028 | E13: 5621593 | F13: 6116104
A14: Total income | B14: 41977144 | C14: 40118921 | D14: 29540550 | E14: 24231551 | F14: 22311366
A15: Non mark-up / interest expenses
A16: Operating expenses | B16: 21017376 | C16: 20217974 | D16: 18235061 | E16: 16240514 | F16: 14948796
A17: Workers’ welfare fund | B17: 213484 | C17: 42982 | D17: 42117 | E17: -540060 | F17: 169833
A18: Total non-markup / interest expenses | B18: 90139 | C18: 48149 | D18: 99947 | E18: 191067 | F18: 23568
B19: 21320999 | C19: 20309105 | D19: 18377125 | E19: 15891521 | F19: 15142197
A20: Profit before provisions | B20: 20656145 | C20: 19809816 | D20: 11163425 | E20: 8340030 | F20: 7169169
A21: Provisions and write offs - net | B21: 4983944 | C21: 1974747 | D21: 773275 | E21: 1460575 | F21: -1176432
A22: Extraordinary / unusual items | B22: – | C22: – | D22: – | E22: – | F22: –
A23: Profit before taxation | B23: 15672201 | C23: 17835069 | D23: 10390150 | E23: 6879455 | F23: 8345601
A24: Taxation | B24: -5956468 | C24: -6978072 | D24: 3372249 | E24: -2448177 | F24: -3223915
A25: Profit after taxation | B25: 9715733 | C25: 10856997 | D25: 7017901 | E25: 4431278 | F25: 5121686
A26: (Loss) / profit after taxation - discontinued operations | D26: 14669 | E26: -2659 | F26: 6611
A27: Attributable to:
A28: Equity holders of the Bank | B28: 9715733 | C28: 10846333 | D28: 7028756 | E28: 4429310 | F28: 5121863
A29: Non-controlling interest | B29: – | C29: 10664 | D29: 3814 | E29: -691 | F29: 6434
B30: 9715733 | C30: 10856997 | D30: =SUM(D28:D29) -> 7032570 | E30: 4428619 | F30: 5128297
A32: Basic and diluted earnings per share | B32: 7.71 | C32: 8.61 | D32: 5.58 | E32: 3.51 | F32: 4.06

Sheet Sheet1
C1: 2021 | D1: 2020 | E1: 2019 | F1: 2018 | G1: 2017
B13: Earning Assets
B14: Loans and Advances | C14: 477673022 | D14: 395416055 | E14: 372913863 | F14: 343107147 | G14: 258693086
B15: Investments | C15: 616231172 | D15: 449611987 | E15: 305435633 | F15: 260233987 | G15: 314956748
B16: Lending to Financial Institutions - Net | C16: 0 | D16: 0 | E16: 20405972 | F16: 0 | G16: 2250000
B17: Balances with other banks | C17: 3556215 | D17: 8196147 | E17: 7886702 | F17: 4093402 | G17: 3193835 | J17: 2021 | K17: 2020 | L17: 2019 | M17: 2018 | N17: 2017
B18: TOTAL EARNING ASSETS | C18: =SUM(C14:C17) -> 1097460409 | D18: =SUM(D14:D17) -> 853224189 | E18: =SUM(E14:E17) -> 706642170 | F18: =SUM(F14:F17) -> 607434536 | G18: =SUM(G14:G17) -> 579093669 | I18: Mark-up / return / interest earned | J18: 77569443 | K18: 79118320 | L18: 71704373 | M18: 43669883 | N18: 36267220
I19: Total non-markup / interest income | J19: 9547598 | K19: 9843140 | L19: 7404028 | M19: 5621593 | N19: 6116104
B20: Interest Bearing Liabilities | I20: Profit after taxation | J20: 9715733 | K20: 10856997 | L20: 7017901 | M20: 4431278 | N20: 5121686
B21: Deposits (less of Current Accounts) | C21: 222888771 | D21: 539726821 | E21: 484456138 | F21: 404040078 | G21: 381975947
B22: Current Account Deposits | C22: 790982287 | D22: 1030588 | E22: 194254257 | F22: 168745407 | G22: 143678468
B23: Current Account Deposits | C23: 1291196 | D23: 250224878 | E23: 535917 | F23: 811441 | G23: 150636
B24: Borrowings | C24: 123563761 | D24: 84163669 | E24: 51187681 | F24: 52702323 | G24: 71587311
B25: Subordinated Debts | C25: 12000000 | D25: 12000000 | E25: 9992000 | F25: 9993600 | G25: 4992800
B26: Lease liability against ROU assets as per IFRS - 16 Leases | C26: 7393878 | D26: 8223995 | E26: 970082 | F26: 0 | G26: 0
B27: Total Interest Bearing Liability | C27: =SUM(C21:C26) -> 1158119893 | D27: =SUM(D21:D26) -> 895369951 | E27: =SUM(E21:E26) -> 741396075 | F27: =SUM(F21:F26) -> 636292849 | G27: =SUM(G21:G26) -> 602385162
B29: Net Income | C29: ='Income Statement'!B25 -> 9715733 | D29: ='Income Statement'!C25 -> 10856997 | E29: ='Income Statement'!D25 -> 7017901 | F29: ='Income Statement'!E25 -> 4431278 | G29: ='Income Statement'!F25 -> 5121686
B30: Equity | C30: ='Balance Sheet'!B41 -> 56040863 | D30: ='Balance Sheet'!C41 -> 54681275 | E30: ='Balance Sheet'!D41 -> 42402183 | F30: ='Balance Sheet'!E41 -> 33600361 | G30: ='Balance Sheet'!F41 -> 32545236
B31: Total Assets | C31: ='Balance Sheet'!B17 -> 1259328610 | D31: ='Balance Sheet'!C17 -> 992886661 | E31: ='Balance Sheet'!D17 -> 833443027 | F31: ='Balance Sheet'!E17 -> 706666079 | G31: ='Balance Sheet'!F17 -> 662938624
B32: Total Operating Revenue | C32: ='Income Statement'!B5-'Income Statement'!B19 -> 11108547 | D32: ='Income Statement'!C5-'Income Statement'!C19 -> 9966676 | E32: ='Income Statement'!D5-'Income Statement'!D19 -> 3759397 | F32: ='Income Statement'!E5-'Income Statement'!E19 -> 2718437 | G32: ='Income Statement'!F5-'Income Statement'!F19 -> 1053065
A34: 2
A35: 3
A36: 4
A37: 5
A38: 6
B40: Workings
B41: Total income | C41: 41977144 | D41: 40118921 | E41: 29540550 | F41: 24231551 | G41: 22311366 | S41: USE FOR NEXT RATIOS WHEN GIVEN | Y41: 2021 | Z41: 2020 | AA41: 2019 | AB41: 2018 | AC41: 2017
B42: Operating expenses | C42: 21017376 | D42: 20217974 | E42: 18235061 | F42: 16240514 | G42: 14948796 | S42: Return on Equity | T42: 13 | U42: ROE=(Net Income/ Pre-Tax Net Operating Income) * (Pre-Tax Net Operating Income/Total Operating Revenue) * (Total Operating Revenue/Total Assets) * (Total Assets/ TOtal Equity Capital )
B43: Total Assets | C43: 1259328610 | D43: 992886661 | E43: 833443027 | F43: 706666079 | G43: 662938624 | S43: Credit Risk | T43: 14 | U43: Nonperforming Loans/Total Loans | Y43: =C25/C14 -> 0.025121787 | Z43: =D25/D14 -> 0.030347781 | AA43: =E25/E14 -> 0.026794391 | AB43: =F25/F14 -> 0.029126761 | AC43: =G25/G14 -> 0.019300091
S44: Credit Risk | T44: 15 | U44: Net Charge-Offs/Total Loans
S45: Credit Risk | T45: 16 | U45: Provision for LOan Loses/Total Loans
S46: Credit Risk | T46: 17 | U46: Provision for LOan Loses/Equity Capital | Y46: ='Income Statement'!B21/'Balance Sheet'!B41 -> 0.088934105 | Z46: ='Income Statement'!C21/'Balance Sheet'!C41 -> 0.03611377 | AA46: ='Income Statement'!D21/'Balance Sheet'!D41 -> 0.018236679 | AB46: ='Income Statement'!E21/'Balance Sheet'!E41 -> 0.043469027 | AC46: ='Income Statement'!F21/'Balance Sheet'!F41 -> -0.036147595
S47: Credit Risk | T47: 18 | U47: Allowance for Loan Losses/ Toal Loans | Y47: ='Income Statement'!B21/C14 -> 0.010433798 | Z47: ='Income Statement'!C21/D14 -> 0.0049940992 | AA47: ='Income Statement'!D21/E14 -> 0.0020736022 | AB47: ='Income Statement'!E21/F14 -> 0.0042569064 | AC47: ='Income Statement'!F21/G14 -> -0.0045475974
Y48: 2021 | Z48: 2020 | AA48: 2019 | AB48: 2018 | AC48: 2017
U49: (Net Income/ Pre-Tax Net Operating Income) | Y49: ='Income Statement'!B25/'Income Statement'!B23 -> 0.61993418 | Z49: ='Income Statement'!C25/'Income Statement'!C23 -> 0.60874432 | AA49: ='Income Statement'!D25/'Income Statement'!D23 -> 0.67543789 | AB49: ='Income Statement'!E25/'Income Statement'!E23 -> 0.64413213 | AC49: ='Income Statement'!F25/'Income Statement'!F23 -> 0.61369888
U50: (Pre-Tax Net Operating Income/Total Operating Revenue)
U51: (Total Operating Revenue/Total Assets) | Y51: =C32/C31 -> 0.0088210074 | Z51: =D32/D31 -> 0.01003808 | AA51: =E32/E31 -> 0.0045106826 | AB51: =F32/F31 -> 0.003846848 | AC51: =G32/G31 -> 0.0015884804
U52: (Total Assets/ TOtal Equity Capital ) | Y52: ='Balance Sheet'!B17/'Balance Sheet'!B41 -> 22.471613 | Z52: ='Balance Sheet'!C17/'Balance Sheet'!C41 -> 18.157709 | AA52: ='Balance Sheet'!D17/'Balance Sheet'!D41 -> 19.655663 | AB52: ='Balance Sheet'!E17/'Balance Sheet'!E41 -> 21.031503 | AC52: ='Balance Sheet'!F17/'Balance Sheet'!F41 -> 20.369759
Y53: =Y49*Y50*Y51*Y52 -> 0 | Z53: =Z49*Z50*Z51*Z52 -> 0 | AA53: =AA49*AA50*AA51*AA52 -> 0 | AB53: =AB49*AB50*AB51*AB52 -> 0 | AC53: =AC49*AC50*AC51*AC52 -> 0
B56: Market Risk Measures | C56: 2021 | D56: 2020 | E56: 2019 | F56: 2018 | G56: 2017
...

Sheet Profitability Ratios
A1: Pr | C1: PROFITABILITY RATIOS
E2: 2021 | F2: 2020 | G2: 2019 | H2: 2018 | I2: 2017
D3: Formula
C4: Return on Equity (ROE) | D4: Net income/Total equity | E4: =SUM(M27/M28) -> 0.17336873 | F4: =SUM(N27/N28) -> 0.19855055 | G4: =SUM(O27/O28) -> 0.16550801 | H4: =SUM(P27/P28) -> 0.13188186 | I4: =SUM(Q27/Q28) -> 0.1573713
C5: Return on Assets (ROA) | D5: Net income/Total Asset | E5: =M27/M29 -> 0.0077150101 | F5: =N27/N29 -> 0.01093478 | G5: =O27/O29 -> 0.0084203728 | H5: =P27/P29 -> 0.0062706816 | I5: =Q27/Q29 -> 0.0077257318
C6: Net Interest Margin | D6: (Interest income-Interest expense)/Total Assets | E6: =SUM(M32-M33)/M29 -> 0.0088210074 | F6: =SUM(N32-N33)/N29 -> 0.01003808 | G6: =SUM(O32-O33)/O29 -> 0.0045106826 | H6: =SUM(P32-P33)/P29 -> 0.003846848 | I6: =SUM(Q32-Q33)/Q29 -> 0.0015884804
C7: Net non Interest Margin | D7: (Non interest revenue-PLLL-Non interest expense)/Total Assets | E7: =SUM(M34-M35-M36)/M29 -> 0.0035523016 | F7: =SUM(N34-N35-N36)/N29 -> 0.0078762706 | G7: =SUM(O34-O35-O36)/O29 -> 0.0078359357 | H7: =SUM(P34-P35-P36)/P29 -> 0.0056178599 | I7: =SUM(Q34-Q35-Q36)/Q29 -> 0.010964768
C8: NOM(Net Operating Margin) | D8: Net Operating Revenue/Total Assets | E8: =SUM(M31-M30)/M29 -> 0.016643605 | F8: =SUM(N31-N30)/N29 -> 0.020043523 | G8: =SUM(O31-O30)/O29 -> 0.013564801 | H8: =SUM(P31-P30)/P29 -> 0.011308081 | I8: =SUM(Q31-Q30)/Q29 -> 0.01110596
C9: Earning Per Share | D9: NI/Total Shares Outstanding | E9: 7.71 | F9: 8.61 | G9: 5.58 | H9: 3.51 | I9: 4.06
C10: Earning Spread | D10: (Total Interest Income/Total Earning Assets-Total Interest Expense/Total Interest Bearing Liability | E10: =(79118320/E12)-(E13/E14) -> 0.045146994 | F10: =(77569443/F12)-(F13/F14) -> 0.055620083 | G10: =(71704373/G12)-(G13/G14) -> 0.062643854 | H10: =(43669883/H12)-(H13/H14) -> 0.034260092 | I10: =(36267220/I12)-(I13/I14) -> 0.026674581
C11: Total Interest Income | E11: 77,569,443 | F11: 79,118,320 | G11: 71704373 | H11: 43669883 | I11: 36267220
C12: Total Earning Asset | E12: 1154362175 | F12: 900147871 | G12: 754485153 | H12: 646435135 | I12: 609263684
C13: Total Interest Expense | E13: 21320999 | F13: 20309105 | G13: 18377125 | H13: 15891521 | I13: 15142197
C14: Total Interest Bearing Liability | E14: 911482373 | F14: 664694832 | G14: 567306696 | H14: 477296785 | I14: 460925390
C16: Return on Equity (ROE) | D16: NPM*EM*AU | E16: =Sheet1!C88*Sheet1!C89*Sheet1!C90 -> 0.17336873 | F16: =Sheet1!D88*Sheet1!D89*Sheet1!D90 -> 0.19855055 | G16: =Sheet1!E88*Sheet1!E89*Sheet1!E90 -> 0.16550801 | H16: =Sheet1!F88*Sheet1!F89*Sheet1!F90 -> 0.13188186 | I16: =Sheet1!G88*Sheet1!G89*Sheet1!G90 -> 0.1573713 | M16: 291805374 | N16: 273510554 | O16: 223592292 | P16: 195687420 | Q16: 169327257
C17: ROA = Net Profit Margin*Asset Utilization | D17: Net income/Total Asset | E17: =SUM(M27/M29) -> 0.0077150101 | F17: =SUM(N27/N29) -> 0.01093478 | G17: =SUM(O27/O29) -> 0.0084203728 | H17: =SUM(P27/P29) -> 0.0062706816 | I17: =SUM(Q27/Q29) -> 0.0077257318 | L17: Total Interest bearing liablity | M17: ='Balance Sheet'!B26-'Profitability Ratios'!M16 -> 911482373 | N17: ='Balance Sheet'!C26-'Profitability Ratios'!N16 -> 664694832 | O17: ='Balance Sheet'!D26-'Profitability Ratios'!O16 -> 567306696 | P17: ='Balance Sheet'!E26-'Profitability Ratios'!P16 -> 477296785 | Q17: ='Balance Sheet'!F26-'Profitability Ratios'!Q16 -> 460925390
C18: Equity Multiplier | D18: Total Assets/Total Equity | E18: =Sheet1!C31/Sheet1!C30 -> 22.471613 | F18: =Sheet1!D31/Sheet1!D30 -> 18.157709 | G18: =Sheet1!E31/Sheet1!E30 -> 19.655663 | H18: =P29/P28 -> 21.031503 | I18: =Q29/Q28 -> 20.369759
C19: Net Profit Margin | D19: NI/Total OP Revenues | E19: =Sheet1!J20/(Sheet1!J18+Sheet1!J19) -> 0.11152506 | F19: =Sheet1!K20/(Sheet1!K18+Sheet1!K19) -> 0.12204158 | G19: =Sheet1!L20/(Sheet1!L18+Sheet1!L19) -> 0.088712462 | H19: =Sheet1!M20/(Sheet1!M18+Sheet1!M19) -> 0.089899479 | I19: =Sheet1!N20/(Sheet1!N18+Sheet1!N19) -> 0.12084201
C20: Asset Utilization | D20: Total OP Revenues/Total Assets | E20: =Sheet1!C32/Sheet1!C31 -> 0.0088210074 | F20: =Sheet1!D32/Sheet1!D31 -> 0.01003808 | G20: =Sheet1!E32/Sheet1!E31 -> 0.0045106826 | H20: =Sheet1!F32/Sheet1!F31 -> 0.003846848 | I20: =Sheet1!G32/Sheet1!G31 -> 0.0015884804
C22: Return on Equity (ROE) | D22: Expense Control Efficiency*Tax Management Efficiency*Asset Mangement Efficiency*Funds Management Efficiency | E22: =E23*E24*E25*E26 -> 0.17336873 | F22: =F23*F24*F25*F26 -> 0.19855055 | G22: =G23*G24*G25*G26 -> 0.16550801 | H22: =H23*H24*H25*H26 -> 0.13188186 | I22: =I23*I24*I25*I26 -> 0.1573713 | M22: 104966435 | N22: 92738790 | O22: 78957874 | P22: 60230944 | Q22: 53674940
C23: Tax management efficiency | D23: Net Income/Pre-Tax Net Operating Income | E23: =Sheet1!C29/'Income Statement'!B23 -> 0.61993418 | F23: =Sheet1!D29/'Income Statement'!C23 -> 0.60874432 | G23: =Sheet1!E29/'Income Statement'!D23 -> 0.67543789 | H23: =Sheet1!F29/'Income Statement'!E23 -> 0.64413213 | I23: =Sheet1!G29/'Income Statement'!F23 -> 0.61369888 | L23: Total Earning Assets | M23: ='Balance Sheet'!B17-'Profitability Ratios'!M22 -> 1154362175 | N23: ='Balance Sheet'!C17-'Profitability Ratios'!N22 -> 900147871 | O23: ='Balance Sheet'!D17-'Profitability Ratios'!O22 -> 754485153 | P23: ='Balance Sheet'!E17-'Profitability Ratios'!P22 -> 646435135 | Q23: ='Balance Sheet'!F17-'Profitability Ratios'!Q22 -> 609263684
C24: Expense control efficiency | D24: Pre-Tax Net Operating Income/ Total Operating Revenue | E24: ='Income Statement'!B23/Sheet1!C32 -> 1.4108237 | F24: ='Income Statement'!C23/Sheet1!D32 -> 1.7894701 | G24: ='Income Statement'!D23/Sheet1!E32 -> 2.763781 | H24: ='Income Statement'!E23/Sheet1!F32 -> 2.5306656 | I24: ='Income Statement'!F23/Sheet1!G32 -> 7.9250578
C25: Asset management efficiency | D25: Total Operating Revenue/ Total Assets | E25: =Sheet1!C32/Sheet1!C31 -> 0.0088210074 | F25: =Sheet1!D32/Sheet1!D31 -> 0.01003808 | G25: =Sheet1!E32/Sheet1!E31 -> 0.0045106826 | H25: =Sheet1!F32/Sheet1!F31 -> 0.003846848 | I25: =Sheet1!G32/Sheet1!G31 -> 0.0015884804
C26: Funds management efficiency | D26: Total Assets/Total Equity Capital | E26: =M29/M28 -> 22.471613 | F26: =N29/N28 -> 18.157709 | G26: =O29/O28 -> 19.655663 | H26: =P29/P28 -> 21.031503 | I26: =Q29/Q28 -> 20.369759 | M26: 2021 | N26: 2020 | O26: 2019 | P26: 2018 | Q26: 2017
L27: Profit after taxation | M27: 9715733 | N27: 10856997 | O27: 7017901 | P27: 4431278 | Q27: 5121686
L28: Equity Capital | M28: 56040863 | N28: 54681275 | O28: 42402183 | P28: 33600361 | Q28: 32545236
L29: Total Assets | M29: 1259328610 | N29: 992886661 | O29: 833443027 | P29: 706666079 | Q29: 662938624
L30: Operating expenses | M30: 21017376 | N30: 20217974 | O30: 18235061 | P30: 16240514 | Q30: 14948796
L31: Total income | M31: 41977144 | N31: 40118921 | O31: 29540550 | P31: 24231551 | Q31: 22311366
L32: Net mark-up / interest income | M32: 32429546 | N32: 30275781 | O32: 22136522 | P32: 18609958 | Q32: 16195262
L33: Interest expense | M33: 21320999 | N33: 20309105 | O33: 18377125 | P33: 15891521 | Q33: 15142197
L34: Total non-markup / interest income | M34: 9547598 | N34: 9843140 | O34: 7404028 | P34: 5621593 | Q34: 6116104
L35: Total non-markup / interest expenses | M35: 90139 | N35: 48149 | O35: 99947 | P35: 191067 | Q35: 23568
L36: Provisions and write offs - net | M36: 4983944 | N36: 1974747 | O36: 773275 | P36: 1460575 | Q36: -1176432
L37: Total expenses | M37: 21320999 | N37: 20309105 | O37: 18377125 | P37: 15891521 | Q37: 15142197
L38: total operating revenve | M38: =SUM(M32-M37) -> 11108547 | N38: =SUM(N32-N37) -> 9966676 | O38: =SUM(O32-O37) -> 3759397 | P38: =SUM(P32-P37) -> 2718437 | Q38: =SUM(Q32-Q37) -> 1053065

Sheet Risk Ratios
A1: Credit Risk Ratios
C2: 2021 | D2: 2020 | E2: 2019 | F2: 2018 | G2: 2017
A3: Nonperforming Loans/Total Loans | C3: =B25/B26 -> 0.065244059 | D3: =C25/C26 -> 0.07267383 | E3: =D25/D26 -> 0.075438514 | F3: =E25/E26 -> 0.077693182 | G3: =F25/F26 -> 0.10341609
A4: Net Charge-Offs/Total Loans | C4: =B27/B26 -> 0.010433798 | D4: =C27/C26 -> 0.0049940992 | E4: =D27/D26 -> 0.0020734617 | F4: =E27/E26 -> 0.0042569064 | G4: =F27/F26 -> -0.0045475974
A5: Provision for loan losses/ Total Loans | C5: =B28/B26 -> 0.059703874 | D5: =C28/C26 -> 0.062771662 | E5: =D28/D26 -> 0.065447829 | F5: =E28/E26 -> 0.073193372 | G5: =F28/F26 -> 0.10903794
A6: Provision for loan losses/ Equity Capital | C6: =B28/B30 -> 0.50889527 | D6: =C28/C30 -> 0.45391998 | E6: =D28/D30 -> 0.57563206 | F6: =E28/E30 -> 0.74740771 | G6: =F28/F30 -> 0.86671244
A7: Allowance for loan losses/ Total Loans | C7: =B31/B26 -> 0.063282234 | D7: =C31/C26 -> 0.066881579 | E7: =D31/D26 -> 0.068737621 | F7: =E31/E26 -> 0.076220575 | G7: =F31/F26 -> 0.099139039
A8: Allowance for Loan Losses / Equity Capital | C8: =B31/B30 -> 0.53939598 | D8: =C31/C30 -> 0.48363997 | E8: =D31/D30 -> 0.6045667 | F8: =E31/E30 -> 0.77831973 | G8: =F31/F30 -> 0.78802882
A9: Non Perfoming Loans / Equity Capital | C9: =B25/B30 -> 0.5561179 | D9: =C25/C30 -> 0.5255254 | E9: =D25/D30 -> 0.66350294 | F9: =E25/E30 -> 0.79335713 | G9: =F25/F30 -> 0.8220259
A11: Liquidity Risk Measures
C12: 2021 | D12: 2020 | E12: 2019 | F12: 2018 | G12: 2017
A13: Purchased Funds / Total Assets | C13: =B29/B32 -> 0.040426363 | D13: =C29/C32 -> 0.030257862 | E13: =D29/D32 -> 0.026294677 | F13: =E29/E32 -> 0.029386942 | G13: =F29/F32 -> 0.074132887
A14: Net Loans/Total Assets | C14: =B26/B32 -> 0.37930769 | D14: =C26/C32 -> 0.39824893 | E14: =D26/D32 -> 0.44746805 | F14: =E26/E32 -> 0.48552939 | G14: =F26/F32 -> 0.39022177
A15: Cash and Due From Banks/Total Assets | C15: =B33/B32 -> 0.073839711 | D15: =C33/C32 -> 0.082434248 | E15: =D33/D32 -> 0.085099988 | F15: =E33/E32 -> 0.075397771 | G15: =F33/F32 -> 0.071549851
A16: Cash and Government Securities/Total Assets | C16: =B34/B32 -> 0.49163911 | D16: =C34/C32 -> 0.45429142 | E16: =D34/D32 -> 0.35661815 | F16: =E34/E32 -> 0.36986264 | G16: =F34/F32 -> 0.47377404
A18: Market Risk Measures
C19: 2021 | D19: 2020 | E19: 2019 | F19: 2018 | G19: 2017
A20: Book-Value of Assets/Market Value of Assets | C20: =B61/B60 -> 1.0864372 | D20: =C61/C60 -> 1.1306289 | E20: =D61/D60 -> 1.0689497 | F20: =E61/E60 -> 1.0174415 | G20: =F61/F60 -> 1.0644903
A21: Book-Value of Equity/Market Value of Equity | C21: =B37/B40 -> 2.0145322 | D21: =C37/C40 -> 1.8503634 | E21: =D37/D40 -> 1.8085221 | F21: =E37/E40 -> 1.1116221 | G21: =F37/F40 -> 1.3329881
A24: Workings | B24: 2021 | C24: 2020 | D24: 2019 | E24: 2018 | F24: 2017 | H24: Workings | I24: 2021 | J24: 2020 | K24: 2019 | L24: 2018 | M24: 2017
A25: Non Performing Loans | B25: 31165327 | C25: 28736399 | D25: 28133973 | E25: 26657086 | F25: 26753027 | H25: Interest Sensitive Assets | I25: 1222420697 | J25: 956675071 | K25: 786642860 | L25: 667452221 | M25: 633359777
A26: Net Loans | B26: 477673022 | C26: 395416055 | D26: 372939122 | E26: 343107147 | F26: 258693086 | H26: Interest Sensitive Liabilities | I26: 927695864 | J26: 904149338 | K26: 762804062 | L26: 622539224 | M26: 622539224
A27: Provisions and write offs - net (Charge Offs) | B27: 4983944 | C27: 1974747 | D27: 773275 | E27: 1460575 | F27: -1176432 | H27: Uninsured Deposits | I27: 610784723000 | J27: 755250763000 | K27: 389838134000 | L27: 314057678000 | M27: 288107323000
A28: Proviison for Loan Losses | B28: 28518930 | C28: 24820923 | D28: 24408056 | E28: 25113169 | F28: 28207361 | H28: Total Deposits | I28: 1015430000000 | J28: 791187000000 | K28: 679299486000 | L28: 573635856000 | M28: 525808308000
A29: Purchased Funds | B29: 50910076 | C29: 30042628 | D29: 21915115 | E29: 20766755 | F29: 49145554 | H29: Stock Price | I29: 22.02 | J29: 23.39 | K29: 18.54 | L29: 23.92 | M29: 19.31
A30: Equity Capital | B30: 56040863 | C30: 54681275 | D30: 42402183 | E30: 33600361 | F30: 32545236 | H30: Earnings Per Share | I30: 7.7 | J30: 8.57 | K30: 5.57 | L30: 3.52 | M30: 4.18
A31: Allowance for loan losses | B31: 30228216 | C31: 26446050 | D31: 25634948 | E31: 26151824 | F31: 25646584 | H31: Equity Capital | I31: 56040863 | J31: 54681275 | K31: 42402183 | L31: 33600361 | M31: 32545236
A32: Total Assets | B32: 1259328610 | C32: 992886661 | D32: 833443027 | E32: 706666079 | F32: 662938624 | H32: Total Assets | I32: 1259328610 | J32: 992886661 | K32: 833443027 | L32: 706666079 | M32: 662938624
A33: Cash and Due From Banks | B33: =89432245+3556215 -> 92988460 | C33: =73651718+8196147 -> 81847865 | D33: =63039290+7886702 -> 70925992 | E33: =49187645+4093402 -> 53281047 | F33: =44239325+3193835 -> 47433160 | H33: Purchased Funds | I33: 50910076 | J33: 30042628 | K33: 21915115 | L33: 20766755 | M33: 49145554
A34: Cash and Government Securities | B34: =593924897+25210301 -> 619135198 | C34: =429738711+21321177 -> 451059888 | D34: =284916148+12304760 -> 297220908 | E34: =249064623+12304760 -> 261369383 | F34: =10995031+303088077 -> 314083108 | H34: Total Liabilites | I34: 1203287747 | J34: 938205386 | K34: 790898988 | L34: 672984205 | M34: 630252647
A35: Number of Shares Outstanding | B35: 1260260180 | C35: 1260260180 | D35: 1260260180 | E35: 1260260180 | F35: 1260260180 | H35: Equity Capital | I35: 56040863 | J35: 54681275 | K35: 42402183 | L35: 33600361 | M35: 32545236
A36: Book Value of Shares | B36: 44.36 | C36: 43.28 | D36: 33.53 | E36: 26.59 | F36: 25.74 | H36: Investments | I36: 616231172 | J36: 449611987 | K36: 305435633 | L36: 260233987 | M36: 314956748
A37: Book Value of Equity | B37: =B36*B35 -> 5.5905142e+10 | C37: =C36*C35 -> 5.4544061e+10 | D37: =D36*D35 -> 4.2256524e+10 | E37: =E36*E35 -> 3.3510318e+10 | F37: =F36*F35 -> 3.2439097e+10 | H37: Total income | I37: 41977144 | J37: 40118921 | K37: 29540550 | L37: 24231551 | M37: 22311366
A38: Market Value Per Share | B38: 22.02 | C38: 23.39 | D38: 18.54 | E38: 23.92 | F38: 19.31 | H38: Operating expenses | I38: 21017376 | J38: 20217974 | K38: 18235061 | L38: 16240514 | M38: 14948796
A39: Number of Shares Outstanding | B39: 1260260180 | C39: 1260260180 | D39: 1260260180 | E39: 1260260180 | F39: 1260260180 | H39: No of Employees | I39: 7478 | J39: 7658 | K39: 7534 | L39: 7538 | M39: 7848
A40: Market Value of Equity | B40: =B38*B39 -> 2.7750929e+10 | C40: =C38*C39 -> 2.9477486e+10 | D40: =D38*D39 -> 2.3365224e+10 | E40: =E38*E39 -> 3.0145424e+10 | F40: =F38*F39 -> 2.4335624e+10 | H40: Non Performing Loans | I40: 9715733 | J40: 10856997 | K40: 7017901 | L40: 4431278 | M40: 5121686
A42: Interest Rate Risk Measures
C43: 2021 | D43: 2020 | E43: 2019 | F43: 2018 | G43: 2017
A44: Interest Sensitive Assets/Interest Sensitive Liabilities | C44: =I25/I26 -> 1.3176955 | D44: =J25/J26 -> 1.0580941 | E44: =K25/K26 -> 1.0312515 | F44: =L25/L26 -> 1.0721448 | G44: =M25/M26 -> 1.0173813
A45: Uninsured Deposits/Total Deposits | C45: =I27/I28 -> 0.60150352 | D45: =J27/J28 -> 0.95457934 | E45: =K27/K28 -> 0.57388257 | F45: =L27/L28 -> 0.54748614 | G45: =M27/M28 -> 0.54793224
...

Sheet CAMELS
A1: 1. Capital Adequacy | B1: 2021 | C1: 2020 | D1: 2019 | E1: 2018 | F1: 2017 | H1: CAMELS | I1: 2021 | J1: 2020 | K1: 2019 | L1: 2018 | M1: 2017 | N1: 2017 | O1: 2018 | P1: 2019 | Q1: 2020 | R1: 2021
B2: 0.1338 | C2: 0.1548 | D2: 0.1338 | E2: 0.1251 | F2: 0.1209 | H2: Capital Adequacy | I2: 0.2 | J2: 0.2 | K2: 0.2 | L2: 0.2 | M2: 0.2 | N2: 0.2 | O2: 0.2 | P2: 0.2 | Q2: 0.2 | R2: 0.2
A3: Rank | B3: 1 | C3: 1 | D3: 1 | E3: 1 | F3: 1 | H3: Asset Quality | I3: 0.2 | J3: 0.2 | K3: 0.2 | L3: 0.2 | M3: 0.2 | N3: 0.2 | O3: 0.2 | P3: 0.2 | Q3: 0.2 | R3: 0.2
A4: Weight | B4: 0.2 | C4: 0.2 | D4: 0.2 | E4: 0.2 | F4: 0.2 | H4: Management | I4: 1.25 | J4: 1.25 | K4: 1.25 | L4: 1.25 | M4: 1.25 | N4: 1.25 | O4: 1.25 | P4: 1.25 | Q4: 1.25 | R4: 1.25
A5: Rank x Weight | B5: =B3*B4 -> 0.2 | C5: =C3*C4 -> 0.2 | D5: =D3*D4 -> 0.2 | E5: =E3*E4 -> 0.2 | F5: =F3*F4 -> 0.2 | H5: Earnings | I5: =B16+B20 -> 0.25771501 | J5: =C16+C20 -> 0.26093478 | K5: =D16+D20 -> 0.25842037 | L5: =E16+E20 -> 0.25627068 | M5: =F16+F20 -> 0.25772573 | N5: 1.05 | O5: 1.2 | P5: 1.05 | Q5: 0.75 | R5: 0.9
H6: Liquidity | I6: =B26+B30 -> 0.6203308 | J6: =C26+C30 -> 0.64972257 | K6: =D26+D30 -> 0.69896886 | L6: =E26+E30 -> 0.74812669 | M6: =F26+F30 -> 0.64199137 | N6: 0.1 | O6: 0.1 | P6: 0.1 | Q6: 0.1 | R6: 0.1
A7: 2. Asset Quality | B7: 2021 | C7: 2020 | D7: 2019 | E7: 2018 | F7: 2017 | H7: Sensitivity | I7: 0.5 | J7: 0.5 | K7: 0.5 | L7: 0.5 | M7: 0.5 | N7: 0.5 | O7: 0.5 | P7: 0.5 | Q7: 0.5 | R7: 0.5
B8: =(Y75-Y76)/Y74 -> 0.0055401852 | C8: =(Z75-Z76)/Z74 -> 0.0098486669 | D8: =(AA75-AA76)/AA74 -> 0.0099913609 | E8: =(AB75-AB76)/AB74 -> 0.0044998101 | F8: =(AC75-AC76)/AC74 -> 0.0069230996 | H8: Total | I8: =SUM(I2:I7) -> 3.0280458 | J8: =SUM(J2:J7) -> 3.0606573 | K8: =SUM(K2:K7) -> 3.1073892 | L8: =SUM(L2:L7) -> 3.1543974 | M8: =SUM(M2:M7) -> 3.0497171 | N8: =SUM(N2:N7) -> 3.3 | O8: =SUM(O2:O7) -> 3.45 | P8: =SUM(P2:P7) -> 3.3 | Q8: =SUM(Q2:Q7) -> 3 | X8: =SUM(X2:X7) -> 0 | Y8: =SUM(Y2:Y7) -> 0 | Z8: =SUM(Z2:Z7) -> 0 | AA8: =SUM(AA2:AA7) -> 0 | AB8: =SUM(AB2:AB7) -> 0 | AC8: =SUM(AC2:AC7) -> 0
A9: Rank | B9: 1 | C9: 1 | D9: 1 | E9: 1 | F9: 1 | X9: =SUM(R2:R7) -> 3.15 | Y9: =SUM(S2:S7) -> 0 | Z9: =SUM(T2:T7) -> 0 | AA9: =SUM(U2:U7) -> 0 | AB9: =SUM(V2:V7) -> 0 | AC9: =SUM(W2:W7) -> 0
A10: Weight | B10: 0.2 | C10: 0.2 | D10: 0.2 | E10: 0.2 | F10: 0.2 | H10: Avreage Rating | I10: =AVERAGE(I8:M8) -> 3.0800414
A11: Rank x Weight | B11: =B9*B10 -> 0.2 | C11: =C9*C10 -> 0.2 | D11: =D9*D10 -> 0.2 | E11: =E9*E10 -> 0.2 | F11: =F9*F10 -> 0.2
Y12: 2021 | Z12: 2020 | AA12: 2019 | AB12: 2018 | AC12: 2017
A13: 3. Management | B13: 2021 | C13: 2020 | D13: 2019 | E13: 2018 | F13: 2017 | X13: Admin Exp | Y13: 21017376 | Z13: 20217974 | AA13: 18235061 | AB13: 16240514 | AC13: 14948796
B14: =Y13/Y14 -> 2.1632311 | C14: =Z13/Z14 -> 1.8622068 | D14: =AA13/AA14 -> 2.598364 | E14: =AB13/AB14 -> 3.6649729 | F14: =AC13/AC14 -> 2.9187256 | X14: NI | Y14: 9715733 | Z14: 10856997 | AA14: 7017901 | AB14: 4431278 | AC14: 5121686
A15: Rank | B15: 5 | C15: 5 | D15: 5 | E15: 5 | F15: 5 | X15: Management
A16: Weight | B16: 0.25 | C16: 0.25 | D16: 0.25 | E16: 0.25 | F16: 0.25
A17: Rank x Weight | B17: =B15*B16 -> 1.25 | C17: =C15*C16 -> 1.25 | D17: =D15*D16 -> 1.25 | E17: =E15*E16 -> 1.25 | F17: =F15*F16 -> 1.25 | Y17: 2021 | Z17: 2020 | AA17: 2019 | AB17: 2018 | AC17: 2017
Q18: - | X18: Investments | Y18: 616231172 | Z18: 449611987 | AA18: 305435633 | AB18: 260233987 | AC18: 314956748
A19: 4. Earnings | B19: 2021 | C19: 2020 | D19: 2019 | E19: 2018 | F19: 2017 | X19: Unit of Mutual Funds | Y19: 1510245 | Z19: 1436420 | AA19: 1272261 | AB19: 971446 | AC19: 1652135
A20: 1. Earnings (ROA) | B20: =Sheet1!C78 -> 0.0077150101 | C20: =Sheet1!D78 -> 0.01093478 | D20: =Sheet1!E78 -> 0.0084203728 | E20: =Sheet1!F78 -> 0.0062706816 | F20: =Sheet1!G78 -> 0.0077257318
A21: Rank | B21: 4 | C21: 3 | D21: 4 | E21: 5 | F21: 4 | Q21: -
A22: Weight | B22: 0.15 | C22: 0.15 | D22: 0.15 | E22: 0.15 | F22: 0.15 | X22: Commercial Paper | Y22: - | Z22: - | AA22: - | AB22: - | AC22: 375075
A23: Rank * Weight | B23: =B21*B22 -> 0.6 | C23: =C21*C22 -> 0.45 | D23: =D21*D22 -> 0.6 | E23: =E21*E22 -> 0.75 | F23: =F21*F22 -> 0.6 | X23: Total Securities | Y23: =Y18-Y19 -> 614720927 | Z23: =Z18-Z19 -> 448175567 | AA23: =AA18-AA19 -> 304163372 | AB23: =AB18-AB19 -> 259262541 | AC23: =AC18-AC19-AC22 -> 312929538
A24: 2. Earnings (ROE) | B24: =Sheet1!C77 -> 0.17336873 | C24: =Sheet1!D77 -> 0.19855055 | D24: =Sheet1!E77 -> 0.16550801 | E24: =Sheet1!F77 -> 0.13188186 | F24: =Sheet1!G77 -> 0.1573713 | X24: Total Assets | Y24: 1259328610 | Z24: 992886661 | AA24: 833443027 | AB24: 706666079 | AC24: 662938624
A25: Rank | B25: 2 | C25: 2 | D25: 3 | E25: 3 | F25: 3
A26: Weight | B26: 0.15 | C26: 0.15 | D26: 0.15 | E26: 0.15 | F26: 0.15
A27: Rank x weight | B27: =B25*B26 -> 0.3 | C27: =C25*C26 -> 0.3 | D27: =D25*D26 -> 0.45 | E27: =E25*E26 -> 0.45 | F27: =F25*F26 -> 0.45
AN28: 2021 | AO28: 2020 | AP28: 2019 | AQ28: 2018 | AR28: 2017
A29: 5. Liquidity | B29: 2021 | C29: 2020 | D29: 2019 | E29: 2018 | F29: 2017 | AM29: advances | AN29: 477673022 | AO29: 395416055 | AP29: 372913863 | AQ29: 343107147 | AR29: 258693086
A30: 1. Advances/Deposits | B30: =Y65/Y66 -> 0.4703308 | C30: =Z65/Z66 -> 0.49972257 | D30: =AA65/AA66 -> 0.54896886 | E30: =Y69/Y70 -> 0.59812669 | F30: =Z69/Z70 -> 0.49199137 | AM30: total assets | AN30: 1259328610 | AO30: 992886661 | AP30: 833433027 | AQ30: 706451322 | AR30: 662610675
A31: Rank | B31: 1 | C31: 1 | D31: 1 | E31: 1 | F31: 1 | AN31: =477673022/1259328610 -> 0.37930769 | AO31: =395416055/992886661 -> 0.39824893 | AP31: =372913863/833433027 -> 0.44744311 | AQ31: =343107147/706451322 -> 0.48567698 | AR31: =258693086/662610675 -> 0.39041491
A32: Weight | B32: 0.05 | C32: 0.05 | D32: 0.05 | E32: 0.05 | F32: 0.05
A33: Rank x Weight | B33: =B31*B32 -> 0.05 | C33: =C31*C32 -> 0.05 | D33: =D31*D32 -> 0.05 | E33: =E31*E32 -> 0.05 | F33: =F31*F32 -> 0.05
A34: 2. Circulating Assets/ Total Assets | B34: =AN29/AN30 -> 0.37930769 | C34: =AO29/AO30 -> 0.39824893 | D34: =AP29/AP30 -> 0.44744311 | E34: =AQ29/AQ30 -> 0.48567698 | F34: =AR29/AR30 -> 0.39041491
A35: Rank | B35: 1 | C35: 1 | D35: 1 | E35: 1 | F35: 1
A36: Weight | B36: 0.05 | C36: 0.05 | D36: 0.05 | E36: 0.05 | F36: 0.05
A37: Rank x Weight | B37: =B35*B36 -> 0.05 | C37: =C35*C36 -> 0.05 | D37: =D35*D36 -> 0.05 | E37: =E35*E36 -> 0.05 | F37: =F35*F36 -> 0.05
X38: WORKING
A39: 6. Sensitivity | B39: 2021 | C39: 2020 | D39: 2019 | E39: 2018 | F39: 2017 | X39: Capital Adequacy | Y39: 2021 | Z39: 2020 | AA39: 2019 | AB39: 2018 | AC39: 2017
B40: =Y23/Y24 -> 0.48813385 | C40: =Z23/Z24 -> 0.45138643 | D40: =AA23/AA24 -> 0.36494801 | E40: =AB23/AB24 -> 0.36688126 | F40: =AC23/AC24 -> 0.47203395
...

Sheet Graphs
N104: INDUSTRY ANALYSIS

Sheet Sector Analysis

Sheet Industry
B2: Industry
C3: 2020 | D3: 2019 | E3: 2018 | F3: 2017
B4: CAR | C4: 0.186 | D4: 0.17 | E4: 0.162 | F4: 0.158 | I4: 2020 | J4: 2019 | K4: 2018 | L4: 2017
B5: NPLs to Gross loans | C5: 0.092 | D5: 0.086 | E5: 0.08 | F5: 0.084 | H5: NPLs to Gross loans
B6: ROA | C6: 0.01 | D6: 0.008 | E6: 0.008 | F6: 0.009 | H6: Industry | I6: 0.092 | J6: 0.086 | K6: 0.08 | L6: 0.084
B7: ROE | C7: 0.138 | D7: 0.113 | E7: 0.107 | F7: 0.115 | H7: Faysal Bank | I7: 0.070421053 | J7: 0.09295758 | K7: 0.086734737 | L7: 0.11414061
H8: Askari Bank | I8: 0.07267383 | J8: 0.075438514 | K8: 0.077693182 | L8: 0.10341609
B9: Askari Bank | H9: Standard Chartered Bank | I9: 0.020928088 | J9: 0.0062490327 | K9: 0.003309299 | L9: 0.0045999872
C10: 2020 | D10: 2019 | E10: 2018 | F10: 2017 | H10: Return on Asset
B11: Car | C11: 0.1548 | D11: 0.1338 | E11: 0.1251 | F11: 0.1209 | H11: Industry | I11: 0.01 | J11: 0.008 | K11: 0.008 | L11: 0.009
B12: NPL to gross loans | C12: 0.07267383 | D12: 0.075438514 | E12: 0.077693182 | F12: 0.10341609 | H12: Faysal Bank | I12: 0.0094084746 | J12: 0.009532334 | K12: 0.0081435667 | L12: 0.0091222599
B13: ROA | C13: 0.01093478 | D13: 0.0084203728 | E13: 0.0062706816 | F13: 0.0077257318 | H13: Askari Bank | I13: 0.01093478 | J13: 0.0084203728 | K13: 0.0062706816 | L13: 0.0077257318
B14: ROE | C14: 0.19855055 | D14: 0.16550801 | E14: 0.13188186 | F14: 0.1573713 | H14: Standard Chartered Bank | I14: 0.018192126 | J14: 0.025835818 | K14: 0.019510023 | L14: 0.016055271
B15: Faysal Bank | H15: Return on Equity
C16: 2020 | D16: 2019 | E16: 2018 | F16: 2017 | H16: Industry | I16: 0.138 | J16: 0.113 | K16: 0.107 | L16: 0.115
B17: Car | C17: 0.1867 | D17: 0.1909 | E17: 0.1672 | F17: 0.159 | H17: Faysal Bank | I17: 0.11094044 | J17: 0.10875819 | K17: 0.1122386 | L17: 0.11507836
B18: NPL to gross loans | C18: 0.070421053 | D18: 0.09295758 | E18: 0.086734737 | F18: 0.11414061 | H18: Askari Bank | I18: 0.19855055 | J18: 0.16550801 | K18: 0.13188186 | L18: 0.1573713
B19: ROA | C19: 0.0094084746 | D19: 0.009532334 | E19: 0.0081435667 | F19: 0.0091222599 | H19: Standard Chartered Bank | I19: 0.16079008 | J19: 0.21966834 | K19: 0.16715694 | L19: 0.13100723
B20: ROE | C20: 0.11094044 | D20: 0.10875819 | E20: 0.1122386 | F20: 0.11507836 | H20: Capital Adequacy Ratio
B21: Standard Chartered Bank | H21: Industry | I21: 0.186 | J21: 0.17 | K21: 0.162 | L21: 0.158
C22: 2020 | D22: 2019 | E22: 2018 | F22: 2017 | H22: Faysal Bank | I22: 0.1867 | J22: 0.1909 | K22: 0.1672 | L22: 0.159
B23: Car | C23: 0.1912 | D23: 0.1694 | E23: 0.1909 | F23: 0.1927 | H23: Askari Bank | I23: 0.1548 | J23: 0.1338 | K23: 0.1251 | L23: 0.1209
B24: NPL to gross loans | C24: 0.020928088 | D24: 0.0062490327 | E24: 0.003309299 | F24: 0.0045999872 | H24: Standard Chartered Bank | I24: 0.1912 | J24: 0.1694 | K24: 0.1909 | L24: 0.1927
B25: ROA | C25: 0.018192126 | D25: 0.025835818 | E25: 0.019510023 | F25: 0.016055271
B26: ROE | C26: 0.16079008 | D26: 0.21966834 | E26: 0.16715694 | F26: 0.13100723
H54: Advances | I54: 2020 | J54: GR
H55: BOP | I55: 391 | J55: 0.02
H56: Askari | I56: 395 | J56: 0.06
H57: Metro | I57: 312 | J57: 0.18
H58: Standard Chartered | I58: 178 | J58: -0.18
H59: Faysal | I59: 318 | J59: 0.03
H60: JS Bank | I60: 250 | J60: 0.03
H63: Deposits | I63: 2020 | J63: GR
H64: BOP | I64: 835 | J64: 0.21
H65: Askari | I65: 791 | J65: 0.16
H66: Metro | I66: 681 | J66: 0.11
H67: Standard Chartered | I67: 557 | J67: 0.2
H68: Faysal | I68: 541 | J68: 0.18
H69: JS Bank | I69: 433 | J69: 0.17

Sheet Comparison
A1: Non Performing Loans/ Total Loas
B2: 2021 | C2: 2020 | D2: 2019 | E2: 2018 | F2: 2017
A3: Standard Chartered Bank | B3: 0.0075120056 | C3: 0.020928088 | D3: 0.0062490327 | E3: 0.003309299 | F3: 0.0045999872
A4: Askari Bank | B4: 0.065244059 | C4: 0.07267383 | D4: 0.075438514 | E4: 0.077693182 | F4: 0.10341609
A5: Faysal Bank | B5: 0.11414061 | C5: 0.086734737 | D5: 0.09295758 | E5: 0.070421053 | F5: 0.048036376
A6: Net Profit Margin
B7: 2021 | C7: 2020 | D7: 2019 | E7: 2018 | F7: 2017
A8: Standard Chartered Bank | B8: 0.2367737 | C8: 0.20197697 | D8: 0.25372193 | E8: 0.27483692 | F8: 0.23043639
A9: Askari Bank | B9: 0.11152506 | C9: 0.12204158 | D9: 0.088712462 | E9: 0.089899479 | F9: 0.12084201
A10: Faysal Bank | B10: 0.13122324 | C10: 0.11748172 | D10: 0.091316709 | E10: 0.10393364 | F10: 0.13303601
A11: ROE
B12: 2021 | C12: 2020 | D12: 2019 | E12: 2018 | F12: 2017
A13: Standard Chartered Bank | B13: 0.1724468 | C13: 0.16079008 | D13: 0.21966834 | E13: 0.16715694 | F13: 0.13100723
A14: Askari Bank | B14: 0.17336873 | C14: 0.19855055 | D14: 0.16550801 | E14: 0.13188186 | F14: 0.1573713
A15: Faysal Bank | B15: 0.11507836 | C15: 0.1122386 | D15: 0.10875819 | E15: 0.11094044 | F15: 0.12631233
A16: EPS
B17: 2021 | C17: 2020 | D17: 2019 | E17: 2018 | F17: 2017
A18: Standard Chartered Bank | B18: 0.35 | C18: 0.34 | D18: 0.41 | E18: 0.29 | F18: 0.21
A19: Askari Bank | B19: 7.71 | C19: 8.61 | D19: 5.58 | E19: 3.51 | F19: 4.06
A20: Faysal Bank | B20: 2.97 | C20: 3.22 | D20: 3.96 | E20: 4.4 | F20: 5.5
A22: Operating Efficiency
B23: 2021 | C23: 2020 | D23: 2019 | E23: 2018 | F23: 2017
A24: Askari Bank | B24: 0.50068618 | C24: 0.50395109 | D24: 0.61728915 | E24: 0.67022181 | F24: 0.6700081
A25: Faysal Bank | B25: 0.33119296 | C25: 0.3044534 | D25: 0.26176582 | E25: 0.34888938 | F25: 0.36645263
A26: Standard Chartered Bank | B26: 0.30859725 | C26: 0.29015306 | D26: 0.28479305 | E26: 0.38174752 | F26: 0.44963879
A27: Equity Multiplier
B28: 2021 | C28: 2020 | D28: 2019 | E28: 2018 | F28: 2017
A29: Askari Bank | B29: 22.471613 | C29: 18.157709 | D29: 19.655663 | E29: 21.031503 | F29: 20.369759
A30: Faysal Bank | B30: 13.155357 | C30: 11.791544 | D30: 11.409397 | E30: 13.782487 | F30: 12.615115
A31: Standard Chartered Bank | B31: 10.54 | C31: 8.84 | D31: 8.5 | E31: 8.57 | F31: 8.16

Sheet Sheet2
B1: 2021 | C1: 2021 | D1: 2020 | E1: 2020 | F1: 2019 | G1: 2019 | H1: 2018 | I1: 2018 | J1: 2017 | K1: 2017 | O1: 2021 | P1: 2020 | Q1: 2019 | R1: 2018 | S1: 2017 | V1: Non Performing Loans | W1: 2021 | X1: 2021 | Y1: 2020 | Z1: 2020 | AA1: 2019 | AB1: 2019 | AC1: 2018 | AD1: 2018 | AE1: 2017 | AF1: 2017 | AI1: Credit Risk by Credit risk by public / private sector (Advances)
A2: Textile | B2: 64650892 | C2: =(B2/$B$9) -> 0.12731153 | D2: 51348259 | E2: =(D2/$D$9) -> 0.12173029 | F2: 49156516 | G2: =(F2/$F$9) -> 0.16173633 | H2: 48018815 | I2: =(H2/$H$9) -> 0.1826893 | J2: 41707804 | K2: =(J2/$J$9) -> 0.14668303 | N2: Public Advances | O2: 156455831 | P2: 129318506 | Q2: 135487857 | R2: 116597785 | S2: 86590715 | V2: Textile | W2: 9573196 | X2: =W2/W9 -> 0.33695611 | Y2: 10377789 | Z2: 0.36527607 | AA2: 11277670 | AB2: 0.40085593 | AC2: 12335315 | AD2: 0.46274056 | AE2: 12000289 | AF2: 0.44855818 | AK2: 2021 | AL2: 2020 | AM2: 2019 | AN2: 2018 | AO2: 2017
A3: Chemical and Pharmaceutical | B3: 15521810 | C3: =(B3/$B$9) -> 0.030565788 | D3: 12361663 | E3: =(D3/$D$9) -> 0.029305548 | F3: 13722368 | G3: =(F3/$F$9) -> 0.045149771 | H3: 20292417 | I3: =(H3/$H$9) -> 0.077203227 | J3: 9251785 | K3: =(J3/$J$9) -> 0.032537792 | N3: Private Advances | O3: 351360622 | P3: 292501384 | Q3: 263060954 | R3: 252661186 | S3: 197748955 | V3: Electronics and electrical appliances | W3: 1104739 | X3: =W3/W9 -> 0.03888446 | Y3: 1114668 | Z3: 0.039233939 | AA3: 1119429 | AB3: 0.039789226 | AC3: 1119429 | AD3: 0.041993675 | AE3: 1116900 | AF3: 0.041748547 | AJ3: Public | AK3: 156455831 | AL3: 129318506 | AM3: 135487857 | AN3: 116597785 | AO3: 86590715
A4: Sugar | B4: 14988981 | C4: =(B4/$B$9) -> 0.029516533 | D4: 12804088 | E4: =(D4/$D$9) -> 0.030354396 | F4: 11623458 | G4: =(F4/$F$9) -> 0.038243871 | H4: 9166459 | I4: =(H4/$H$9) -> 0.034874121 | J4: 7181562 | K4: =(J4/$J$9) -> 0.025256982 | V4: Power (electricity), Gas, Water, Sanitary | W4: 5478395 | X4: 0.19282784 | Y4: 3295100 | Z4: 0.1159805 | AA4: 3570878 | AB4: 0.12692406 | AC4: 1671611 | AD4: 0.062707942 | AE4: 1675648 | AF4: 0.062633959 | AJ4: Private | AK4: 351360622 | AL4: 292501384 | AM4: 263060954 | AN4: 252661186 | AO4: 252661186
A5: Food and allied | B5: 54707437 | C5: =(B5/$B$9) -> 0.10773073 | D5: 31213168 | E5: =(D5/$D$9) -> 0.073996435 | F5: 5660916 | G5: =(F5/$F$9) -> 0.018625726 | H5: 4474849 | I5: =(H5/$H$9) -> 0.017024723 | J5: 2677099 | K5: =(J5/$J$9) -> 0.0094151442 | N5: Non Perfomring Public Advances | O5: 0 | P5: 0 | Q5: 0 | R5: 0 | S5: 0 | V5: Individuals | W5: 2569558 | X5: 0.090442969 | Y5: 2662811 | Z5: 0.093725276 | AA5: 2166505 | AB5: 0.077006721 | AC5: 2111521 | AD5: 0.079210496 | AE5: 2004025 | AF5: 0.074908346
A6: Power and energy | B6: 60184351 | C6: =(B6/$B$9) -> 0.11851595 | D6: 52409615 | E6: =(D6/$D$9) -> 0.12424643 | F6: 8072920 | G6: =(F6/$F$9) -> 0.026561778 | H6: 2604170 | I6: =(H6/$H$9) -> 0.0099076579 | J6: 22138997 | K6: =(J6/$J$9) -> 0.077861091 | N6: Non Performing Private | O6: 31165327 | P6: 28736399 | Q6: 28133973 | R6: 26657086 | S6: 26753027 | V6: Edible oil and ghee | W6: 1668682 | X6: 0.058734052 | Y6: 1681161 | Z6: 0.059173287 | AA6: 512951 | AB6: 0.018232441 | AC6: 549956 | AD6: 0.020630762 | AE6: 460614 | AF6: 0.017217267
A7: Services | B7: 37091770 | C7: =(B7/$B$9) -> 0.073041686 | D7: 33989548 | E7: =(D7/$D$9) -> 0.080578344 | F7: 20244401 | G7: =(F7/$F$9) -> 0.066608772 | H7: 9004661 | I7: =(H7/$H$9) -> 0.034258555 | J7: 11298355 | K7: =(J7/$J$9) -> 0.039735416 | V7: Others | W7: 2547719 | X7: 0.089674282 | Y7: 2311783 | Z7: 0.081369838 | AA7: 2076292 | AB7: 0.07380017 | AC7: 2164010 | AD7: 0.081179541 | AE7: 2382125 | AF7: 0.089041326
A8: Others | B8: =B9-(B2+B3+B4+B5+B6+B7) -> 260671212 | C8: =(B8/$B$9) -> 0.51331778 | D8: =D9-(D2+D3+D4+D5+D6+D7) -> 227693549 | E8: =(D8/$D$9) -> 0.53978856 | F8: =F9-(F2+F3+F4+F5+F6+F7) -> 195449377 | G8: =(F8/$F$9) -> 0.64307375 | H8: =H9-(H2+H3+H4+H5+H6+H7) -> 169282786 | I8: =(H8/$H$9) -> 0.64404242 | J8: =J9-(J2+J3+J4+J5+J6+J7) -> 190084068 | K8: =(J8/$J$9) -> 0.66851055 | V8: Oil and gas | W8: 2199598 | Y8: 16303
A9: TOTAL | B9: 507816453 | D9: 421819890 | F9: 303929956 | H9: 262844157 | J9: 284339670 | V9: Total | W9: 28410810 | X9: 0.71784543 | Y9: 28410810 | Z9: 0.67338907 | AA9: 28133973 | AB9: 0.66280838 | AC9: 26657086 | AD9: 0.66728344 | AE9: 26753027 | AF9: 0.64506629
