Workbook

Sheet Balance Sheet
A1: Rupees in ‘000 | B1: 2021 | C1: 2020 | D1: 2019 | E1: 2018 | F1: 2017
A3: Assets
A4: Cash and balances with treasury banks | B4: 89432245 | C4: 73651718 | D4: 63039290 | E4: 49187645 | F4: 44239325
A5: Balances with other banks | B5: 3556215 | C5: 8196147 | D5: 7886702 | E5: 4093402 | F5: 3193835
A6: Lendings to financial institutions | B6: – | C6: – | D6: 20405972 | E6: – | F6: 2250000
A7: Investments | B7: 616231172 | C7: 449611987 | D7: 305435633 | E7: 260233987 | F7: 314956748
A8: Advances | B8: 477673022 | C8: 395416055 | D8: 372913863 | E8: 343107147 | F8: 258693086
A9: Fixed assets | B9: 20179222 | C9: 21232750 | D9: 19696568 | E9: 12791827 | F9: 9885958
A10: Intangible assets | B10: 1188985 | C10: 1158857 | D10: 808994 | E10: 741361 | F10: 842869
A11: Deferred tax assets | B11: 5161697 | C11: 1597334 | D11: 2489752 | E11: 3773779 | F11: 100755
A12: Other assets | B12: 45906052 | C12: 42021813 | D12: 40450512 | E12: 32522174 | F12: 28448099
D13: 833208006 | E13: 706451322 | F13: 662610675
A14: Assets attributable to discontinued operations | D14: 315741 | E14: 214757 | F14: 327949
A17: Total Assets | B17: 1259328610 | C17: 992886661 | D17: 833443027 | E17: 706666079 | F17: 662938624
A18: Liabilities
A19: Bills payable | B19: 10235374 | C19: 12629996 | D19: 15768947 | E19: 15512880 | F19: 10769262
A20: Borrowings | B20: 123563761 | C20: 84163669 | D20: 51187681 | E20: 52702323 | F20: 71587311
A21: Deposits and other accounts | B21: 1015162254 | C21: 790982287 | D21: 679246312 | E21: 573596926 | F21: 525805051
A22: Liabilities against assets subject to finance lease | B22: – | C22: – | D22: – | E22: – | F22: –
A23: Subordinated debts | B23: 12000000 | C23: 12000000 | D23: 9992000 | E23: 9993600 | F23: 4992800
A24: Deferred tax liabilities | B24: – | C24: – | D24: – | E24: – | F24: –
A25: Other liabilities | B25: 42326358 | C25: 38429434 | D25: 34704048 | E25: 21178476 | F25: 17098223
A26: Total Liabilites | B26: 1203287747 | C26: 938205386 | D26: =SUM(D19:D25) -> 790,898,988 | E26: 672984205 | F26: 630252647
A27: Liabilities associated with discontionued operations | B27: – | C27: – | D27: 141856 | E27: 81513 | F27: 140741
D28: =SUM(D26:D27) -> 791,040,844 | E28: 673065718 | F28: 630393388
A29: Net Assets | B29: 56040863 | C29: 54681275 | D29: 42402183 | E29: 33600361 | F29: 32545236
A30: Represented By
A31: Share capital | B31: 12602602 | C31: 12602602 | D31: 12602602 | E31: 12602602 | F31: 12602602
A32: Reserves | B32: 32832051 | C32: 25701665 | D32: 19408889 | E32: 15588694 | F32: 12032263
A33: Surplus on revaluation of assets - net of tax | B33: 1987976 | C33: 7670955
A34: Continued operations | B34: 8618234 | C34: 8706053 | D34: 4300426 | E34: 1649197 | F34: 5142254
A35: Discontinued operations | D35: 39467 | E35: 5723 | F35: 19877
A36: Unappropriated profit | D36: 6002253 | E36: 3710867 | F36: 2703887
D37: 42353637 | E37: 33557083 | F37: 32500883
A39: Non-controlling interest | B39: – | C39: – | D39: 48546 | E39: 43278 | F39: 44353
B41: 56040863 | C41: 54681275 | D41: =SUM(D37:D39) -> 42,402,183 | E41: 33600361 | F41: 32545236

Sheet Income Statement
A1: Rupees in ‘000 | B1: 2021 | C1: 2020 | D1: 2019 | E1: 2018 | F1: 2017
A3: Mark-up / return / interest earned | B3: 77,569,443 | C3: 79,118,320 | D3: 71704373 | E3: 43669883 | F3: 36267220
A4: Mark-up / return / interest expenses | B4: 45139897 | C4: 48842539 | D4: 49567851 | E4: 25059925 | F4: 20071958
A5: Net mark-up / interest income | B5: 32429546 | C5: 30275781 | D5: 22136522 | E5: 18609958 | F5: 16195262
A6: Non mark-up / interest income
A7: Fee and commission income | B7: 4785268 | C7: 3991285 | D7: 3616428 | E7: 3116070 | F7: 2706794
A8: Dividend income | B8: 421964 | C8: 273524 | D8: 274440 | E8: 231312 | F8: 302894
A9: Foreign exchange income | B9: 3123524 | C9: 2673493 | D9: 2507707 | E9: 1596027 | F9: 843032
A10: Income / (loss) from derivatives | B10: – | C10: – | D10: – | E10: – | F10: –
A11: Gain on securities | B11: 814724 | C11: 2555400 | D11: 739351 | E11: 260103 | F11: 2063043
A12: Other income | B12: 402118 | C12: 349438 | D12: 266102 | E12: 418081 | F12: 200341
A13: Total non-markup / interest income | B13: 9547598 | C13: 9843140 | D13: 7404028 | E13: 5621593 | F13: 6116104
A14: Total income | B14: 41977144 | C14: 40118921 | D14: 29540550 | E14: 24231551 | F14: 22311366
A15: Non mark-up / interest expenses
A16: Operating expenses | B16: 21017376 | C16: 20217974 | D16: 18235061 | E16: 16240514 | F16: 14948796
A17: Workers’ welfare fund | B17: 213484 | C17: 42982 | D17: 42117 | E17: -540060 | F17: 169833
A18: Total non-markup / interest expenses | B18: 90139 | C18: 48149 | D18: 99947 | E18: 191067 | F18: 23568
B19: 21320999 | C19: 20309105 | D19: 18377125 | E19: 15891521 | F19: 15142197
A20: Profit before provisions | B20: 20656145 | C20: 19809816 | D20: 11163425 | E20: 8340030 | F20: 7169169
A21: Provisions and write offs - net | B21: 4983944 | C21: 1974747 | D21: 773275 | E21: 1460575 | F21: -1176432
A22: Extraordinary / unusual items | B22: – | C22: – | D22: – | E22: – | F22: –
A23: Profit before taxation | B23: 15672201 | C23: 17835069 | D23: 10390150 | E23: 6879455 | F23: 8345601
A24: Taxation | B24: -5956468 | C24: -6978072 | D24: 3372249 | E24: -2448177 | F24: -3223915
A25: Profit after taxation | B25: 9715733 | C25: 10856997 | D25: 7017901 | E25: 4431278 | F25: 5121686
A26: (Loss) / profit after taxation - discontinued operations | D26: 14669 | E26: -2659 | F26: 6611
A27: Attributable to:
A28: Equity holders of the Bank | B28: 9715733 | C28: 10846333 | D28: 7028756 | E28: 4429310 | F28: 5121863
A29: Non-controlling interest | B29: – | C29: 10664 | D29: 3814 | E29: -691 | F29: 6434
B30: 9715733 | C30: 10856997 | D30: =SUM(D28:D29) -> 7,032,570 | E30: 4428619 | F30: 5128297
A32: Basic and diluted earnings per share | B32: 7.71 | C32: 8.61 | D32: 5.58 | E32: 3.51 | F32: 4.06

Sheet Profitability Ratio
B1: 2021 | C1: 2020 | D1: 2019 | E1: 2018 | F1: 2017
A13: Earning Assets
A14: Loans and Advances | B14: 477673022 | C14: 395416055 | D14: 372913863 | E14: 343107147 | F14: 258693086
A15: Investments | B15: 616231172 | C15: 449611987 | D15: 305435633 | E15: 260233987 | F15: 314956748
A16: Lending to Financial Institutions - Net | B16: 0 | C16: 0 | D16: 20405972 | E16: 0 | F16: 2250000
A17: Balances with other banks | B17: 3556215 | C17: 8196147 | D17: 7886702 | E17: 4093402 | F17: 3193835
A18: TOTAL EARNING ASSETS | B18: =SUM(B14:B17) -> 1,097,460,409 | C18: =SUM(C14:C17) -> 853,224,189 | D18: =SUM(D14:D17) -> 706,642,170 | E18: =SUM(E14:E17) -> 607,434,536 | F18: =SUM(F14:F17) -> 579,093,669
A20: Interest Bearing Liabilities
A21: Deposits (less of Current Accounts) | B21: 222888771 | C21: 539726821 | D21: 484456138 | E21: 404040078 | F21: 381975947
A22: Current Account Deposits | B22: 790982287 | C22: 1030588 | D22: 194254257 | E22: 168745407 | F22: 143678468
A23: Current Account Deposits | B23: 1291196 | C23: 250224878 | D23: 535917 | E23: 811441 | F23: 150636
A24: Borrowings | B24: 123563761 | C24: 84163669 | D24: 51187681 | E24: 52702323 | F24: 71587311
A25: Subordinated Debts | B25: 12000000 | C25: 12000000 | D25: 9992000 | E25: 9993600 | F25: 4992800
A26: Lease liability against ROU assets as per IFRS - 16 Leases | B26: 7393878 | C26: 8223995 | D26: 970082 | E26: 0 | F26: 0
A27: Total Interest Bearing Liability | B27: =SUM(B21:B26) -> 1,158,119,893 | C27: =SUM(C21:C26) -> 895,369,951 | D27: =SUM(D21:D26) -> 741,396,075 | E27: =SUM(E21:E26) -> 636,292,849 | F27: =SUM(F21:F26) -> 602,385,162
A29: Net Income | B29: ='Income Statement'!B25 -> 9,715,733 | C29: ='Income Statement'!C25 -> 10,856,997 | D29: ='Income Statement'!D25 -> 7,017,901 | E29: ='Income Statement'!E25 -> 4,431,278 | F29: ='Income Statement'!F25 -> 5,121,686
A30: Equity | B30: ='Balance Sheet'!B41 -> 56,040,863 | C30: ='Balance Sheet'!C41 -> 54,681,275 | D30: ='Balance Sheet'!D41 -> 42,402,183 | E30: ='Balance Sheet'!E41 -> 33,600,361 | F30: ='Balance Sheet'!F41 -> 32,545,236
A31: Total Assets | B31: ='Balance Sheet'!B17 -> 1,259,328,610 | C31: ='Balance Sheet'!C17 -> 992,886,661 | D31: ='Balance Sheet'!D17 -> 833,443,027 | E31: ='Balance Sheet'!E17 -> 706,666,079 | F31: ='Balance Sheet'!F17 -> 662,938,624
A32: Total Operating Revenue | B32: ='Income Statement'!B5-'Income Statement'!B19 -> 11,108,547 | C32: ='Income Statement'!C5-'Income Statement'!C19 -> 9,966,676 | D32: ='Income Statement'!D5-'Income Statement'!D19 -> 3,759,397 | E32: ='Income Statement'!E5-'Income Statement'!E19 -> 2,718,437 | F32: ='Income Statement'!F5-'Income Statement'!F19 -> 1,053,065
A40: Workings
A41: Total income | B41: 41977144 | C41: 40118921 | D41: 29540550 | E41: 24231551 | F41: 22311366 | R41: USE FOR NEXT RATIOS WHEN GIVEN | X41: 2021 | Y41: 2020 | Z41: 2019 | AA41: 2018 | AB41: 2017
A42: Operating expenses | B42: 21017376 | C42: 20217974 | D42: 18235061 | E42: 16240514 | F42: 14948796 | R42: Return on Equity | S42: 13 | T42: ROE=(Net Income/ Pre-Tax Net Operating Income) * (Pre-Tax Net Operating Income/Total Operating Revenue) * (Total Operating Revenue/Total Assets) * (Total Assets/ TOtal Equity Capital )
A43: Total Assets | B43: 1259328610 | C43: 992886661 | D43: 833443027 | E43: 706666079 | F43: 662938624 | R43: Credit Risk | S43: 14 | T43: Nonperforming Loans/Total Loans | X43: =B25/B14 -> 0.02512178718 | Y43: =C25/C14 -> 0.0303477814 | Z43: =D25/D14 -> 0.02679439139 | AA43: =E25/E14 -> 0.02912676138 | AB43: =F25/F14 -> 0.01930009061
R44: Credit Risk | S44: 15 | T44: Net Charge-Offs/Total Loans
R45: Credit Risk | S45: 16 | T45: Provision for LOan Loses/Total Loans
R46: Credit Risk | S46: 17 | T46: Provision for LOan Loses/Equity Capital | X46: ='Income Statement'!B21/'Balance Sheet'!B41 -> 0.0889341051 | Y46: ='Income Statement'!C21/'Balance Sheet'!C41 -> 0.03611377021 | Z46: ='Income Statement'!D21/'Balance Sheet'!D41 -> 0.01823667899 | AA46: ='Income Statement'!E21/'Balance Sheet'!E41 -> 0.04346902701 | AB46: ='Income Statement'!F21/'Balance Sheet'!F41 -> -0.03614759469
R47: Credit Risk | S47: 18 | T47: Allowance for Loan Losses/ Toal Loans | X47: ='Income Statement'!B21/B14 -> 0.01043379837 | Y47: ='Income Statement'!C21/C14 -> 0.00499409919 | Z47: ='Income Statement'!D21/D14 -> 0.002073602182 | AA47: ='Income Statement'!E21/E14 -> 0.004256906371 | AB47: ='Income Statement'!F21/F14 -> -0.00454759738
X48: 2021 | Y48: 2020 | Z48: 2019 | AA48: 2018 | AB48: 2017
T49: (Net Income/ Pre-Tax Net Operating Income) | X49: ='Income Statement'!B25/'Income Statement'!B23 -> 0.6199341752 | Y49: ='Income Statement'!C25/'Income Statement'!C23 -> 0.6087443228 | Z49: ='Income Statement'!D25/'Income Statement'!D23 -> 0.6754378907 | AA49: ='Income Statement'!E25/'Income Statement'!E23 -> 0.6441321297 | AB49: ='Income Statement'!F25/'Income Statement'!F23 -> 0.6136988816
T50: (Pre-Tax Net Operating Income/Total Operating Revenue)
T51: (Total Operating Revenue/Total Assets) | X51: =B32/B31 -> 0.00882100741 | Y51: =C32/C31 -> 0.01003808027 | Z51: =D32/D31 -> 0.004510682648 | AA51: =E32/E31 -> 0.00384684801 | AB51: =F32/F31 -> 0.001588480384
T52: (Total Assets/ TOtal Equity Capital ) | X52: ='Balance Sheet'!B17/'Balance Sheet'!B41 -> 22.47161344 | Y52: ='Balance Sheet'!C17/'Balance Sheet'!C41 -> 18.15770867 | Z52: ='Balance Sheet'!D17/'Balance Sheet'!D41 -> 19.65566318 | AA52: ='Balance Sheet'!E17/'Balance Sheet'!E41 -> 21.03150258 | AB52: ='Balance Sheet'!F17/'Balance Sheet'!F41 -> 20.36975931
X53: =X49*X50*X51*X52 -> 0 | Y53: =Y49*Y50*Y51*Y52 -> 0 | Z53: =Z49*Z50*Z51*Z52 -> 0 | AA53: =AA49*AA50*AA51*AA52 -> 0 | AB53: =AB49*AB50*AB51*AB52 -> 0
A56: Market Risk Measures | B56: 2021 | C56: 2020 | D56: 2019 | E56: 2018 | F56: 2017
A57: Book-Value of Assets/Market Value of Assets
A58: Book-Value of Equity/Market Value of Equity | B58: =(B61*B60)/(B60*B59) -> 2.014532243 | C58: =(C61*C60)/(C60*C59) -> 1.850363403 | D58: =(D61*D60)/(D60*D59) -> 1.808522114 | E58: =(E61*E60)/(E60*E59) -> 1.111622074 | F58: =(F61*F60)/(F60*F59) -> 1.332988089
A59: Market Value Per Share | B59: 22.02 | C59: 23.39 | D59: 18.54 | E59: 23.92 | F59: 19.31
A60: Number of Shares Outstanding | B60: 1260260180 | C60: 1260260180 | D60: 1260260180 | E60: 1260260180 | F60: 1260260180
A61: Book Value of Shares | B61: 44.36 | C61: 43.28 | D61: 33.53 | E61: 26.59 | F61: 25.74
A62: Book-Value of Bonds/Market Value of Bonds
...

Sheet Risk Ratios
A1: Credit Risk Ratios
B2: 2021 | C2: 2020 | D2: 2019 | E2: 2018 | F2: 2017
A3: Nonperforming Loans/Total Loans | B3: 0.025121787 | C3: 0.030347781 | D3: 0.026794391 | E3: 0.029126761 | F3: 0.019300091
A4: Net Charge-Offs/Total Loans | B4: 0.010433798 | C4: 0.0043921138 | D4: 0.0020736022 | E4: 0.0056125451 | F4: -0.0045475974
A5: Provision for loan losses/ Total Loans | B5: 0.012181679 | C5: 0.0059101617 | D5: 0.002319874 | E5: 0.0047825189 | F5: -0.0048996183
A6: Provision for loan losses/ Equity Capital | B6: 0.088934105 | C6: 0.03611377 | D6: 0.018236679 | E6: 0.043469027 | F6: -0.036147595
A7: Allowance for loan losses/ Total Loans | B7: 0.0104 | C7: 0.005 | D7: 0.0021 | E7: 0.0043 | F7: -0.0045
A8: Allowance for Loan Losses / Equity Capital | B8: 0.088934105 | C8: 0.03611377 | D8: 0.018236679 | E8: 0.043469027 | F8: -0.036147595
A9: Non Perfoming Loans / Equity Capital | B9: 0.45348401 | C9: 0.44510023 | D9: 0.61924149 | E9: 0.77874827 | F9: 0.8220259
A11: Liquidity Risk Measures
B12: 2021 | C12: 2020 | D12: 2019 | E12: 2018 | F12: 2017
A13: Purchased Funds / Total Assets
A14: Net Loans/Total Assets | B14: 0.37936327 | C14: 0.39839724 | D14: 0.44759426 | E14: 0.4856215 | F14: 0.39036735
A15: Cash and Due From Banks/Total Assets | B15: 0.07385053 | C15: 0.082464945 | D15: 0.085123992 | E15: 0.075412075 | F15: 0.071576544
A16: Cash and Government Securities/Total Assets | B16: 0.49171115 | C16: 0.45446059 | D16: 0.35671874 | E16: 0.36993281 | F16: 0.47395079
A18: Market Risk Measures
B19: 2021 | C19: 2020 | D19: 2019 | E19: 2018 | F19: 2017
A20: Book-Value of Assets/Market Value of Assets
A21: Book-Value of Equity/Market Value of Equity | B21: 2.0145322 | C21: 1.8503634 | D21: 1.8085221 | E21: 1.1116221 | F21: 1.3329881
A22: Book-Value of Bonds/Market Value of Bonds
A24: Interest Rate Risk Measures
B25: 2021 | C25: 2020 | D25: 2019 | E25: 2018 | F25: 2017
A26: Intrest Sensitive Assets/Intrest Sensitive Liabilities | B26: 1.3176955 | C26: 1.0580941 | D26: 1.0312515 | E26: 1.0721448 | F26: 1.0173813
A27: Uninsured Deposits/Total Deposits | B27: 0.60150352 | C27: 0.95457934 | D27: 0.57388257 | E27: 0.54748614 | F27: 0.54793224
A29: Capital Risk Measures
B30: 2021 | C30: 2020 | D30: 2019 | E30: 2018 | F30: 2017
A31: Stock Price/Earnings Per Share | B31: 22.02 | C31: 23.39 | D31: 18.54 | E31: 23.92 | F31: 19.31
A32: Equity Capital/Total Assets | B32: 0.044500587 | C32: 0.055073028 | D32: 0.050875923 | E32: 0.04754772 | F32: 0.049092382
A33: Purchased funds/Total liabilties
A34: Equity capital /Risk Assets | B34: 0.090941299 | C34: 0.12161881 | D34: 0.13882527 | E34: 0.12911596 | F34: 0.1033324
A36: Other Goals in Banking
B37: 2021 | C37: 2020 | D37: 2019 | E37: 2018 | F37: 2017
A38: Operating Efficieny ratio | B38: 0.50068618 | C38: 0.50395109 | D38: 0.61728915 | E38: 0.67022181 | F38: 0.6700081
A39: Employee productivity ratio | B39: 1299.2422 | C39: 1417.7327 | D39: 931.49735 | E39: 587.85858 | F39: 652.61035

Sheet CAMELS
A1: 1. Capital Adequacy | B1: 2021 | C1: 2020 | D1: 2019 | E1: 2018 | F1: 2017 | H1: CAMELS | I1: 2021 | J1: 2020 | K1: 2019 | L1: 2018 | M1: 2017
B2: 0.1338 | C2: 0.1548 | D2: 0.1338 | E2: 0.1251 | F2: 0.1209 | H2: Capital Adequacy | I2: 0.2 | J2: 0.2 | K2: 0.2 | L2: 0.2 | M2: 0.2
A3: Rank | B3: 1 | C3: 1 | D3: 1 | E3: 1 | F3: 1 | H3: Asset Quality | I3: 0.2 | J3: 0.2 | K3: 0.2 | L3: 0.2 | M3: 0.2
A4: Weight | B4: 0.2 | C4: 0.2 | D4: 0.2 | E4: 0.2 | F4: 0.2 | H4: Management | I4: 1.25 | J4: 1.25 | K4: 1.25 | L4: 1.25 | M4: 1.25
A5: Rank x Weight | B5: =B4*B3 -> 0.2 | C5: =C4*C3 -> 0.2 | D5: =D4*D3 -> 0.2 | E5: =E4*E3 -> 0.2 | F5: =F4*F3 -> 0.2 | H5: Earnings | I5: =B23+B27 -> 0.9 | J5: =C23+C27 -> 0.75 | K5: =D23+D27 -> 1.05 | L5: =E23+E27 -> 1.2 | M5: =F23+F27 -> 1.05
H6: Liquidity | I6: =B33+B37 -> 0.1 | J6: =C33+C37 -> 0.1 | K6: =D33+D37 -> 0.1 | L6: =E33+E37 -> 0.1 | M6: =F33+F37 -> 0.1
A7: 2. Asset Quality | B7: 2021 | C7: 2020 | D7: 2019 | E7: 2018 | F7: 2017 | H7: Sensitivity | I7: 0.5 | J7: 0.5 | K7: 0.5 | L7: 0.5 | M7: 0.5
B8: 0.0055 | C8: 0.0098 | D8: 0.01 | E8: 0.0045 | F8: 0.0069 | H8: Total | I8: =SUM(I2:I7) -> 3.15 | J8: =SUM(J2:J7) -> 3 | K8: =SUM(K2:K7) -> 3.3 | L8: =SUM(L2:L7) -> 3.45 | M8: =SUM(M2:M7) -> 3.3
A9: Rank | B9: 1 | C9: 1 | D9: 1 | E9: 1 | F9: 1
A10: Weight | B10: 0.2 | C10: 0.2 | D10: 0.2 | E10: 0.2 | F10: 0.2 | H10: Average Rating | I10: =AVERAGE(I8:M8) -> 3.24
A11: Rank x Weight | B11: =B10*B9 -> 0.2 | C11: 0.2 | D11: 0.2 | E11: 0.2 | F11: 0.2
A13: 3. Management | B13: 2021 | C13: 2020 | D13: 2019 | E13: 2018 | F13: 2017
B14: 2.1632 | C14: 1.8622 | D14: 2.5984 | E14: 3.665 | F14: 2.9187
A15: Rank | B15: 5 | C15: 5 | D15: 5 | E15: 5 | F15: 5
A16: Weight | B16: 0.25 | C16: 0.25 | D16: 0.25 | E16: 0.25 | F16: 0.25
A17: Rank x Weight | B17: 1.25 | C17: 1.25 | D17: 1.25 | E17: 1.25 | F17: 1.25
A19: 4. Earnings | B19: 2021 | C19: 2020 | D19: 2019 | E19: 2018 | F19: 2017
A20: Earnings (ROA) | B20: 0.0077 | C20: 0.0109 | D20: 0.0084 | E20: 0.0063 | F20: 0.0077
A21: Rank | B21: 4 | C21: 3 | D21: 4 | E21: 5 | F21: 4
A22: Weight | B22: 0.15 | C22: 0.15 | D22: 0.15 | E22: 0.15 | F22: 0.15
A23: Rank x Weight | B23: 0.6 | C23: 0.45 | D23: 0.6 | E23: 0.75 | F23: 0.6
A24: Earnings (ROE) | B24: 0.1734 | C24: 0.1986 | D24: 0.1655 | E24: 0.1319 | F24: 0.1574
A25: Rank | B25: 2 | C25: 2 | D25: 3 | E25: 3 | F25: 3
A26: Weight | B26: 0.15 | C26: 0.15 | D26: 0.15 | E26: 0.15 | F26: 0.15
A27: Rank x Weight | B27: 0.3 | C27: 0.3 | D27: 0.45 | E27: 0.45 | F27: 0.45
... A33: Rank x Weight | B33: 0.05 | C33: 0.05 | D33: 0.05 | E33: 0.05 | F33: 0.05
A34: 2. Circulating Assets/ Total Assets | B34: =477673022/1259328610 -> 37.93% | C34: =395416055/992886661 -> 39.82% | D34: =372913863/833433027 -> 44.74% | E34: =343107147/706451322 -> 48.57% | F34: =258693086/662610675 -> 39.04%
A35: Rank | B35: 1 | C35: 1 | D35: 1 | E35: 1 | F35: 1
A36: Weight | B36: 0.05 | C36: 0.05 | D36: 0.05 | E36: 0.05 | F36: 0.05
A37: Rank x Weight | B37: 0.05 | C37: 0.05 | D37: 0.05 | E37: 0.05 | F37: 0.05
A39: 6. Sensitivity | B39: 2021 | C39: 2020 | D39: 2019 | E39: 2018 | F39: 2017
B40: 0.4881 | C40: 0.4514 | D40: 0.3649 | E40: 0.3669 | F40: 0.472
A41: Rank | B41: 5 | C41: 5 | D41: 5 | E41: 5 | F41: 5
A42: Weight | B42: 0.1 | C42: 0.1 | D42: 0.1 | E42: 0.1 | F42: 0.1
A43: Rank x Weight | B43: 0.5 | C43: 0.5 | D43: 0.5 | E43: 0.5 | F43: 0.5

Sheet Sheet2
A1: Market Risk Measures | B1: 2021 | C1: 2020 | D1: 2019 | E1: 2018 | F1: 2017
A2: Book-Value of Assets/Market Value of Assets
A3: Book-Value of Equity/Market Value of Equity | B3: 2.0145322 | C3: 1.8503634 | D3: 1.8085221 | E3: 1.1116221 | F3: 1.3329881
A4: Market Value Per Share | B4: 22.02 | C4: 23.39 | D4: 18.54 | E4: 23.92 | F4: 19.31
A5: Number of Shares Outstanding | B5: 1260260180 | C5: 1260260180 | D5: 1260260180 | E5: 1260260180 | F5: 1260260180
A6: Book Value of Shares | B6: 44.36 | C6: 43.28 | D6: 33.53 | E6: 26.59 | F6: 25.74
A7: Book-Value of Bonds/Market Value of Bonds
A8: Intrest Sensitive Assets/Intrest Sensitive Liabilities | B8: 1.3176955 | C8: 1.0580941 | D8: 1.0312515 | E8: 1.0721448 | F8: 1.0173813
A9: Intrest Sensitive Assets | B9: 1222420697 | C9: 956675071 | D9: 786642860 | E9: 667452221 | F9: 633359777
A10: Intrest Sensitive Liabilitis | B10: 927695864 | C10: 904149338 | D10: 762804062 | E10: 622539224 | F10: 622539224
A11: Uninsured Deposits/Total Deposits | B11: 0.60150352 | C11: 0.95457934 | D11: 0.57388257 | E11: 0.54748614 | F11: 0.54793224
A12: Uninsured Deposits | B12: 610784723000 | C12: 755250763000 | D12: 389838134000 | E12: 314057678000 | F12: 288107323000
A13: Total Deposits | B13: 1015430000000 | C13: 791187000000 | D13: 679299486000 | E13: 573635856000 | F13: 525808308000
A14: Stock Price/Earnings Per Share | B14: 2.8597403 | C14: 2.7292882 | D14: 3.3285458 | E14: 6.7954545 | F14: 4.6196172
A15: Stock Price | B15: 22.02 | C15: 23.39 | D15: 18.54 | E15: 23.92 | F15: 19.31
A16: Earnings Per Share | B16: 7.7 | C16: 8.57 | D16: 5.57 | E16: 3.52 | F16: 4.18
