Workbook

Sheet Income statements Consolidated
G3: 2021 | H3: 2020 | I3: 2019 | J3: 2018 | K3: 2017
G4: Rupees in '000'
B6: Mark-up / return / interest earned | G6: 132609303 | H6: 145772451 | I6: 148088700 | J6: 87502337 | K6: 76189800
B7: Mark-up / return / interest expensed | G7: 64231302 | H7: 69929012 | I7: 84370609 | J7: 39495913 | K7: 32649614
B8: Net mark-up / interest income | G8: 68378001 | H8: 75843439 | I8: 63718091 | J8: 48006424 | K8: 43540186
B10: Net mark-up / interest income after provisions
B11: NON MARK-UP / INTEREST INCOME
B12: Fee and commission income | G12: 13691432 | H12: 11971491 | I12: 12230871 | J12: 11636751 | K12: 10454980
B13: Dividend income | G13: 1955213 | H13: 969322 | I13: 1240771 | J13: 1156944 | K13: 1632466
B14: Foreign exchange income | G14: 3847755 | H14: 2735228 | I14: 2957999 | J14: 3568576 | K14: 1677861
B15: Income from derivatives | G15: 14035 | H15: 4087 | I15: 14616 | J15: 11845 | K15: 15487
B16: Gain / (loss) on securities | G16: 262835 | H16: 3396296 | I16: 828873 | J16: 1257148 | K16: 4666214
B17: Other income | G17: 883253 | H17: 192103 | I17: 244551 | J17: 434351 | K17: 51203
B18: Total non-markup / interest Income | G18: 20654523 | H18: 19268527 | I18: 17517681 | J18: 18065615 | K18: 18498211
B19: Total Income | G19: 89032524 | H19: 95111966 | I19: 81235772 | J19: 66072039 | K19: =K8+K18 -> 62038397
B20: NON MARK-UP / INTEREST EXPENSES
B21: Operating expenses | G21: 40589732 | H21: 37763917 | I21: 37685431 | J21: 35715447 | K21: 30297380
B22: Workers welfare fund | G22: 1058419 | H22: 974808 | I22: 802046 | J22: 644304 | K22: 625969
B23: Other charges | G23: 525339 | H23: 297987 | I23: 260743 | J23: 174431 | K23: 142953
B24: Total non-markup / interest expenses | G24: 42173490 | H24: 39036712 | I24: 38748220 | J24: 36534182 | K24: 31066302
B25: Share of profit of associates | G25: 943587 | H25: 573078 | I25: 339633 | J25: 446257 | K25: 433119
B26: Profit before provisions | G26: 47802621 | H26: 56648332 | I26: 42827185 | J26: 29984114 | K26: 31661112
A27: what net | B27: (Reversals) / provisions and write offs - net | G27: -5472779 | H27: 7330044 | I27: 2673592 | J27: -821807 | K27: 1047405 | L27: Why They are in -ve
B28: Extra ordinary / unusual items
B29: PROFIT BEFORE TAXATION | G29: 53275400 | H29: 49318288 | I29: 40153593 | J29: 30805921 | K29: 30613707
B30: Taxation | G30: 21947646 | H30: 19756019 | I30: 16206382 | J30: 10390637 | K30: 8565943
B31: PROFIT AFTER TAXATION | G31: 31327754 | H31: 29562269 | I31: 23947211 | J31: 20415284 | K31: 22047764
B32: Attributable to:
B33: Equity shareholders of the Bank | G33: 31179708 | H33: 29410227 | I33: 23868249 | J33: 20352756 | K33: 21963146
B34: Non-controlling interest | G34: 148046 | H34: 152042 | I34: 78962 | J34: 62528 | K34: 84618
G35: 31327754 | H35: 29562269 | I35: =I33+I34 -> 23947211 | J35: =J33+J34 -> 20415284 | K35: =K33+K34 -> 22047764
D41: Total operating revenues | G41: =G8+G18 -> 89032524 | H41: =H8+H18 -> 95111966 | I41: =I8+I18 -> 81235772 | J41: =J8+J18 -> 66072039 | K41: =K8+K18 -> 62038397
D42: Total operating expenses | G42: =G7+G24 -> 106404792 | H42: =H7+H24 -> 108965724 | I42: =I7+I24 -> 123118829 | J42: =J7+J24 -> 76030095 | K42: =K7+K24 -> 63715916

Sheet Balance Sheet Consolidated
D3: 2021 | E3: 2020 | F3: 2019 | G3: 2018 | H3: 2017
D4: (Rupees in '000')
C5: ASSETS | K5: Interest Earning Assets
C6: Cash and balances with treasury banks | D6: 175922469 | E6: 132053041 | F6: 142957358 | G6: 110165006 | H6: 109462902 | L6: 2021 | M6: 2020 | N6: 2019 | O6: 2018 | P6: 2017
C7: Balances with other banks | D7: 22554329 | E7: 29011521 | F7: 21371753 | G7: 13338117 | H7: 7348882 | K7: Balances with other banks | L7: 22554329 | M7: 29011521 | N7: 21371753 | O7: 13338117 | P7: 7348882
C8: Lendings to financial institutions | D8: 40617110 | E8: 17968243 | F8: 6060869 | G8: 39149890 | H8: 5273524 | K8: Current Account (Deduct it) | L8: =L32 -> 12146594 | M8: =M32 -> 26778002 | N8: =N32 -> 12847895 | O8: =O32 -> 9679255 | P8: =P32 -> 3219973
C9: Investments | D9: 1062568511 | E9: 1036217535 | F9: 757441590 | G9: 754385775 | H9: 660070246 | K9: Lending to financial institutions | L9: 40617110 | M9: 17968243 | N9: 6060869 | O9: 39149890 | P9: 5273524
C10: Advances | D10: 686388652 | E10: 547685708 | F10: 548472860 | G10: 566792265 | H10: 500965801 | K10: Investments | L10: 1062568511 | M10: 1036217535 | N10: 757441590 | O10: 754385775 | P10: 660070246
C11: Fixed assets | D11: 62351545 | E11: 63679312 | F11: 64201807 | G11: 43531396 | H11: 42565448 | K11: Advances | L11: 686388652 | M11: 547685708 | N11: 548472860 | O11: 566792265 | P11: 500965801
C12: Intangible assets | D12: 1838136 | E12: 1867244 | F12: 1978975 | G12: 1452462 | H12: 1173561 | L12: =L7-L8+L9+L10+L11 -> 1799982008 | M12: =M7-M8+M9+M10+M11 -> 1604105005 | N12: =N7-N8+N9+N10+N11 -> 1320499177 | O12: =O7-O8+O9+O10+O11 -> 1363986792 | P12: =P7-P8+P9+P10+P11 -> 1170438480
C13: Deferred tax assets
C14: Other assets | D14: 69880727 | E14: 62793791 | F14: 69729659 | G14: 56395096 | H14: 63805253 | K14: Cash and balances with treasury banks | L14: 175922469 | M14: 132053041 | N14: 142957358 | O14: 110165006 | P14: 109462902
C15: TOTAL ASSETS | D15: 2122121479 | E15: 1891276395 | F15: 1612214871 | G15: 1585210007 | H15: 1389492056 | K15: Deduct Cash in hand | L15: 31584636 | M15: 32127643 | N15: 23635710 | O15: 21516831 | P15: 22560179
K16: Deduct Local currency in current accounts - SBP | L16: 89811750 | M16: 51920851 | N16: 62180493 | O16: 43735552 | P16: 48926928
C17: LIABILITIES | K17: Deduct Foreign curreny in current accounts - SBP | L17: 2937151 | M17: 2271659 | N17: 599384 | O17: 571438 | P17: 309346
C18: Bills payable | D18: 26486445 | E18: 26451513 | F18: 12795325 | G18: 17003272 | H18: 22994877 | K18: Deduct foreign currency current accounts - Other central banks | L18: 6728135 | M18: 11851311 | N18: 16220148 | O18: 5197681 | P18: 6809706
C19: Borrowings | D19: 282898882 | E19: 184577340 | F19: 92859968 | G19: 223216115 | H19: 140462138 | K19: Deduct Local currency current accounts - NBP | L19: 34016028 | M19: 22308442 | N19: 25666525 | O19: 26181864 | P19: 21424315
C20: Deposits and other accounts | D20: 1534586671 | E20: 1388737961 | F20: 1226593025 | G20: 1122306535 | H20: 1001146162
C21: Liabilities against assets subject to finance lease | L21: =L14-SUM(L15:L19) -> 10844769 | M21: =M14-SUM(M15:M19) -> 11573135 | N21: =N14-SUM(N15:N19) -> 14655098 | O21: =O14-SUM(O15:O19) -> 12961640 | P21: =P14-SUM(P15:P19) -> 9432428
C22: Subordinated debt | G22: 3891019 | H22: 3892578
C23: Deferred tax liabilities | D23: 1578782 | E23: 7491040 | F23: 6214223 | G23: 1983145 | H23: 5661073 | K23: Total Earning Assets | L23: =L12+L21 -> 1810826777 | M23: =M12+M21 -> 1615678140 | N23: =N12+N21 -> 1335154275 | O23: =O12+O21 -> 1376948432 | P23: =P12+P21 -> 1179870908
C24: Other liabilities | D24: 99002039 | E24: 91027158 | F24: 102405513 | G24: 65487042 | H24: 58792147
C25: TOTAL LIABILITIES | D25: 1944552819 | E25: 1698285012 | F25: 1440868054 | G25: 1433887128 | H25: 1232948975
C26: NET ASSETS | D26: 177568660 | E26: 192991383 | F26: 171346817 | G26: 151322879 | H26: 156543081
C28: REPRESENTED BY | K28: Balances with other Banks - Current Account | L28: 2021 | M28: 2020 | N28: 2019 | O28: 2018 | P28: 2017
C29: Share capital | D29: 11850600 | E29: 11850600 | F29: 11850600 | G29: 11850600 | H29: 11850600 | K29: Current Account - In Pakistan | L29: 27123 | M29: 9190 | N29: 9183 | O29: 3182 | P29: 3593
C30: Reserves | D30: 85043592 | E30: 81060051 | F30: 77894829 | G30: 74374573 | H30: 71027912 | K30: Current Account - Outside Pakistan | L30: 12119471 | M30: 26768812 | N30: 12838712 | O30: 9676073 | P30: 3216380
B31: what net | C31: Surplus on revaluation of assets - net | D31: 15225689 | E31: 28803351 | F31: 24752206 | G31: 10417875 | H31: 17736093
C32: Unappropriated profit | D32: 64697360 | E32: 70498820 | F32: 56108779 | G32: 53971079 | H32: 55221069 | K32: Total Currrent Account Deposit to be deducted | L32: =L29+L30 -> 12146594 | M32: =M29+M30 -> 26778002 | N32: =N29+N30 -> 12847895 | O32: =O29+O30 -> 9679255 | P32: =P29+P30 -> 3219973
D33: 176817241 | E33: 192212822 | F33: 170606414 | G33: 150614127 | H33: 155835674
C34: Non-controlling interest | D34: 751419 | E34: 778561 | F34: 740403 | G34: 708752 | H34: 707407
D35: 177568660 | E35: 192991383 | F35: 171346817 | G35: 151322879 | H35: 156543081
K36: Interest Bearing Liabilities
C37: Total Equity | D37: =D29+D30+D31+D32+D34 -> 177568660 | E37: =E29+E30+E31+E32+E34 -> 192991383 | F37: =F29+F30+F31+F32+F34 -> 171346817 | G37: =G29+G30+G31+G32+G34 -> 151322879 | H37: =H29+H30+H31+H32+H34 -> 156543081 | L37: 2021 | M37: 2020 | N37: 2019 | O37: 2018 | P37: 2017
C38: Total Liabilties + Equity | D38: =D25+D37 -> 2122121479 | E38: =E25+E37 -> 1891276395 | F38: =F25+F37 -> 1612214871 | G38: =G25+G37 -> 1585210007 | H38: =H25+H37 -> 1389492056 | K38: Bills payable | L38: =D18 -> 26486445 | M38: =E18 -> 26451513 | N38: =F18 -> 12795325 | O38: =G18 -> 17003272 | P38: =H18 -> 22994877
K39: Borrowings | L39: =D19 -> 282898882 | M39: =E19 -> 184577340 | N39: =F19 -> 92859968 | O39: =G19 -> 223216115 | P39: =H19 -> 140462138
K40: Subordinated debt | O40: =G22 -> 3891019 | P40: =H22 -> 3892578
L42: =SUM(L38:L40) -> 309385327 | M42: =SUM(M38:M40) -> 211028853 | N42: =SUM(N38:N40) -> 105655293 | O42: =SUM(O38:O40) -> 244110406 | P42: =SUM(P38:P40) -> 167349593
K44: Deposits and other accounts | L44: =D20 -> 1534586671 | M44: =E20 -> 1388737961 | N44: =F20 -> 1226593025 | O44: =G20 -> 1122306535 | P44: =H20 -> 1001146162
K45: (Deduct) Current Accounts - Customers
...

Sheet Profitability Ratios
G2: 2021 | H2: 2020 | I2: 2019 | J2: 2018 | K2: 2017
D3: Total Equity | G3: ='Balance Sheet Consolidated'!D37 -> 177568660 | H3: ='Balance Sheet Consolidated'!E37 -> 192991383 | I3: ='Balance Sheet Consolidated'!F37 -> 171346817 | J3: ='Balance Sheet Consolidated'!G37 -> 151322879 | K3: ='Balance Sheet Consolidated'!H37 -> 156543081
D4: Pre-Tax Net Operating Income | G4: ='Income statements Consolidated'!G30 -> 21947646 | H4: ='Income statements Consolidated'!H30 -> 19756019 | I4: ='Income statements Consolidated'!I30 -> 16206382 | J4: ='Income statements Consolidated'!J30 -> 10390637 | K4: ='Income statements Consolidated'!K30 -> 8565943
D5: Profit After Taxation (Net Income) | G5: ='Income statements Consolidated'!G31 -> 31327754 | H5: ='Income statements Consolidated'!H31 -> 29562269 | I5: ='Income statements Consolidated'!I31 -> 23947211 | J5: ='Income statements Consolidated'!J31 -> 20415284 | K5: ='Income statements Consolidated'!K31 -> 22047764
D6: Total Operating Revenues (Net Interest + Net Non Interest) | G6: ='Income statements Consolidated'!G19 -> 89032524 | H6: ='Income statements Consolidated'!H19 -> 95111966 | I6: ='Income statements Consolidated'!I19 -> 81235772 | J6: ='Income statements Consolidated'!J19 -> 66072039 | K6: ='Income statements Consolidated'!K19 -> 62038397
D7: Total Operating Expenses (Net Interest + Net Non Interest) | G7: ='Income statements Consolidated'!G42 -> 106404792 | H7: ='Income statements Consolidated'!H42 -> 108965724 | I7: ='Income statements Consolidated'!I42 -> 123118829 | J7: ='Income statements Consolidated'!J42 -> 76030095 | K7: ='Income statements Consolidated'!K42 -> 63715916
D8: Total Assets | G8: ='Balance Sheet Consolidated'!D15 -> 2122121479 | H8: ='Balance Sheet Consolidated'!E15 -> 1891276395 | I8: ='Balance Sheet Consolidated'!F15 -> 1612214871 | J8: ='Balance Sheet Consolidated'!G15 -> 1585210007 | K8: ='Balance Sheet Consolidated'!H15 -> 1389492056
D9: Net Interest Income | G9: ='Income statements Consolidated'!G8 -> 68378001 | H9: ='Income statements Consolidated'!H8 -> 75843439 | I9: ='Income statements Consolidated'!I8 -> 63718091 | J9: ='Income statements Consolidated'!J8 -> 48006424 | K9: ='Income statements Consolidated'!K8 -> 43540186
D10: Net Non Interest Income | G10: ='Income statements Consolidated'!G18-'Income statements Consolidated'!G24 -> -21518967 | H10: ='Income statements Consolidated'!H18-'Income statements Consolidated'!H24 -> -19768185 | I10: ='Income statements Consolidated'!I18-'Income statements Consolidated'!I24 -> -21230539 | J10: ='Income statements Consolidated'!J18-'Income statements Consolidated'!J24 -> -18468567 | K10: ='Income statements Consolidated'!K18-'Income statements Consolidated'!K24 -> -12568091
D11: Net Operating Income (Pre Tax) | G11: ='Income statements Consolidated'!G26 -> 47802621 | H11: ='Income statements Consolidated'!H26 -> 56648332 | I11: ='Income statements Consolidated'!I26 -> 42827185 | J11: ='Income statements Consolidated'!J26 -> 29984114 | K11: ='Income statements Consolidated'!K26 -> 31661112
D12: Common Shares Outstanding | G12: 1185060006 | H12: 1185060006 | I12: 1185060006 | J12: 1185060006 | K12: 1147960005
D13: Total Earning Assets | G13: ='Balance Sheet Consolidated'!L23 -> 1810826777 | H13: ='Balance Sheet Consolidated'!M23 -> 1615678140 | I13: ='Balance Sheet Consolidated'!N23 -> 1335154275 | J13: ='Balance Sheet Consolidated'!O23 -> 1376948432 | K13: ='Balance Sheet Consolidated'!P23 -> 1179870908
D14: Total Interest Bearing Liabilities | G14: ='Balance Sheet Consolidated'!L54 -> 1272388564 | H14: ='Balance Sheet Consolidated'!M54 -> 1106314022 | I14: ='Balance Sheet Consolidated'!N54 -> 909989503 | J14: ='Balance Sheet Consolidated'!O54 -> 973973744 | K14: ='Balance Sheet Consolidated'!P54 -> 817258185
D15: Interest Income | G15: ='Income statements Consolidated'!G6 -> 132609303 | H15: ='Income statements Consolidated'!H6 -> 145772451 | I15: ='Income statements Consolidated'!I6 -> 148088700 | J15: ='Income statements Consolidated'!J6 -> 87502337 | K15: ='Income statements Consolidated'!K6 -> 76189800
D16: Interest Expenses | G16: ='Income statements Consolidated'!G7 -> 64231302 | H16: ='Income statements Consolidated'!H7 -> 69929012 | I16: ='Income statements Consolidated'!I7 -> 84370609 | J16: ='Income statements Consolidated'!J7 -> 39495913 | K16: ='Income statements Consolidated'!K7 -> 32649614
G19: 2021 | H19: 2020 | I19: 2019 | J19: 2018 | K19: 2017
E21: Return on Capital (ROE) | F21: NI/(Total Equity Capital) | G21: =G5/G3 -> 0.17642614 | H21: =H5/H3 -> 0.15317922 | I21: =I5/I3 -> 0.13975872 | J21: =J5/J3 -> 0.13491208 | K21: =K5/K3 -> 0.14084151
E22: Return on Assets (ROA) | F22: NI/(Total Assets) | G22: =G5/G8 -> 0.01476247 | H22: =H5/H8 -> 0.015630856 | I22: =I5/I8 -> 0.01485361 | J22: =J5/J8 -> 0.012878599 | K22: =K5/K8 -> 0.015867499
E23: Net Interest Margin | F23: Net Interest Income/(TA) | G23: =G9/G8 -> 0.03222153 | H23: =H9/H8 -> 0.040101721 | I23: =I9/I8 -> 0.039522084 | J23: =J9/J8 -> 0.030283952 | K23: =K9/K8 -> 0.031335326
E24: Net Non Interest Margin | F24: Net Non Interest income/TA | G24: =G10/G8 -> -0.010140309 | H24: =H10/H8 -> -0.010452298 | I24: =I10/I8 -> -0.013168554 | J24: =J10/J8 -> -0.011650549 | K24: =K10/K8 -> -0.0090450974
E25: Net Bank Operating Margin | F25: Net Operating Revenue/Total Assets | G25: =(G6-G7)/G8 -> -0.0081862741 | H25: =(H6-H7)/H8 -> -0.0073250838 | I25: =(I6-I7)/I8 -> -0.025978582 | J25: =(J6-J7)/J8 -> -0.0062818528 | K25: =(K6-K7)/K8 -> -0.0012072894
E27: Net Profit Margin (NPM) | F27: NI/Total OP Revenues | G27: =G5/G6 -> 0.35186865 | H27: =H5/H6 -> 0.31081546 | I27: =I5/I6 -> 0.29478653 | J27: =J5/J6 -> 0.30898523 | K27: =K5/K6 -> 0.355389
E28: Equity Multiplier (EM) | F28: Total Assets/Total Equity | G28: =G8/G3 -> 11.950991 | H28: =H8/H3 -> 9.7997971 | I28: =I8/I3 -> 9.4090739 | J28: =J8/J3 -> 10.47568 | K28: =K8/K3 -> 8.8761001
E29: Asset Utilization (AU) | F29: Total OP Revenues/Total Assets | G29: =G6/G8 -> 0.04195449 | H29: =H6/H8 -> 0.050289829 | I29: =I6/I8 -> 0.050387683 | J29: =J6/J8 -> 0.041680307 | K29: =K6/K8 -> 0.044648256
E30: ROE (from Above 3) | F30: NPM*EM*AU | G30: =G27*G28*G29 -> 0.17642614 | H30: =H27*H28*H29 -> 0.15317922 | I30: =I27*I28*I29 -> 0.13975872 | J30: =J27*J28*J29 -> 0.13491208 | K30: =K27*K28*K29 -> 0.14084151
E34: Expense Control Efficiency | F34: Pre-Tax Net Operating Income/ Total Operating Revenue | G34: =G11/G6 -> 0.53691189 | H34: =H11/H6 -> 0.59559627 | I34: =I11/I6 -> 0.52719613 | J34: =J11/J6 -> 0.45380942 | K34: =K11/K6 -> 0.51034704
E35: Tax Management Efficiency | F35: Net Income/Pre-Tax Net Operating Income | G35: =G5/G11 -> 0.65535641 | H35: =H5/H11 -> 0.52185595 | I35: =I5/I11 -> 0.55915912 | J35: =J5/J11 -> 0.68087001 | K35: =K5/K11 -> 0.69636733
E36: Asset Management Efficiency | F36: Total Operating Revenue/ Total Assets | G36: =G6/G8 -> 0.04195449 | H36: =H6/H8 -> 0.050289829 | I36: =I6/I8 -> 0.050387683 | J36: =J6/J8 -> 0.041680307 | K36: =K6/K8 -> 0.044648256
E37: Funds Management Efficiency | F37: Total Assets/Total Equity Capital | G37: =G8/G3 -> 11.950991 | H37: =H8/H3 -> 9.7997971 | I37: =I8/I3 -> 9.4090739 | J37: =J8/J3 -> 10.47568 | K37: =K8/K3 -> 8.8761001
E38: ROE (from Above 4) | F38: Expense Control Efficiency*Tax Management Efficiency*Asset Mangement Efficiency*Funds Management Efficiency | G38: =G34*G35*G36*G37 -> 0.17642614 | H38: =H34*H35*H36*H37 -> 0.15317922 | I38: =I34*I35*I36*I37 -> 0.13975872 | J38: =J34*J35*J36*J37 -> 0.13491208 | K38: =K34*K35*K36*K37 -> 0.14084151
E41: Earning Spread | F41: (Total Interest Income/Total Earning Assets-Total Interest Expense/Total Interest Bearing Liability | G41: =(G15/G13)-(G16/G14) -> 0.022750471 | H41: =(H15/H13)-(H16/H14) -> 0.027014686 | I41: =(I15/I13)-(I16/I14) -> 0.018199023 | J41: =(J15/J13)-(J16/J14) -> 0.022996701 | K41: =(K15/K13)-(K16/K14) -> 0.024624509
E44: Earning Per Share (PKR/share) | F44: NI/Total Shares Outstanding | G44: =G5/G12 -> 0.026435585 | H44: =H5/H12 -> 0.024945799 | I44: =I5/I12 -> 0.020207594 | J44: =J5/J12 -> 0.017227215 | K44: =K5/K12 -> 0.019206038
F49: DUPONT ANALYSIS
G50: 2021 | H50: 2020 | I50: 2019 | J50: 2018 | K50: 2017
F52: ROE (Net Income/Total Equity Capital) | G52: =G38 -> 0.17642614 | H52: =H38 -> 0.15317922 | I52: =I38 -> 0.13975872 | J52: =J38 -> 0.13491208 | K52: =K38 -> 0.14084151
F53: ROE = ROA * (Equity Multiplier)
F55: Breakdown of ROE
F57: ROA (Net Income/Total Assets) | G57: =G22 -> 0.01476247 | H57: =H22 -> 0.015630856 | I57: =I22 -> 0.01485361 | J57: =J22 -> 0.012878599 | K57: =K22 -> 0.015867499
F58: - Net Profit Margin | G58: =G27 -> 0.35186865 | H58: =H27 -> 0.31081546 | I58: =I27 -> 0.29478653 | J58: =J27 -> 0.30898523 | K58: =K27 -> 0.355389
F59: - Asset Utilization | G59: =G29 -> 0.04195449 | H59: =H29 -> 0.050289829 | I59: =I29 -> 0.050387683 | J59: =J29 -> 0.041680307 | K59: =K29 -> 0.044648256
...

Sheet RIsk Measures Ratio
O2: 2021 | P2: 2020 | Q2: 2019 | R2: 2018 | S2: 2017
C3: Capital Risk Measures | L3: Total Equity | O3: ='Profitability Ratios'!G3 -> 177568660 | P3: ='Profitability Ratios'!H3 -> 192991383 | Q3: ='Profitability Ratios'!I3 -> 171346817 | R3: ='Profitability Ratios'!J3 -> 151322879 | S3: ='Profitability Ratios'!K3 -> 156543081
F4: 2021 | G4: 2020 | H4: 2019 | I4: 2018 | J4: 2017 | L4: Total Assets | O4: ='Profitability Ratios'!G8 -> 2122121479 | P4: ='Profitability Ratios'!H8 -> 1891276395 | Q4: ='Profitability Ratios'!I8 -> 1612214871 | R4: ='Profitability Ratios'!J8 -> 1585210007 | S4: ='Profitability Ratios'!K8 -> 1389492056
C5: Stock price / EPS | F5: =O13/O19 -> 5800.8931 | G5: =P13/P19 -> 7427.3026 | H5: =Q13/Q19 -> 10149.155 | I5: =R13/R19 -> 11236.291 | J5: =S13/S19 -> 10545.642 | L5: Total Liabilities | O5: ='Balance Sheet Consolidated'!D25 -> 1944552819 | P5: ='Balance Sheet Consolidated'!E25 -> 1698285012 | Q5: ='Balance Sheet Consolidated'!F25 -> 1440868054 | R5: ='Balance Sheet Consolidated'!G25 -> 1433887128 | S5: ='Balance Sheet Consolidated'!H25 -> 1232948975
C6: Equity Capital / Total Assets | F6: =O3/O4 -> 0.083675068 | G6: =P3/P4 -> 0.10204293 | H6: =Q3/Q4 -> 0.10628038 | I6: =R3/R4 -> 0.0954592 | J6: =S3/S4 -> 0.11266209 | L6: Total Deposits | O6: ='Balance Sheet Consolidated'!D20 -> 1534586671 | P6: ='Balance Sheet Consolidated'!E20 -> 1388737961 | Q6: ='Balance Sheet Consolidated'!F20 -> 1226593025 | R6: ='Balance Sheet Consolidated'!G20 -> 1122306535 | S6: ='Balance Sheet Consolidated'!H20 -> 1001146162
C7: Purchased Funds / Total Liabilities | F7: =O30/O5 -> 0.056150987 | G7: =P30/P5 -> 0.045396131 | H7: =Q30/Q5 -> 0.036817561 | I7: =R30/R5 -> 0.029865068 | J7: =S30/S5 -> 0.032169674 | L7: Uninsured Deposits | O7: =O46 -> 489020153 | P7: =P46 -> 431619365 | Q7: =Q46 -> 393690515 | R7: =R46 -> 329400809 | S7: =S46 -> 302015652
C8: Equity Capital / Risk Assets | F8: =O3/O9 -> 0.099223968 | G8: =P3/P9 -> 0.12047869 | H8: =Q3/Q9 -> 0.13060216 | I8: =R3/R9 -> 0.11124 | J8: =S3/S9 -> 0.13422087 | L8: Total Loans | O8: =O35 -> 732440841 | P8: =P35 -> 598365775 | Q8: =Q35 -> 591871632 | R8: =R35 -> 610028645 | S8: =S35 -> 493089800
L9: Risk Assets | O9: =SUM('Balance Sheet Consolidated'!D8:D10) -> 1789574273 | P9: =SUM('Balance Sheet Consolidated'!E8:E10) -> 1601871486 | Q9: =SUM('Balance Sheet Consolidated'!F8:F10) -> 1311975319 | R9: =SUM('Balance Sheet Consolidated'!G8:G10) -> 1360327930 | S9: =SUM('Balance Sheet Consolidated'!H8:H10) -> 1166309571
C10: Other Goals in Banking | L10: Purchased Funds | O10: =O30 -> 109188561 | P10: =P30 -> 77095569 | Q10: =Q30 -> 53049247 | R10: =R30 -> 42823137 | S10: =S30 -> 39663567
F11: 2021 | G11: 2020 | H11: 2019 | I11: 2018 | J11: 2017 | L11: Interest Earninigs Assets | O11: ='Profitability Ratios'!G13 -> 1810826777 | P11: ='Profitability Ratios'!H13 -> 1615678140 | Q11: ='Profitability Ratios'!I13 -> 1335154275 | R11: ='Profitability Ratios'!J13 -> 1376948432 | S11: ='Profitability Ratios'!K13 -> 1179870908
C12: Operating Efficiency Ratio | F12: =O21/O20 -> 1.1951227 | G12: =P21/P20 -> 1.1456574 | H12: =Q21/Q20 -> 1.5155741 | I12: =R21/R20 -> 1.1507151 | J12: =S21/S20 -> 1.02704 | L12: Interest Bearing Liabilities | O12: ='Profitability Ratios'!G14 -> 1272388564 | P12: ='Profitability Ratios'!H14 -> 1106314022 | Q12: ='Profitability Ratios'!I14 -> 909989503 | R12: ='Profitability Ratios'!J14 -> 973973744 | S12: ='Profitability Ratios'!K14 -> 817258185
C13: Employee Productive Ratio =(Non Performing Loans/No. of permamanet employees) | F13: =O34/O16 -> 3296.579 | G13: =P34/P16 -> 3365.0008 | H13: =Q34/Q16 -> 3694.7838 | I13: =R34/R16 -> 3807.6449 | J13: =S34/S16 -> 3662.6228 | L13: Stock Price | O13: 153.35 | P13: 185.28 | Q13: 205.09 | R13: 193.57 | S13: 202.54
L14: Non Performing Loans | O14: 51192575 | P14: 51945518 | Q14: 49424259 | R14: 48955548 | S14: 48753000
C15: Interest Rate Risk Measures | L15: Provisions | O15: 44281189 | P15: 45168351 | Q15: 41934421 | R15: 41943509 | S15: 44587000
F16: 2021 | G16: 2020 | H16: 2019 | I16: 2018 | J16: 2017 | L16: Permanent Staffs | O16: 15529 | P16: 15437 | Q16: 13480 | R16: 12860 | S16: 13014
C17: Interest Sensitive Assets/Interest Sensitive Liabilities | F17: =O6/O7 -> 3.1380847 | G17: =P6/P7 -> 3.2175061 | H17: =Q6/Q7 -> 3.1156276 | I17: =R6/R7 -> 3.4071153 | J17: =S6/S7 -> 3.3148817 | L17: Net Loans = Total Loans - Provisions | O17: =O8-O15 -> 688159652 | P17: =P8-P15 -> 553197424 | Q17: =Q8-Q15 -> 549937211 | R17: =R8-R15 -> 568085136 | S17: =S8-S15 -> 448502800
C18: Uninsured Deposits/Total Deposits | F18: =O41/O39 -> 1.6841966 | G18: =P41/P39 -> 1.5458834 | H18: =Q41/Q39 -> 1.7321142 | I18: =R41/R39 -> 1.8032258 | J18: =S41/S39 -> 1.7669477 | L18: Charge Offs | O18: 2687996 | P18: 9837173 | Q18: 3534252 | R18: 1772254 | S18: 3340193
L19: EPS | O19: ='Profitability Ratios'!G44 -> 0.026435585 | P19: ='Profitability Ratios'!H44 -> 0.024945799 | Q19: ='Profitability Ratios'!I44 -> 0.020207594 | R19: ='Profitability Ratios'!J44 -> 0.017227215 | S19: ='Profitability Ratios'!K44 -> 0.019206038
C20: Market Risk Measures | L20: Operating Revenues | O20: ='Profitability Ratios'!G6 -> 89032524 | P20: ='Profitability Ratios'!H6 -> 95111966 | Q20: ='Profitability Ratios'!I6 -> 81235772 | R20: ='Profitability Ratios'!J6 -> 66072039 | S20: ='Profitability Ratios'!K6 -> 62038397
F21: 2021 | G21: 2020 | H21: 2019 | I21: 2018 | J21: 2017 | L21: Operating Expenses | O21: ='Profitability Ratios'!G7 -> 106404792 | P21: ='Profitability Ratios'!H7 -> 108965724 | Q21: ='Profitability Ratios'!I7 -> 123118829 | R21: ='Profitability Ratios'!J7 -> 76030095 | S21: ='Profitability Ratios'!K7 -> 63715916
C22: Book-Value of Assets/ Market Value of Assets | F22: =O24/O22 -> 2.0546089 | G22: =P24/P22 -> 1.8685009 | H22: =Q24/Q22 -> 1.9823372 | I22: =R24/R22 -> 2.2195967 | J22: =S24/S22 -> 2.2350043 | L22: Market value of Assets | O22: 1032859095 | P22: 1012189158 | Q22: 813289931 | R22: 714188317 | S22: 621695481
C23: Book-Value of Equity/ Market Value of Equity | L23: Market value of Equity
C24: Book-Value of Bonds/Market Value of Bonds | L24: Book Value of Assets | O24: ='Balance Sheet Consolidated'!D15 -> 2122121479 | P24: ='Balance Sheet Consolidated'!E15 -> 1891276395 | Q24: ='Balance Sheet Consolidated'!F15 -> 1612214871 | R24: ='Balance Sheet Consolidated'!G15 -> 1585210007 | S24: ='Balance Sheet Consolidated'!H15 -> 1389492056
C25: Market Value of Preferred Stock and Common Stock | L25: Book Value of Equity | O25: ='Balance Sheet Consolidated'!D37 -> 177568660 | P25: ='Balance Sheet Consolidated'!E37 -> 192991383 | Q25: ='Balance Sheet Consolidated'!F37 -> 171346817 | R25: ='Balance Sheet Consolidated'!G37 -> 151322879 | S25: ='Balance Sheet Consolidated'!H37 -> 156543081
C27: Liquidity Risk Measures | N27: Purchased Funds | O27: 2021 | P27: 2020 | Q27: 2019 | R27: 2018 | S27: 2017
F28: 2021 | G28: 2020 | H28: 2019 | I28: 2018 | J28: 2017 | N28: Borrowings from State Bank | O28: 108724289 | P28: 75375228 | Q28: 52274333 | R28: 42266198 | S28: 37831766
C29: Purchased Funds/Total Assets | F29: =O30/O4 -> 0.05145255 | G29: =P30/P4 -> 0.040763777 | H29: =Q30/Q4 -> 0.032904576 | I29: =R30/R4 -> 0.027014173 | J29: =S30/S4 -> 0.028545372 | N29: Borrwing from other financial institutions | O29: 464272 | P29: 1720341 | Q29: 774914 | R29: 556939 | S29: 1831801
C30: Net Loans/Total Assets | F30: =O17/O4 -> 0.3242791 | G30: =P17/P4 -> 0.29249951 | H30: =Q17/Q4 -> 0.34110665 | I30: =R17/R4 -> 0.35836585 | J30: =S17/S4 -> 0.32278184 | N30: Total Purchased Funds | O30: =SUM(O28:O29) -> 109188561 | P30: =SUM(P28:P29) -> 77095569 | Q30: =SUM(Q28:Q29) -> 53049247 | R30: =SUM(R28:R29) -> 42823137 | S30: =SUM(S28:S29) -> 39663567
C31: Cash and Due from Banks/Total Assets | F31: =O51/O4 -> 0.025511718 | G31: =P51/P4 -> 0.032326932 | H31: =Q51/Q4 -> 0.027916541 | I31: =R51/R4 -> 0.02198759 | J31: =S51/S4 -> 0.021525176
C32: Cash and Government Securities/Total Assets | F32: =O56/O4 -> 0.08289934 | G32: =P56/P4 -> 0.06982218 | H32: =Q56/Q4 -> 0.088671405 | I32: =R56/R4 -> 0.069495528 | J32: =S56/S4 -> 0.078779077 | N32: Total Loans | O32: 2021 | P32: 2020 | Q32: 2019 | R32: 2018 | S32: 2017
N33: Total Performing Loans | O33: 681248266 | P33: 546420257 | Q33: 542065946 | R33: 561062331 | S33: 445424427
C34: Credit Risk Measures | N34: Non Performing Loans | O34: 51192575 | P34: 51945518 | Q34: 49805686 | R34: 48966314 | S34: 47665373
F35: 2021 | G35: 2020 | H35: 2019 | I35: 2018 | J35: 2017 | N35: Total Loans | O35: =O33+O34 -> 732440841 | P35: =P33+P34 -> 598365775 | Q35: =Q33+Q34 -> 591871632 | R35: =R33+R34 -> 610028645 | S35: =S33+S34 -> 493089800
C36: Nonperforming Loans/Total Loans | F36: =O34/O35 -> 0.069893119 | G36: =P34/P35 -> 0.086812315 | H36: =Q34/Q35 -> 0.084149473 | I36: =R34/R35 -> 0.080268877 | J36: =S34/S35 -> 0.096666719
C37: Net Charge-Offs/Total Loans | F37: =O18/O35 -> 0.0036699155 | G37: =P18/P35 -> 0.016440066 | H37: =Q18/Q35 -> 0.0059713151 | I37: =R18/R35 -> 0.002905198 | J37: =S18/S35 -> 0.0067740055 | N37: Total Risk Assets | O37: 2021 | P37: 2020 | Q37: 2019 | R37: 2018 | S37: 2017
C38: Provision for Loan Losses/Total Loans | F38: =O15/O35 -> 0.060457018 | G38: =P15/P35 -> 0.075486187 | H38: =Q15/Q35 -> 0.070850534 | I38: =R15/R35 -> 0.068756622 | J38: =S15/S35 -> 0.090423692 | N38: Lending to Finacnial institutions | O38: ='Balance Sheet Consolidated'!D8 -> 40617110 | P38: ='Balance Sheet Consolidated'!E8 -> 17968243 | Q38: ='Balance Sheet Consolidated'!F8 -> 6060869 | R38: ='Balance Sheet Consolidated'!G8 -> 39149890 | S38: ='Balance Sheet Consolidated'!H8 -> 5273524
C39: Provision for Loan Losses/Equity Capital | F39: =O15/O3 -> 0.24937502 | G39: =P15/P3 -> 0.23404336 | H39: =Q15/Q3 -> 0.24473417 | I39: =R15/R3 -> 0.2771789 | J39: =S15/S3 -> 0.28482255 | N39: Investments | O39: ='Balance Sheet Consolidated'!D9 -> 1062568511 | P39: ='Balance Sheet Consolidated'!E9 -> 1036217535 | Q39: ='Balance Sheet Consolidated'!F9 -> 757441590 | R39: ='Balance Sheet Consolidated'!G9 -> 754385775 | S39: ='Balance Sheet Consolidated'!H9 -> 660070246
C40: Allowance for Loan Losses/Total Loans | F40: =O62/O35 -> 0.066683735 | G40: =P62/P35 -> 0.062854628 | H40: =Q62/Q35 -> 0.071095227 | I40: =R62/R35 -> 0.073428722 | J40: =S62/S35 -> 0.096293823 | N40: Advances | O40: ='Balance Sheet Consolidated'!D10 -> 686388652 | P40: ='Balance Sheet Consolidated'!E10 -> 547685708 | Q40: ='Balance Sheet Consolidated'!F10 -> 548472860 | R40: ='Balance Sheet Consolidated'!G10 -> 566792265 | S40: ='Balance Sheet Consolidated'!H10 -> 500965801
C41: Allowance for Loan Losses/Equity Capital | F41: =O62/O3 -> 0.27505919 | G41: =P62/P3 -> 0.19487947 | H41: =Q62/Q3 -> 0.2455794 | I41: =R62/R3 -> 0.29601356 | J41: =S62/S3 -> 0.30331268 | N41: Total Risk Assets | O41: =SUM(O38:O40) -> 1789574273 | P41: =SUM(P38:P40) -> 1601871486 | Q41: =SUM(Q38:Q40) -> 1311975319 | R41: =SUM(R38:R40) -> 1360327930 | S41: =SUM(S38:S40) -> 1166309571
C42: Nonperforming Loans/Equity Capital | F42: =O14/O3 -> 0.28829735 | G42: =P14/P3 -> 0.26915978 | H42: =Q14/Q3 -> 0.28844574 | I42: =R14/R3 -> 0.32351716 | J42: =S14/S3 -> 0.31143504
...

Sheet C.A.M.E.L.S
M3: Total Securities | N3: 2021 | O3: 2020 | P3: 2019 | Q3: 2018 | R3: 2017
M4: Federal Government Securities | N4: 1014920266 | O4: 987228543 | P4: 710382910 | Q4: 710544756 | R4: 616940868
M5: Treasury Securities | N5: ='RIsk Measures Ratio'!O55 -> 144337833 | O5: ='RIsk Measures Ratio'!P55 -> 99925398 | P5: ='RIsk Measures Ratio'!Q55 -> 119321648 | Q5: ='RIsk Measures Ratio'!R55 -> 88648175 | R5: ='RIsk Measures Ratio'!S55 -> 86902723
M6: Provincial Government Securities | N6: 23877312 | O6: 21923938 | P6: 18462438 | Q6: 20444791 | R6: 23488891
M7: No Government Debt Securities | N7: 10153608 | O7: 11983596 | P7: 12333239 | Q7: 11038267 | R7: 9114514
M8: Foreign Securities | N8: 8334043 | O8: 10606098 | P8: 11987345 | Q8: 8338435 | R8: 6069734
M9: Purchase of Governemnt Securities | N9: =26076+19077222+5096819 -> 24200117 | O9: =19827+999+1232917+653148 -> 1906891 | P9: =58956+6410544+17302184 -> 23771684 | Q9: =27486+6699290+297767019 -> 304493795 | R9: =6568012+54507456 -> 61075468
M11: Total Securities | N11: =SUM(N4:N9) -> 1225823179 | O11: =SUM(O4:O9) -> 1133574464 | P11: =SUM(P4:P9) -> 896259264 | Q11: =SUM(Q4:Q9) -> 1143508219 | R11: =SUM(R4:R9) -> 803592198
B17: CAMELS
G18: 2021 | H18: 2020 | I18: 2019 | J18: 2018 | K18: 2017
B19: Capital Adequacy Ratio | G19: ='RIsk Measures Ratio'!F46 -> 0.1599 | H19: ='RIsk Measures Ratio'!G46 -> 0.1969 | I19: ='RIsk Measures Ratio'!H46 -> 0.1886 | J19: ='RIsk Measures Ratio'!I46 -> 0.1813 | K19: ='RIsk Measures Ratio'!J46 -> 0.1634
B21: Rankings | G21: 1 | H21: 1 | I21: 1 | J21: 1 | K21: 1
B22: Weightage | G22: 0.2 | H22: 0.2 | I22: 0.2 | J22: 0.2 | K22: 0.2
B24: Value | G24: =G21*G22 -> 0.2 | H24: =H21*H22 -> 0.2 | I24: =I21*I22 -> 0.2 | J24: =J21*J22 -> 0.2 | K24: =K21*K22 -> 0.2
B27: CAMELS
G28: 2021 | H28: 2020 | I28: 2019 | J28: 2018 | K28: 2017
B29: Non performing Loans / Advances | G29: ='RIsk Measures Ratio'!O34/'RIsk Measures Ratio'!O40 -> 0.07458249 | H29: ='RIsk Measures Ratio'!P34/'RIsk Measures Ratio'!P40 -> 0.094845488 | I29: ='RIsk Measures Ratio'!Q34/'RIsk Measures Ratio'!Q40 -> 0.090807932 | J29: ='RIsk Measures Ratio'!R34/'RIsk Measures Ratio'!R40 -> 0.086391994 | K29: ='RIsk Measures Ratio'!S34/'RIsk Measures Ratio'!S40 -> 0.09514696
B31: Rankings | G31: 4 | H31: 4 | I31: 4 | J31: 4 | K31: 5
B32: Weightage | G32: 0.2 | H32: 0.2 | I32: 0.2 | J32: 0.2 | K32: 0.2
B34: Value | G34: =G31*G32 -> 0.8 | H34: =H31*H32 -> 0.8 | I34: =I31*I32 -> 0.8 | J34: =J31*J32 -> 0.8 | K34: =K31*K32 -> 1
B36: CAMELS
G37: 2021 | H37: 2020 | I37: 2019 | J37: 2018 | K37: 2017
B38: Fee and Commission /Net Income | G38: ='Income statements Consolidated'!G12/'Income statements Consolidated'!G31 -> 0.43703842 | H38: ='Income statements Consolidated'!H12/'Income statements Consolidated'!H31 -> 0.40495846 | I38: ='Income statements Consolidated'!I12/'Income statements Consolidated'!I31 -> 0.51074303 | J38: ='Income statements Consolidated'!J12/'Income statements Consolidated'!J31 -> 0.57000192 | K38: ='Income statements Consolidated'!K12/'Income statements Consolidated'!K31 -> 0.47419684
B40: Rankings | G40: 4 | H40: 4 | I40: 5 | J40: 5 | K40: 5
B41: Weightage | G41: 0.25 | H41: 0.25 | I41: 0.25 | J41: 0.25 | K41: 0.25
B43: Value | G43: =G40*G41 -> 1 | H43: =H40*H41 -> 1 | I43: =I40*I41 -> 1.25 | J43: =J40*J41 -> 1.25 | K43: =K40*K41 -> 1.25
B45: CAMELS
G46: 2021 | H46: 2020 | I46: 2019 | J46: 2018 | K46: 2017
B47: ROE | G47: ='Profitability Ratios'!G21 -> 0.17642614 | H47: ='Profitability Ratios'!H21 -> 0.15317922 | I47: ='Profitability Ratios'!I21 -> 0.13975872 | J47: ='Profitability Ratios'!J21 -> 0.13491208 | K47: ='Profitability Ratios'!K21 -> 0.14084151
B49: Rankings | G49: 2 | H49: 3 | I49: 3 | J49: 3 | K49: 3
B50: Weightage | G50: 0.15 | H50: 0.15 | I50: 0.15 | J50: 0.15 | K50: 0.15
B52: Value | G52: =G49*G50 -> 0.3 | H52: =H49*H50 -> 0.45 | I52: =I49*I50 -> 0.45 | J52: =J49*J50 -> 0.45 | K52: =K49*K50 -> 0.45
B54: ROA | G54: ='Profitability Ratios'!G22 -> 0.01476247 | H54: ='Profitability Ratios'!H22 -> 0.015630856 | I54: ='Profitability Ratios'!I22 -> 0.01485361 | J54: ='Profitability Ratios'!J22 -> 0.012878599 | K54: ='Profitability Ratios'!K22 -> 0.015867499
B56: Rankings | G56: 2 | H56: 1 | I56: 2 | J56: 2 | K56: 1
B57: Weightage | G57: 0.15 | H57: 0.15 | I57: 0.15 | J57: 0.15 | K57: 0.15
B59: Value | G59: =G56*G57 -> 0.3 | H59: =H56*H57 -> 0.15 | I59: =I56*I57 -> 0.3 | J59: =J56*J57 -> 0.3 | K59: =K56*K57 -> 0.15
B62: CAMELS
G63: 2021 | H63: 2020 | I63: 2019 | J63: 2018 | K63: 2017
B64: Advances / Deposits | G64: ='RIsk Measures Ratio'!O40/'RIsk Measures Ratio'!O44 -> 0.44467127 | H64: ='RIsk Measures Ratio'!P40/'RIsk Measures Ratio'!P44 -> 0.39437657 | I64: ='RIsk Measures Ratio'!Q40/'RIsk Measures Ratio'!Q44 -> 0.47911466 | J64: ='RIsk Measures Ratio'!R40/'RIsk Measures Ratio'!R44 -> 0.54029737 | K64: ='RIsk Measures Ratio'!S40/'RIsk Measures Ratio'!S44 -> 0.50039227
B66: Rankings | G66: 1 | H66: 1 | I66: 1 | J66: 1 | K66: 1
...
