Workbook

Sheet Balance Sheet
A1: Rupees in ‘000 | B1: 2021 | C1: 2020 | D1: 2019 | E1: 2018 | F1: 2017
A3: Assets
A4: Cash and balances with treasury banks | B4: 89432245 | C4: 73651718 | D4: 63039290 | E4: 49187645 | F4: 44239325
A5: Balances with other banks | B5: 3556215 | C5: 8196147 | D5: 7886702 | E5: 4093402 | F5: 3193835
A6: Lendings to financial institutions | B6: – | C6: – | D6: 20405972 | E6: – | F6: 2250000
A7: Investments | B7: 616231172 | C7: 449611987 | D7: 305435633 | E7: 260233987 | F7: 314956748
A8: Advances | B8: 477673022 | C8: 395416055 | D8: 372913863 | E8: 343107147 | F8: 258693086
A9: Fixed assets | B9: 20179222 | C9: 21232750 | D9: 19696568 | E9: 12791827 | F9: 9885958
A10: Intangible assets | B10: 1188985 | C10: 1158857 | D10: 808994 | E10: 741361 | F10: 842869
A11: Deferred tax assets | B11: 5161697 | C11: 1597334 | D11: 2489752 | E11: 3773779 | F11: 100755
A12: Other assets | B12: 45906052 | C12: 42021813 | D12: 40450512 | E12: 32522174 | F12: 28448099
D13: 833208006 | E13: 706451322 | F13: 662610675
A14: Assets attributable to discontinued operations | D14: 315741 | E14: 214757 | F14: 327949
A17: Total Assets | B17: 1259328610 | C17: 992886661 | D17: 833443027 | E17: 706666079 | F17: 662938624
A18: Liabilities
A19: Bills payable | B19: 10235374 | C19: 12629996 | D19: 15768947 | E19: 15512880 | F19: 10769262
A20: Borrowings | B20: 123563761 | C20: 84163669 | D20: 51187681 | E20: 52702323 | F20: 71587311
A21: Deposits and other accounts | B21: 1015162254 | C21: 790982287 | D21: 679246312 | E21: 573596926 | F21: 525805051
A22: Liabilities against assets subject to finance lease | B22: – | C22: – | D22: – | E22: – | F22: –
A23: Subordinated debts | B23: 12000000 | C23: 12000000 | D23: 9992000 | E23: 9993600 | F23: 4992800
A24: Deferred tax liabilities | B24: – | C24: – | D24: – | E24: – | F24: –
A25: Other liabilities | B25: 42326358 | C25: 38429434 | D25: 34704048 | E25: 21178476 | F25: 17098223
A26: Total Liabilites | B26: 1203287747 | C26: 938205386 | D26: =SUM(D19:D25) -> 790898988 | E26: 672984205 | F26: 630252647
A27: Liabilities associated with discontionued operations | B27: – | C27: – | D27: 141856 | E27: 81513 | F27: 140741
D28: =SUM(D26:D27) -> 791040844 | E28: 673065718 | F28: 630393388
A29: Net Assets | B29: 56040863 | C29: 54681275 | D29: 42402183 | E29: 33600361 | F29: 32545236
A30: Represented By
A31: Share capital | B31: 12602602 | C31: 12602602 | D31: 12602602 | E31: 12602602 | F31: 12602602
A32: Reserves | B32: 32832051 | C32: 25701665 | D32: 19408889 | E32: 15588694 | F32: 12032263
A33: Surplus on revaluation of assets - net of tax | B33: 1987976 | C33: 7670955
A34: Continued operations | B34: 8618234 | C34: 8706053 | D34: 4300426 | E34: 1649197 | F34: 5142254
A35: Discontinued operations | D35: 39467 | E35: 5723 | F35: 19877
A36: Unappropriated profit | D36: 6002253 | E36: 3710867 | F36: 2703887
D37: 42353637 | E37: 33557083 | F37: 32500883
A39: Non-controlling interest | B39: – | C39: – | D39: 48546 | E39: 43278 | F39: 44353
B41: 56040863 | C41: 54681275 | D41: =SUM(D37:D39) -> 42402183 | E41: 33600361 | F41: 32545236

Sheet Income Statement
A1: Rupees in ‘000 | B1: 2021 | C1: 2020 | D1: 2019 | E1: 2018 | F1: 2017
A3: Mark-up / return / interest earned | B3: 77,569,443 | C3: 79,118,320 | D3: 71704373 | E3: 43669883 | F3: 36267220
A4: Mark-up / return / interest expenses | B4: 45139897 | C4: 48842539 | D4: 49567851 | E4: 25059925 | F4: 20071958
A5: Net mark-up / interest income | B5: 32429546 | C5: 30275781 | D5: 22136522 | E5: 18609958 | F5: 16195262
A6: Non mark-up / interest income
A7: Fee and commission income | B7: 4785268 | C7: 3991285 | D7: 3616428 | E7: 3116070 | F7: 2706794
A8: Dividend income | B8: 421964 | C8: 273524 | D8: 274440 | E8: 231312 | F8: 302894
A9: Foreign exchange income | B9: 3123524 | C9: 2673493 | D9: 2507707 | E9: 1596027 | F9: 843032
A10: Income / (loss) from derivatives | B10: – | C10: – | D10: – | E10: – | F10: –
A11: Gain on securities | B11: 814724 | C11: 2555400 | D11: 739351 | E11: 260103 | F11: 2063043
A12: Other income | B12: 402118 | C12: 349438 | D12: 266102 | E12: 418081 | F12: 200341
A13: Total non-markup / interest income | B13: 9547598 | C13: 9843140 | D13: 7404028 | E13: 5621593 | F13: 6116104
A14: Total income | B14: 41977144 | C14: 40118921 | D14: 29540550 | E14: 24231551 | F14: 22311366
A15: Non mark-up / interest expenses
A16: Operating expenses | B16: 21017376 | C16: 20217974 | D16: 18235061 | E16: 16240514 | F16: 14948796
A17: Workers’ welfare fund | B17: 213484 | C17: 42982 | D17: 42117 | E17: -540060 | F17: 169833
A18: Total non-markup / interest expenses | B18: 90139 | C18: 48149 | D18: 99947 | E18: 191067 | F18: 23568
B19: 21320999 | C19: 20309105 | D19: 18377125 | E19: 15891521 | F19: 15142197
A20: Profit before provisions | B20: 20656145 | C20: 19809816 | D20: 11163425 | E20: 8340030 | F20: 7169169
A21: Provisions and write offs - net | B21: 4983944 | C21: 1974747 | D21: 773275 | E21: 1460575 | F21: -1176432
A22: Extraordinary / unusual items | B22: – | C22: – | D22: – | E22: – | F22: –
A23: Profit before taxation | B23: 15672201 | C23: 17835069 | D23: 10390150 | E23: 6879455 | F23: 8345601
A24: Taxation | B24: -5956468 | C24: -6978072 | D24: 3372249 | E24: -2448177 | F24: -3223915
A25: Profit after taxation | B25: 9715733 | C25: 10856997 | D25: 7017901 | E25: 4431278 | F25: 5121686
A26: (Loss) / profit after taxation - discontinued operations | D26: 14669 | E26: -2659 | F26: 6611
A27: Attributable to:
A28: Equity holders of the Bank | B28: 9715733 | C28: 10846333 | D28: 7028756 | E28: 4429310 | F28: 5121863
A29: Non-controlling interest | B29: – | C29: 10664 | D29: 3814 | E29: -691 | F29: 6434
B30: 9715733 | C30: 10856997 | D30: =SUM(D28:D29) -> 7032570 | E30: 4428619 | F30: 5128297
A32: Basic and diluted earnings per share | B32: 7.71 | C32: 8.61 | D32: 5.58 | E32: 3.51 | F32: 4.06

Sheet Profitability Ratio
C1: 2021 | D1: 2020 | E1: 2019 | F1: 2018 | G1: 2017
B13: Earning Assets
B14: Loans and Advances | C14: 477673022 | D14: 395416055 | E14: 372913863 | F14: 343107147 | G14: 258693086
B15: Investments | C15: 616231172 | D15: 449611987 | E15: 305435633 | F15: 260233987 | G15: 314956748
B16: Lending to Financial Institutions - Net | C16: 0 | D16: 0 | E16: 20405972 | F16: 0 | G16: 2250000
B17: Balances with other banks | C17: 3556215 | D17: 8196147 | E17: 7886702 | F17: 4093402 | G17: 3193835
B18: TOTAL EARNING ASSETS | C18: =SUM(C14:C17) -> 1097460409 | D18: =SUM(D14:D17) -> 853224189 | E18: =SUM(E14:E17) -> 706642170 | F18: =SUM(F14:F17) -> 607434536 | G18: =SUM(G14:G17) -> 579093669
B20: Interest Bearing Liabilities
B21: Deposits (less of Current Accounts) | C21: 222888771 | D21: 539726821 | E21: 484456138 | F21: 404040078 | G21: 381975947
B22: Current Account Deposits | C22: 790982287 | D22: 1030588 | E22: 194254257 | F22: 168745407 | G22: 143678468
B23: Current Account Deposits | C23: 1291196 | D23: 250224878 | E23: 535917 | F23: 811441 | G23: 150636
B24: Borrowings | C24: 123563761 | D24: 84163669 | E24: 51187681 | F24: 52702323 | G24: 71587311
B25: Subordinated Debts | C25: 12000000 | D25: 12000000 | E25: 9992000 | F25: 9993600 | G25: 4992800
B26: Lease liability against ROU assets as per IFRS - 16 Leases | C26: 7393878 | D26: 8223995 | E26: 970082 | F26: 0 | G26: 0
B27: Total Interest Bearing Liability | C27: =SUM(C21:C26) -> 1158119893 | D27: =SUM(D21:D26) -> 895369951 | E27: =SUM(E21:E26) -> 741396075 | F27: =SUM(F21:F26) -> 636292849 | G27: =SUM(G21:G26) -> 602385162
B29: Net Income | C29: ='Income Statement'!B25 -> 9715733 | D29: ='Income Statement'!C25 -> 10856997 | E29: ='Income Statement'!D25 -> 7017901 | F29: ='Income Statement'!E25 -> 4431278 | G29: ='Income Statement'!F25 -> 5121686
B30: Equity | C30: ='Balance Sheet'!B41 -> 56040863 | D30: ='Balance Sheet'!C41 -> 54681275 | E30: ='Balance Sheet'!D41 -> 42402183 | F30: ='Balance Sheet'!E41 -> 33600361 | G30: ='Balance Sheet'!F41 -> 32545236
B31: Total Assets | C31: ='Balance Sheet'!B17 -> 1259328610 | D31: ='Balance Sheet'!C17 -> 992886661 | E31: ='Balance Sheet'!D17 -> 833443027 | F31: ='Balance Sheet'!E17 -> 706666079 | G31: ='Balance Sheet'!F17 -> 662938624
B32: Total Operating Revenue | C32: ='Income Statement'!B5-'Income Statement'!B19 -> 11108547 | D32: ='Income Statement'!C5-'Income Statement'!C19 -> 9966676 | E32: ='Income Statement'!D5-'Income Statement'!D19 -> 3759397 | F32: ='Income Statement'!E5-'Income Statement'!E19 -> 2718437 | G32: ='Income Statement'!F5-'Income Statement'!F19 -> 1053065
A34: 2
A35: 3
A36: 4
A37: 5
A38: 6
B40: Workings
B41: Total income | C41: 41977144 | D41: 40118921 | E41: 29540550 | F41: 24231551 | G41: 22311366 | S41: USE FOR NEXT RATIOS WHEN GIVEN | Y41: 2021 | Z41: 2020 | AA41: 2019 | AB41: 2018 | AC41: 2017
B42: Operating expenses | C42: 21017376 | D42: 20217974 | E42: 18235061 | F42: 16240514 | G42: 14948796 | S42: Return on Equity | T42: 13 | U42: ROE=(Net Income/ Pre-Tax Net Operating Income) * (Pre-Tax Net Operating Income/Total Operating Revenue) * (Total Operating Revenue/Total Assets) * (Total Assets/ TOtal Equity Capital )
B43: Total Assets | C43: 1259328610 | D43: 992886661 | E43: 833443027 | F43: 706666079 | G43: 662938624 | S43: Credit Risk | T43: 14 | U43: Nonperforming Loans/Total Loans | Y43: =C25/C14 -> 0.025121787 | Z43: =D25/D14 -> 0.030347781 | AA43: =E25/E14 -> 0.026794391 | AB43: =F25/F14 -> 0.029126761 | AC43: =G25/G14 -> 0.019300091
S44: Credit Risk | T44: 15 | U44: Net Charge-Offs/Total Loans
S45: Credit Risk | T45: 16 | U45: Provision for LOan Loses/Total Loans
S46: Credit Risk | T46: 17 | U46: Provision for LOan Loses/Equity Capital | Y46: ='Income Statement'!B21/'Balance Sheet'!B41 -> 0.088934105 | Z46: ='Income Statement'!C21/'Balance Sheet'!C41 -> 0.03611377 | AA46: ='Income Statement'!D21/'Balance Sheet'!D41 -> 0.018236679 | AB46: ='Income Statement'!E21/'Balance Sheet'!E41 -> 0.043469027 | AC46: ='Income Statement'!F21/'Balance Sheet'!F41 -> -0.036147595
S47: Credit Risk | T47: 18 | U47: Allowance for Loan Losses/ Toal Loans | Y47: ='Income Statement'!B21/C14 -> 0.010433798 | Z47: ='Income Statement'!C21/D14 -> 0.0049940992 | AA47: ='Income Statement'!D21/E14 -> 0.0020736022 | AB47: ='Income Statement'!E21/F14 -> 0.0042569064 | AC47: ='Income Statement'!F21/G14 -> -0.0045475974
Y48: 2021 | Z48: 2020 | AA48: 2019 | AB48: 2018 | AC48: 2017
U49: (Net Income/ Pre-Tax Net Operating Income) | Y49: ='Income Statement'!B25/'Income Statement'!B23 -> 0.61993418 | Z49: ='Income Statement'!C25/'Income Statement'!C23 -> 0.60874432 | AA49: ='Income Statement'!D25/'Income Statement'!D23 -> 0.67543789 | AB49: ='Income Statement'!E25/'Income Statement'!E23 -> 0.64413213 | AC49: ='Income Statement'!F25/'Income Statement'!F23 -> 0.61369888
U50: (Pre-Tax Net Operating Income/Total Operating Revenue)
U51: (Total Operating Revenue/Total Assets) | Y51: =C32/C31 -> 0.0088210074 | Z51: =D32/D31 -> 0.01003808 | AA51: =E32/E31 -> 0.0045106826 | AB51: =F32/F31 -> 0.003846848 | AC51: =G32/G31 -> 0.0015884804
U52: (Total Assets/ TOtal Equity Capital ) | Y52: ='Balance Sheet'!B17/'Balance Sheet'!B41 -> 22.471613 | Z52: ='Balance Sheet'!C17/'Balance Sheet'!C41 -> 18.157709 | AA52: ='Balance Sheet'!D17/'Balance Sheet'!D41 -> 19.655663 | AB52: ='Balance Sheet'!E17/'Balance Sheet'!E41 -> 21.031503 | AC52: ='Balance Sheet'!F17/'Balance Sheet'!F41 -> 20.369759
Y53: =Y49*Y50*Y51*Y52 -> 0 | Z53: =Z49*Z50*Z51*Z52 -> 0 | AA53: =AA49*AA50*AA51*AA52 -> 0 | AB53: =AB49*AB50*AB51*AB52 -> 0 | AC53: =AC49*AC50*AC51*AC52 -> 0
B56: Market Risk Measures | C56: 2021 | D56: 2020 | E56: 2019 | F56: 2018 | G56: 2017
B57: Book-Value of Assets/Market Value of Assets
...

Sheet Sheet2
A1: Market Risk Measures | B1: 2021 | C1: 2020 | D1: 2019 | E1: 2018 | F1: 2017
A2: Book-Value of Assets/Market Value of Assets
A3: Book-Value of Equity/Market Value of Equity | B3: 2.0145322 | C3: 1.8503634 | D3: 1.8085221 | E3: 1.1116221 | F3: 1.3329881
A4: Market Value Per Share | B4: 22.02 | C4: 23.39 | D4: 18.54 | E4: 23.92 | F4: 19.31
A5: Number of Shares Outstanding | B5: 1260260180 | C5: 1260260180 | D5: 1260260180 | E5: 1260260180 | F5: 1260260180
A6: Book Value of Shares | B6: 44.36 | C6: 43.28 | D6: 33.53 | E6: 26.59 | F6: 25.74
A7: Book-Value of Bonds/Market Value of Bonds
A8: Intrest Sensitive Assets/Intrest Sensitive Liabilities | B8: 1.3176955 | C8: 1.0580941 | D8: 1.0312515 | E8: 1.0721448 | F8: 1.0173813
A9: Intrest Sensitive Assets | B9: 1222420697 | C9: 956675071 | D9: 786642860 | E9: 667452221 | F9: 633359777
A10: Intrest Sensitive Liabilitis | B10: 927695864 | C10: 904149338 | D10: 762804062 | E10: 622539224 | F10: 622539224
A11: Uninsured Deposits/Total Deposits | B11: 0.60150352 | C11: 0.95457934 | D11: 0.57388257 | E11: 0.54748614 | F11: 0.54793224
A12: Uninsured Deposits | B12: 610784723000 | C12: 755250763000 | D12: 389838134000 | E12: 314057678000 | F12: 288107323000
A13: Total Deposits | B13: 1015430000000 | C13: 791187000000 | D13: 679299486000 | E13: 573635856000 | F13: 525808308000
A14: Stock Price/Earnings Per Share | B14: 2.8597403 | C14: 2.7292882 | D14: 3.3285458 | E14: 6.7954545 | F14: 4.6196172
A15: Stock Price | B15: 22.02 | C15: 23.39 | D15: 18.54 | E15: 23.92 | F15: 19.31
A16: Earnings Per Share | B16: 7.7 | C16: 8.57 | D16: 5.57 | E16: 3.52 | F16: 4.18
