Workbook

Sheet 2021
A1: Consolidated Statement of Financial Position
A2: As at December 31, 2021
A4: Assets
A5: Cash and Balances with treasury banks | B5: 58516658
A6: Balances with other banks | B6: 3517361
A7: Lending to financial institutions
A8: Investments | B8: 357249356
A9: Advances | B9: 396295362
A10: Fixed Assets | B10: 26416480
A11: Intangible Assets | B11: 2098064
A12: Deferred Tax Assets
A13: Other Assets | B13: 25875215
B14: 869968496
A15: Liabilities
A16: Bills Payable | B16: 14122901
A17: Borrowings | B17: 111189829
A18: Deposits and other accounts | B18: 644039999
A19: Liabilities against assets subject to finance lease
A20: Subordinated debt
A21: Deferred Tax Liabilities | B21: 611506
A22: Other Liabilities | B22: 33873861
B23: 803838096
A24: Net Assets | B24: 66130400
A25: Represented by
A26: Share capital | B26: 15176965
A27: Reserves | B27: 12613183
A28: Surplus on revaluation of assets - net of tax | B28: 7061583
A29: Unappropriated profit | B29: 31278631
A30: Total equity attributable to the equity holders of the bank | B30: 66130362
A31: Non-controlling interest | B31: 38
B32: 66130400

Sheet 2020
A1: Consolidated Statement of Financial Position
A2: As at December 31, 2020
A4: Assets
A5: Cash and Balances with treasury banks | B5: 59881290
A6: Balances with other banks | B6: 2878630
A7: Lending to financial institutions | B7: 2985000
A8: Investments | B8: 276469824
A9: Advances | B9: 318179878
A10: Fixed Assets | B10: 24102155
A11: Intangible Assets | B11: 1894204
A12: Deferred Tax Assets
A13: Other Assets | B13: 23673221
B14: 710064202
A15: Liabilities
A16: Bills Payable | B16: 13543270
A17: Borrowings | B17: 58446516
A18: Deposits and other accounts | B18: 540632217
A19: Liabilities against assets subject to finance lease
A20: Subordinated debt
A21: Deferred Tax Liabilities | B21: 1582351
A22: Other Liabilities | B22: 35641746
B23: 649846100
A24: Net Assets | B24: 60218102
A25: Represented by
A26: Share capital | B26: 15176965
A27: Reserves | B27: 11032647
A28: Surplus on revaluation of assets - net of tax | B28: 9027473
A29: Unappropriated profit | B29: 24981002
A30: Total equity attributable to the equity holders of the bank | B30: 60218087
A31: Non-controlling interest | B31: 15
B32: 60218102

Sheet 2019
A1: Consolidated Statement of Financial Position
A2: As at December 31, 2019
A4: Assets
A5: Cash and Balances with treasury banks | B5: 60368426
A6: Balances with other banks | B6: 2835650
A7: Lending to financial institutions
A8: Investments | B8: 203594303
A9: Advances | B9: 309573002
A10: Fixed Assets | B10: 24241544
A11: Intangible Assets | B11: 1840624
A12: Deferred Tax Assets
A13: Other Assets | B13: 27406984
B14: 629860533
A15: Liabilities
A16: Bills Payable | B16: 8356460
A17: Borrowings | B17: 72746795
A18: Deposits and other accounts | B18: 457785183
A19: Liabilities against assets subject to finance lease
A20: Subordinated debt
A21: Deferred Tax Liabilities | B21: 2816798
A22: Other Liabilities | B22: 32949870
B23: 574655106
A24: Net Assets | B24: 55205427
A25: Represented by
A26: Share capital | B26: 15176965
A27: Reserves | B27: 9830958
A28: Surplus on revaluation of assets - net of tax | B28: 10748080
A29: Unappropriated profit | B29: 19449413
A30: Total equity attributable to the equity holders of the bank | B30: 55205416
A31: Non-controlling interest | B31: 11
B32: 55205427

Sheet 2018
A1: Consolidated Statement of Financial Position
A2: As at December 31, 2018
A4: Assets
B5: 43174003
A6: Balances with other banks | B6: 1848859
A7: Lending to financial institutions | B7: 2997486
A8: Investments | B8: 213815803
A9: Advances | B9: 296444861
A10: Fixed Assets | B10: 11662446
A11: Intangible Assets | B11: 1743900
A12: Deferred Tax Assets | B12: 141712
A13: Other Assets | B13: 28167363
B14: 599996433
A15: Liabilities
A16: Bills Payable | B16: 23543524
A17: Borrowings | B17: 98351921
A18: Deposits and other accounts | B18: 409383501
A19: Liabilities against assets subject to finance lease
A20: Subordinated debt
A21: Deferred Tax Liabilities
A22: Other Liabilities | B22: 25184233
B23: 556463179
A24: Net Assets | B24: 43533254
A25: Represented by
A26: Share capital | B26: 15176965
A27: Reserves | B27: 8778908
A28: Surplus on revaluation of assets - net of tax | B28: 5093667
A29: Unappropriated profit | B29: 14483709
A30: Total equity attributable to the equity holders of the bank | B30: 43533249
A31: Non-controlling interest | B31: 5
B32: 43533254

Sheet BS
B2: Consolidated Balance Sheet
C4: 2021 | D4: =C4-1 -> 2020 | E4: =D4-1 -> 2019 | F4: =E4-1 -> 2018 | G4: =F4-1 -> 2017
B5: Assets
B6: Cash and Balances with treasury banks | C6: 58516658 | D6: 59881290 | E6: 60368426 | F6: 43174003 | G6: 37861767
B7: Balances with other banks | C7: 3517361 | D7: 2878630 | E7: 2835650 | F7: 1848859 | G7: 1872771
B8: Lending to financial institutions | C8: 0 | D8: 2985000 | E8: 0 | F8: 2997486 | G8: 9010335
B9: Investments | C9: 357249356 | D9: 276469824 | E9: 203594303 | F9: 213815803 | G9: 179706358
B10: Advances | C10: 396295362 | D10: 318179878 | E10: 309573002 | F10: 296444861 | G10: 231532160
B11: Fixed Assets | C11: 26416480 | D11: 24102155 | E11: 24241544 | F11: 11662446 | G11: 11443528
B12: Intangible Assets | C12: 2098064 | D12: 1894204 | E12: 1840624 | F12: 1743900 | G12: 1496097
B13: Deferred Tax Assets | C13: 0 | D13: 0 | E13: 0 | F13: 141712 | G13: 1607625
B14: Other Assets | C14: 25875215 | D14: 23673221 | E14: 27406984 | F14: 28167363 | G14: 20389047
B15: Total Assets | C15: 869968496 | D15: 710064202 | E15: 629860533 | F15: 599996433 | G15: 494919688
B17: Liabilities
B18: Bills Payable | C18: 14122901 | D18: 13543270 | E18: 8356460 | F18: 23543524 | G18: 8761334
B19: Borrowings | C19: 111189829 | D19: 58446516 | E19: 72746795 | F19: 98351921 | G19: 54788547
B20: Deposits and other accounts | C20: 644039999 | D20: 540632217 | E20: 457785183 | F20: 409383501 | G20: 371624155
B21: Liabilities against assets subject to finance lease | C21: 0 | D21: 0 | E21: 0 | F21: 0 | G21: 0
B22: Subordinated debt | C22: 0 | D22: 0 | E22: 0 | F22: 0 | G22: 0
B23: Deferred Tax Liabilities | C23: 611506 | D23: 1582351 | E23: 2816798 | F23: 0 | G23: 0
B24: Other Liabilities | C24: 33873861 | D24: 35641746 | E24: 32949870 | F24: 25184233 | G24: 20513376
B25: Total Liabilities | C25: 803838096 | D25: 649846100 | E25: 574655106 | F25: 556463179 | G25: 455687412
B27: Net Assets | C27: 66130400 | D27: 60218102 | E27: 55205427 | F27: 43533254 | G27: 39232276
B28: Represented by
B29: Share capital | C29: 15176965 | D29: 15176965 | E29: 15176965 | F29: 15176965 | G29: 13197361
B30: Reserves | C30: 12613183 | D30: 11032647 | E30: 9830958 | F30: 8778908 | G30: 7936338
B31: Surplus on revaluation of assets - net of tax | C31: 7061583 | D31: 9027473 | E31: 10748080 | F31: 5093667 | G31: 5613243
B32: Unappropriated profit | C32: 31278631 | D32: 24981002 | E32: 19449413 | F32: 14483709 | G32: 12485334
B33: Total equity attributable to the equity holders of the bank | C33: 66130362 | D33: 60218087 | E33: 55205416 | F33: 43533249 | G33: 39232276
B34: Non-controlling interest | C34: 38 | D34: 15 | E34: 11 | F34: 5 | G34: 0
C35: 66130400 | D35: 60218102 | E35: 55205427 | F35: 43533254 | G35: 39232276
C38: ='Risk Ratios'!L5/(BS!C10+905190) -> 0.047926905 | D38: ='Risk Ratios'!M5/BS!D10 -> 0.070421053 | E38: ='Risk Ratios'!N5/BS!E10 -> 0.09295758 | F38: ='Risk Ratios'!O5/BS!F10 -> 0.086734737 | G38: ='Risk Ratios'!P5/BS!G10 -> 0.11414061

Sheet IS
B2: Consolidated Income Statement
C4: 2021 | D4: 2020 | E4: 2019 | F4: 2018 | G4: 2017
B5: Mark-up / return / interest earned | C5: 53872073 | D5: 55925846 | E5: 58398995 | F5: 35201159 | G5: 28766119
B6: Mark-up / return / interest expensed | C6: 28032641 | D6: 31378104 | E6: 37272461 | F6: 18924879 | G6: 14830923
B7: Net mark-up / interest income | C7: 25839432 | D7: 24547742 | E7: 21126534 | F7: 16276300 | G7: 13935196
B9: NON MARK UP/ INTEREST INCOME
B10: Fee and commission income | C10: 5583433 | D10: 4085368 | E10: 4228311 | F10: 3554907 | G10: 3086639
B11: Dividend income | C11: 435437 | D11: 281864 | E11: 428588 | F11: 170110 | G11: 159514
B12: Foreign exchange income | C12: 2379113 | D12: 2093354 | E12: 2833324 | F12: 1970720 | G12: 1385057
B13: Income / (loss) from derivatives | C13: -25176 | D13: 48201 | E13: 175652 | F13: 118641 | G13: -58936
B14: (Loss) / Gain on securities | C14: 291070 | D14: 1714254 | E14: -565986 | F14: 50627 | G14: 807210
B15: Other income | C15: 252163 | D15: 128865 | E15: 250759 | F15: 524231 | G15: 259780
B16: Total non mark-up / interest income | C16: 8916040 | D16: 8351906 | E16: 7350648 | F16: 6389236 | G16: 5639264
B18: Total income | C18: 34755472 | D18: 32899648 | E18: 28477182 | F18: 22665536 | G18: 19574459
B20: NON MARK-UP / INTEREST EXPENSES
B21: Operating expenses | C21: 20794981 | D21: 19569580 | E21: 17211009 | F21: 14510447 | G21: 12607943
B22: Workers welfare fund | C22: 273650 | D22: 227031 | E22: 232722 | F22: 172758 | G22: 154382
B23: Other charges | C23: 7682 | D23: 114170 | E23: 32707 | F23: 90275 | G23: 11761
B24: Total non mark-up / interest expenses | C24: 21076313 | D24: 19910781 | E24: 17476438 | F24: 14773480 | G24: 12774086
B26: Profit before provisions | C26: 13737390 | D26: 13145037 | E26: 11000744 | F26: 7892056 | G26: 6800373
B27: Provision and write-offs - net | C27: 44969 | D27: 2254301 | E27: 842257 | F27: -421992 | G27: -491802
B28: Share of profit/ (loss) of associates | C28: 58231 | D28: 156170 | E28: - | F28: -11804 | G28: -22863
B29: extra ordinary/ unusual items | C29: - | D29: - | E29: - | F29: - | G29: -
B31: PROFIT BEFORE TAXATION | C31: 13692421 | D31: 10890736 | E31: 10158487 | F31: 8302244 | G31: 7269312
B32: Taxation | C32: 5339341 | D32: 4210115 | E32: 4154446 | F32: 3416133 | G32: 2754526
B34: PROFIT AFTER TAXATION | C34: 8353080 | D34: 6680621 | E34: 6004041 | F34: 4886111 | G34: 4514786
B36: Attributable to:
B37: Equity holders of the parent | C37: 8353057 | D37: 6680617 | E37: 6004046 | F37: 4886111 | G37: 4514786
B38: Non-controlling interest | C38: 23 | D38: 4 | E38: -5 | F38: 0 | G38: 0
C39: 8353080 | D39: 6680621 | E39: 6004041 | F39: 4886111 | G39: 4514786
B40: Basic / diluted earnings per share | C40: 5.5 | D40: 4.4 | E40: 3.96 | F40: 3.22 | G40: 2.97

Sheet Profitibility Ratios
B3: Faysal Bank
B4: Profitability Ratios
C5: 2021 | D5: 2020 | E5: 2019 | F5: 2018 | G5: 2017
B6: Return on Equity (ROE) | C6: =IS!C34/BS!C33 -> 0.12631233 | D6: =IS!D34/BS!D33 -> 0.11094044 | E6: =IS!E34/BS!E33 -> 0.10875819 | F6: =IS!F34/BS!F33 -> 0.1122386 | G6: =IS!G34/BS!G33 -> 0.11507836
B7: Gross Spread Ratio (NIM/ Gross Interest Income) | C7: =C8/IS!C5 -> 5.5133524e-10 | D7: =D8/IS!D5 -> 6.1816067e-10 | E7: =E8/IS!E5 -> 5.7435246e-10 | F7: =F8/IS!F5 -> 7.7063735e-10 | G7: =G8/IS!G5 -> 9.7880703e-10
B8: Net Interest Margin | C8: =IS!C7/BS!C15 -> 0.029701572 | D8: =IS!D7/BS!D15 -> 0.034571158 | E8: =IS!E7/BS!E15 -> 0.033541606 | F8: =IS!F7/BS!F15 -> 0.027127328 | G8: =IS!G7/BS!G15 -> 0.028156479
B9: Net Non-Interest Margin | C9: =(IS!C16-IS!C24)/BS!C15 -> -0.013977831 | D9: =(IS!D16-IS!D24)/BS!D15 -> -0.016278634 | E9: =(IS!E16-IS!E24)/BS!E15 -> -0.016076241 | F9: =(IS!F16-IS!F24)/BS!F15 -> -0.013973823 | G9: =(IS!G16-IS!G24)/BS!G15 -> -0.014416121
B10: Earning Spread | C10: =(IS!C5/(BS!C8+BS!C9+BS!C10))-(IS!C6/(BS!C19+BS!C20)) -> 0.034373514 | D10: =(IS!D5/(BS!D8+BS!D9+BS!D10))-(IS!D6/(BS!D19+BS!D20)) -> 0.041201383 | E10: =(IS!E5/(BS!E8+BS!E9+BS!E10))-(IS!E6/(BS!E19+BS!E20)) -> 0.043546202 | F10: =(IS!F5/(BS!F8+BS!F9+BS!F10))-(IS!F6/(BS!F19+BS!F20)) -> 0.03131062 | G10: =(IS!G5/(BS!G8+BS!G9+BS!G10))-(IS!G6/(BS!G19+BS!G20)) -> 0.033669524
B11: Net Profit Margin | C11: =IS!C34/(IS!C5+IS!C16) -> 0.13303601 | D11: =IS!D34/(IS!D5+IS!D16) -> 0.10393364 | E11: =IS!E34/(IS!E5+IS!E16) -> 0.091316709 | F11: =IS!F34/(IS!F5+IS!F16) -> 0.11748172 | G11: =IS!G34/(IS!G5+IS!G16) -> 0.13122324
B13: Efficiency Ratios
B14: Operating efficiency | C14: =IS!C21/IS!C18 -> 0.5983225 | D14: =IS!D21/IS!D18 -> 0.59482642 | E14: =IS!E21/IS!E18 -> 0.60437894 | F14: =IS!F21/IS!F18 -> 0.64019871 | G14: =IS!G21/IS!G18 -> 0.64410173
B15: Tax management efficency | C15: =IS!C34/IS!C31 -> 0.61005136 | D15: =IS!D34/IS!D31 -> 0.61342236 | E15: =IS!E34/IS!E31 -> 0.59103693 | F15: =IS!F34/IS!F31 -> 0.58852896 | G15: =IS!G34/IS!G31 -> 0.62107473
B16: Asset management efficiency | C16: =IS!C18/BS!C15 -> 0.039950265 | D16: =IS!D18/BS!D15 -> 0.046333343 | E16: =IS!E18/BS!E15 -> 0.045211885 | F16: =IS!F18/BS!F15 -> 0.037776118 | G16: =IS!G18/BS!G15 -> 0.039550779
B21: DuPont Analysis
B22: Net Bank operating Margin | C22: =(IS!C18-IS!C21)/BS!C15 -> 0.016047122 | D22: =(IS!D18-IS!D21)/BS!D15 -> 0.018773046 | E22: =(IS!E18-IS!E21)/BS!E15 -> 0.017886774 | F22: =(IS!F18-IS!F21)/BS!F15 -> 0.013591896 | G22: =(IS!G18-IS!G21)/BS!G15 -> 0.014076053
B23: Return on Assets (ROA) | C23: =IS!C34/BS!C15 -> 0.0096015891 | D23: =IS!D34/BS!D15 -> 0.0094084746 | E23: =IS!E34/BS!E15 -> 0.009532334 | F23: =IS!F34/BS!F15 -> 0.0081435667 | G23: =IS!G34/BS!G15 -> 0.0091222599
B24: Asset Utilization | C24: =IS!C18/BS!C15 -> 0.039950265 | D24: =IS!D18/BS!D15 -> 0.046333343 | E24: =IS!E18/BS!E15 -> 0.045211885 | F24: =IS!F18/BS!F15 -> 0.037776118 | G24: =IS!G18/BS!G15 -> 0.039550779
B25: Leverage | C25: =BS!C25/BS!C15 -> 0.92398529 | D25: =BS!D25/BS!D15 -> 0.91519344 | E25: =BS!E25/BS!E15 -> 0.91235294 | F25: =BS!F25/BS!F15 -> 0.92744415 | G25: =BS!G25/BS!G15 -> 0.92073002
B26: Equity Multiplier | C26: =BS!C15/BS!C33 -> 13.155357 | D26: =BS!D15/BS!D33 -> 11.791544 | E26: =BS!E15/BS!E33 -> 11.409397 | F26: =BS!F15/BS!F33 -> 13.782487 | G26: =BS!G15/BS!G33 -> 12.615115
B27: Leverage / Equity Multiplier | C27: =C25/C26 -> 0.070236431 | D27: =D25/D26 -> 0.077614388 | E27: =E25/E26 -> 0.079965041 | F27: =F25/F26 -> 0.067291495 | G27: =G25/G26 -> 0.072986254
B28: Return on Equity (ROE) | C28: =C23*C26 -> 0.12631233 | D28: =D23*D26 -> 0.11094044 | E28: =E23*E26 -> 0.10875819 | F28: =F23*F26 -> 0.1122386 | G28: =G23*G26 -> 0.11507836

Sheet Risk Ratios
B2: Credit Risk Measures
C3: 2021 | D3: 2020 | E3: 2019 | F3: 2018 | G3: 2017 | L3: 2021 | M3: =L3-1 -> 2020 | N3: =M3-1 -> 2019 | O3: =N3-1 -> 2018 | P3: =O3-1 -> 2017
B4: Non Performing loans/ Total Loans | C4: =L5/BS!C10 -> 0.048036376 | D4: =M5/BS!D10 -> 0.070421053 | E4: =N5/BS!E10 -> 0.09295758 | F4: =O5/BS!F10 -> 0.086734737 | G4: =P5/BS!G10 -> 0.11414061 | J4: Note 11: | K4: Total Loans | L4: 61512908 | M4: 141824644 | N4: 211337634 | O4: 235798986 | P4: 203609174
B5: Net Charge-offs/ Total Loans | C5: =IS!C27/BS!C10 -> 0.00011347345 | D5: =IS!D27/BS!D10 -> 0.0070849892 | E5: =IS!E27/BS!E10 -> 0.0027207056 | F5: =IS!F27/BS!F10 -> -0.0014235092 | G5: =IS!G27/BS!G10 -> -0.0021241196 | J5: Note 11: | K5: Non Performing loans | L5: 19036593 | M5: 22406562 | N5: 28777157 | O5: 25712067 | P5: 26427221
B6: Provision for Loan Losses / Total Loans | C6: =L6/BS!C10 -> 0.05170415 | D6: =M6/BS!D10 -> 0.06777741 | E6: =N6/BS!E10 -> 0.078293891 | F6: =O6/BS!F10 -> 0.078042375 | G6: =P6/BS!G10 -> 0.10247562 | J6: Note 11: | K6: Provision against loans | L6: 20490115 | M6: 21565408 | N6: 24237675 | O6: 23135261 | P6: 23726401
B7: Provision for Loan Losses / Equity Capital | C7: =L6/BS!C33 -> 0.30984429 | D7: =M6/BS!D33 -> 0.35812177 | E7: =N6/BS!E33 -> 0.43904524 | F7: =O6/BS!F33 -> 0.53143888 | G7: =P6/BS!G33 -> 0.60476739
B8: Allowance for Loan losses / Total loans
B9: Allowance for Loan losses / Equity Capital
B10: Nonperforming Loans / Equity Capital | C10: =L5/BS!C33 -> 0.28786464 | D10: =M5/BS!D33 -> 0.37209023 | E10: =N5/BS!E33 -> 0.52127416 | F10: =O5/BS!F33 -> 0.59063055 | G10: =P5/BS!G33 -> 0.67360917
B13: Other Goals In Banking | L13: 2021 | M13: =L13-1 -> 2020 | N13: =M13-1 -> 2019 | O13: =N13-1 -> 2018 | P13: =O13-1 -> 2017
C14: 2021 | D14: 2020 | E14: 2019 | F14: 2018 | G14: 2017 | K14: no of full time equiv emp | L14: 7093 | M14: 6767 | N14: 6916 | O14: 6118 | P14: 3592
B15: operating efficiency ratio | C15: =C23/C21 -> 0.5983225 | D15: =D23/D21 -> 0.59482642 | E15: =E23/E21 -> 0.60437894 | F15: =F23/F21 -> 0.64019871 | G15: =G23/G21 -> 0.64410173 | K15: net operating income= rev - exp | L15: =C21-C23 -> 13960491 | M15: =D21-D23 -> 13330068 | N15: =E21-E23 -> 11266173 | O15: =F21-F23 -> 8155089 | P15: =G21-G23 -> 6966516
B16: employee productivity ratio | C16: =L15/L14 -> 1968.2068 | D16: =M15/M14 -> 1969.8638 | E16: =N15/N14 -> 1629.0013 | F16: =O15/O14 -> 1332.9665 | G16: =P15/P14 -> 1939.4532
B21: Total income | C21: 34755472 | D21: 32899648 | E21: 28477182 | F21: 22665536 | G21: 19574459
B23: Operating expenses | C23: 20794981 | D23: 19569580 | E23: 17211009 | F23: 14510447 | G23: 12607943
B24: Capital Risk Ratios
C25: 2017 | D25: 2018 | E25: 2019 | F25: 2020 | G25: 2021 | L25: 2021 | M25: =L25-1 -> 2020 | N25: =M25-1 -> 2019 | O25: =N25-1 -> 2018 | P25: =O25-1 -> 2017
B26: Stock price/ EPS | C26: =P26/P27 -> 7.2080537 | D26: =O26/O27 -> 7.5454545 | E26: =N26/N27 -> 4.7788945 | F26: =M26/M27 -> 4.027972 | G26: =L26/L27 -> 4.283054 | K26: Stock price | L26: 23 | M26: 17.28 | N26: 19.02 | O26: 24.07 | P26: 21.48
B27: Equity Capital / Total Assets | C27: =BS!C33/BS!C15 -> 0.076014663 | D27: =BS!D33/BS!D15 -> 0.084806538 | E27: =BS!E33/BS!E15 -> 0.087647047 | F27: =BS!F33/BS!F15 -> 0.072555846 | G27: =BS!G33/BS!G15 -> 0.079269985 | K27: EPS | L27: 5.37 | M27: 4.29 | N27: 3.98 | O27: 3.19 | P27: 2.98
B28: Purchased Funds/ Total Liabilities | C28: =P29/BS!C25 -> 0.055638263 | D28: =O29/BS!D25 -> 0.067428485 | E28: =N29/BS!E25 -> 0.13545283 | F28: =M29/BS!F25 -> 0.094179322 | G28: =L29/BS!G25 -> 0.21207976 | K28: Purchased funds
B29: Equity Capital / Risk assets | C29: =BS!C33/'Risk Ratios'!P34 -> 0.087759041 | D29: =BS!D33/'Risk Ratios'!O34 -> 0.10076069 | E29: =BS!E33/'Risk Ratios'!N34 -> 0.10757781 | F29: =BS!F33/'Risk Ratios'!M34 -> 0.084817453 | G29: =BS!G33/'Risk Ratios'!L34 -> 0.093354868 | J29: from the notes | K29: Borrowings from state bank and other financial institutions | L29: 96642078 | M29: 52407325 | N29: 77838662 | O29: 43818138 | P29: 44724155
K30: Risk assets
K31: Lending to financial institutions | L31: 9010335 | M31: 2997486 | N31: 0 | O31: 2985000 | P31: 0
K32: Investments | L32: 179706358 | M32: 213815803 | N32: 203594303 | O32: 276469824 | P32: 357249356
B33: Interest Rate Risk Measures | K33: Advances | L33: 231532160 | M33: 296444861 | N33: 309573002 | O33: 318179878 | P33: 396295362
C34: 2021 | D34: =C34-1 -> 2020 | E34: =D34-1 -> 2019 | F34: =E34-1 -> 2018 | G34: =F34-1 -> 2017 | K34: Total risk assets | L34: =SUM(L31:L33) -> 420248853 | M34: =SUM(M31:M33) -> 513258150 | N34: =SUM(N31:N33) -> 513167305 | O34: =SUM(O31:O33) -> 597634702 | P34: =SUM(P31:P33) -> 753544718
B35: Interest Sensitive Assets / Interest Sensitive Liabilities | C35: =(BS!C8+BS!C10)/'Risk Ratios'!L40 -> 0.9150971 | D35: =(BS!D8+BS!D10)/'Risk Ratios'!M40 -> 0.8573276 | E35: =(BS!E8+BS!E10)/'Risk Ratios'!N40 -> 0.96125664 | F35: =(BS!F8+BS!F10)/'Risk Ratios'!O40 -> 1.0646005 | G35: =(BS!G8+BS!G10)/'Risk Ratios'!P40 -> 0.9593268
B36: Uninsured Deposits / Total Deposits
K37: Deposits and other accounts | L37: 644039999 | M37: 540632217 | N37: 457785183 | O37: 409383501 | P37: 371624155
K38: Current deposits - Customers | L38: 209205907 | M38: 165157864 | N38: 134559298 | O38: 126932482 | P38: 120326105
B39: Liquidity Risk Measures | K39: Current deposits - Financial Institutions | L39: 1770365 | M39: 862738 | N39: 1175572 | O39: 1178990 | P39: 557119
C40: 2021 | D40: 2020 | E40: 2019 | F40: 2018 | G40: 2017 | K40: Interest Sensitive Liabilities | L40: =L37-L38-L39 -> 433063727 | M40: =M37-M38-M39 -> 374611615 | N40: =N37-N38-N39 -> 322050313 | O40: =O37-O38-O39 -> 281272029 | P40: =P37-P38-P39 -> 250740931
B41: Purchased funds/ Total Assets | C41: =L53/L47 -> 0.11108687 | D41: =M53/M47 -> 0.07380646 | E41: =N53/N47 -> 0.12358079 | F41: =O53/O47 -> 0.073030664 | G41: =P53/P47 -> 0.09036649
B42: Net loans/Total Assets | C42: =L45/L47 -> 0.048825119 | D42: =M45/M47 -> 0.16817927 | E42: =N45/N47 -> 0.2898427 | F42: =O45/O47 -> 0.35014695 | G42: =P45/P47 -> 0.35800142
B43: Cash and due from bank/Total Assets | C43: =L51/L47 -> 0.071306052 | D43: =M51/M47 -> 0.088386261 | E43: =N51/N47 -> 0.10034614 | F43: =O51/O47 -> 0.075038549 | G43: =P51/P47 -> 0.08028482
B44: Cash and govt. securities/Total Assets | C44: =L54/L47 -> 0.067262962 | D44: =M54/M47 -> 0.084332219 | E44: =N54/N47 -> 0.095844116 | F44: =O54/O47 -> 0.071957099 | G44: =P54/P47 -> 0.07650083 | L44: 2021 | M44: 2020 | N44: 2019 | O44: 2018 | P44: 2017
K45: Net laons= total loans -non performing loans | L45: =L4-L5 -> 42476315 | M45: =M4-M5 -> 119418082 | N45: =N4-N5 -> 182560477 | O45: =O4-O5 -> 210086919 | P45: =P4-P5 -> 177181953
K47: Total Assets | L47: 869968496 | M47: 710064202 | N47: 629860533 | O47: 599996433 | P47: 494919688
K49: Cash and Balances with treasury banks | L49: 58516658 | M49: 59881290 | N49: 60368426 | O49: 43174003 | P49: 37861767
K50: Balances with other banks | L50: 3517361 | M50: 2878630 | N50: 2835650 | O50: 1848859 | P50: 1872771
...
